{"asctime": "2025-06-30 09:00:01", "msecs": 806.0, "levelname": "INFO", "name": "src", "lineno": 24, "message": "Logging works!!!"}
{"asctime": "2025-06-30 09:00:06", "msecs": 22.0, "levelname": "INFO", "name": "uvicorn.error", "lineno": 62, "message": "Application startup complete."}
{"asctime": "2025-06-30 09:00:06", "msecs": 26.0, "levelname": "INFO", "name": "uvicorn.error", "lineno": 215, "message": "Uvicorn running on http://127.0.0.1:8000 (Press CTRL+C to quit)", "color_message": "Uvicorn running on \u001b[1m%s://%s:%d\u001b[0m (Press CTRL+C to quit)"}
{"asctime": "2025-06-30 09:00:34", "msecs": 34.0, "levelname": "INFO", "name": "uvicorn.error", "lineno": 263, "message": "Shutting down"}
{"asctime": "2025-06-30 09:00:34", "msecs": 143.0, "levelname": "INFO", "name": "uvicorn.error", "lineno": 67, "message": "Waiting for application shutdown."}
{"asctime": "2025-06-30 09:00:34", "msecs": 297.0, "levelname": "INFO", "name": "uvicorn.error", "lineno": 76, "message": "Application shutdown complete."}
{"asctime": "2025-06-30 09:00:34", "msecs": 299.0, "levelname": "INFO", "name": "uvicorn.error", "lineno": 93, "message": "Finished server process [9980]", "color_message": "Finished server process [\u001b[36m%d\u001b[0m]"}
{"asctime": "2025-06-30 09:04:11", "msecs": 429.0, "levelname": "INFO", "name": "src", "lineno": 24, "message": "Logging works!!!"}
{"asctime": "2025-06-30 09:04:15", "msecs": 826.0, "levelname": "INFO", "name": "uvicorn.error", "lineno": 62, "message": "Application startup complete."}
{"asctime": "2025-06-30 09:04:15", "msecs": 828.0, "levelname": "INFO", "name": "uvicorn.error", "lineno": 215, "message": "Uvicorn running on http://127.0.0.1:8000 (Press CTRL+C to quit)", "color_message": "Uvicorn running on \u001b[1m%s://%s:%d\u001b[0m (Press CTRL+C to quit)"}
{"asctime": "2025-06-30 09:05:08", "msecs": 2.0, "levelname": "INFO", "name": "uvicorn.error", "lineno": 263, "message": "Shutting down"}
{"asctime": "2025-06-30 09:05:08", "msecs": 110.0, "levelname": "INFO", "name": "uvicorn.error", "lineno": 67, "message": "Waiting for application shutdown."}
{"asctime": "2025-06-30 09:05:08", "msecs": 265.0, "levelname": "INFO", "name": "uvicorn.error", "lineno": 76, "message": "Application shutdown complete."}
{"asctime": "2025-06-30 09:05:08", "msecs": 267.0, "levelname": "INFO", "name": "uvicorn.error", "lineno": 93, "message": "Finished server process [10217]", "color_message": "Finished server process [\u001b[36m%d\u001b[0m]"}
{"asctime": "2025-06-30 09:06:27", "msecs": 754.0, "levelname": "INFO", "name": "src", "lineno": 24, "message": "Logging works!!!"}
{"asctime": "2025-06-30 09:06:31", "msecs": 935.0, "levelname": "INFO", "name": "uvicorn.error", "lineno": 62, "message": "Application startup complete."}
{"asctime": "2025-06-30 09:06:31", "msecs": 947.0, "levelname": "INFO", "name": "uvicorn.error", "lineno": 215, "message": "Uvicorn running on http://127.0.0.1:8000 (Press CTRL+C to quit)", "color_message": "Uvicorn running on \u001b[1m%s://%s:%d\u001b[0m (Press CTRL+C to quit)"}
{"asctime": "2025-06-30 09:06:34", "msecs": 941.0, "levelname": "INFO", "name": "uvicorn.access", "lineno": 476, "message": "127.0.0.1:56220 - \"GET /docs HTTP/1.1\" 200"}
{"asctime": "2025-06-30 09:06:35", "msecs": 474.0, "levelname": "INFO", "name": "uvicorn.access", "lineno": 476, "message": "127.0.0.1:56220 - \"GET /openapi.json HTTP/1.1\" 200"}
{"asctime": "2025-06-30 09:07:33", "msecs": 82.0, "levelname": "WARNING", "name": "passlib.handlers.bcrypt", "lineno": 622, "message": "(trapped) error reading bcrypt version", "exc_info": "Traceback (most recent call last):\n  File \"/Users/Apple/TO-DO project/venv/lib/python3.12/site-packages/passlib/handlers/bcrypt.py\", line 620, in _load_backend_mixin\n    version = _bcrypt.__about__.__version__\n              ^^^^^^^^^^^^^^^^^\nAttributeError: module 'bcrypt' has no attribute '__about__'"}
{"asctime": "2025-06-30 09:07:33", "msecs": 98.0, "levelname": "DEBUG", "name": "passlib.handlers.bcrypt", "lineno": 625, "message": "detected 'bcrypt' backend, version '<unknown>'"}
{"asctime": "2025-06-30 09:07:33", "msecs": 102.0, "levelname": "DEBUG", "name": "passlib.handlers.bcrypt", "lineno": 406, "message": "'bcrypt' backend lacks $2$ support, enabling workaround"}
{"asctime": "2025-06-30 09:07:34", "msecs": 384.0, "levelname": "INFO", "name": "uvicorn.access", "lineno": 476, "message": "127.0.0.1:56266 - \"POST /api/v1/auth/register HTTP/1.1\" 201"}
{"asctime": "2025-06-30 09:09:33", "msecs": 669.0, "levelname": "INFO", "name": "uvicorn.access", "lineno": 476, "message": "127.0.0.1:56314 - \"POST /api/v1/auth/login HTTP/1.1\" 200"}
{"asctime": "2025-06-30 09:09:56", "msecs": 394.0, "levelname": "ERROR", "name": "root", "lineno": 44, "message": "Token decoding failed: Signature verification failed"}
{"asctime": "2025-06-30 09:09:56", "msecs": 397.0, "levelname": "INFO", "name": "uvicorn.access", "lineno": 476, "message": "127.0.0.1:56333 - \"GET /api/v1/auth/me HTTP/1.1\" 401"}
{"asctime": "2025-06-30 09:11:19", "msecs": 70.0, "levelname": "INFO", "name": "uvicorn.access", "lineno": 476, "message": "127.0.0.1:56396 - \"GET /api/v1/auth/user/omotomi.eniola%40bowen.edu.ng HTTP/1.1\" 200"}
{"asctime": "2025-06-30 09:11:29", "msecs": 212.0, "levelname": "ERROR", "name": "root", "lineno": 44, "message": "Token decoding failed: Signature verification failed"}
{"asctime": "2025-06-30 09:11:29", "msecs": 219.0, "levelname": "INFO", "name": "uvicorn.access", "lineno": 476, "message": "127.0.0.1:56400 - \"GET /api/v1/todo/ HTTP/1.1\" 401"}
{"asctime": "2025-06-30 09:12:37", "msecs": 608.0, "levelname": "INFO", "name": "uvicorn.access", "lineno": 476, "message": "127.0.0.1:56443 - \"POST /api/v1/auth/register HTTP/1.1\" 201"}
{"asctime": "2025-06-30 09:13:08", "msecs": 683.0, "levelname": "INFO", "name": "uvicorn.access", "lineno": 476, "message": "127.0.0.1:56451 - \"POST /api/v1/auth/login HTTP/1.1\" 200"}
{"asctime": "2025-06-30 09:13:53", "msecs": 934.0, "levelname": "DEBUG", "name": "src.utils.utils", "lineno": 41, "message": "Decoding Token here"}
{"asctime": "2025-06-30 09:13:54", "msecs": 349.0, "levelname": "INFO", "name": "uvicorn.access", "lineno": 476, "message": "127.0.0.1:56484 - \"GET /api/v1/auth/me HTTP/1.1\" 200"}
{"asctime": "2025-06-30 09:15:13", "msecs": 991.0, "levelname": "INFO", "name": "uvicorn.access", "lineno": 476, "message": "127.0.0.1:56505 - \"GET /api/v1/todo HTTP/1.1\" 307"}
{"asctime": "2025-06-30 09:15:14", "msecs": 50.0, "levelname": "DEBUG", "name": "src.utils.utils", "lineno": 41, "message": "Decoding Token here"}
{"asctime": "2025-06-30 09:15:14", "msecs": 631.0, "levelname": "INFO", "name": "uvicorn.access", "lineno": 476, "message": "127.0.0.1:56505 - \"GET /api/v1/todo/ HTTP/1.1\" 200"}
{"asctime": "2025-06-30 09:16:23", "msecs": 375.0, "levelname": "INFO", "name": "uvicorn.access", "lineno": 476, "message": "127.0.0.1:56530 - \"POST /api/v1/todo HTTP/1.1\" 307"}
{"asctime": "2025-06-30 09:16:23", "msecs": 383.0, "levelname": "DEBUG", "name": "src.utils.utils", "lineno": 41, "message": "Decoding Token here"}
{"asctime": "2025-06-30 09:16:23", "msecs": 974.0, "levelname": "INFO", "name": "uvicorn.access", "lineno": 476, "message": "127.0.0.1:56530 - \"POST /api/v1/todo/ HTTP/1.1\" 500"}
{"asctime": "2025-06-30 09:16:23", "msecs": 977.0, "levelname": "ERROR", "name": "uvicorn.error", "lineno": 414, "message": "Exception in ASGI application\n", "exc_info": "Traceback (most recent call last):\n  File \"/Users/Apple/TO-DO project/venv/lib/python3.12/site-packages/sqlalchemy/dialects/postgresql/asyncpg.py\", line 545, in _prepare_and_execute\n    self._rows = deque(await prepared_stmt.fetch(*parameters))\n                       ^^^^^^^^^^^^^^^^^^^^^^^^^^^^^^^^^^^^^^\n  File \"/Users/Apple/TO-DO project/venv/lib/python3.12/site-packages/asyncpg/prepared_stmt.py\", line 176, in fetch\n    data = await self.__bind_execute(args, 0, timeout)\n           ^^^^^^^^^^^^^^^^^^^^^^^^^^^^^^^^^^^^^^^^^^^\n  File \"/Users/Apple/TO-DO project/venv/lib/python3.12/site-packages/asyncpg/prepared_stmt.py\", line 267, in __bind_execute\n    data, status, _ = await self.__do_execute(\n                      ^^^^^^^^^^^^^^^^^^^^^^^^\n  File \"/Users/Apple/TO-DO project/venv/lib/python3.12/site-packages/asyncpg/prepared_stmt.py\", line 256, in __do_execute\n    return await executor(protocol)\n           ^^^^^^^^^^^^^^^^^^^^^^^^\n  File \"asyncpg/protocol/protocol.pyx\", line 206, in bind_execute\nasyncpg.exceptions.NotNullViolationError: null value in column \"is_completed\" of relation \"todo_items\" violates not-null constraint\nDETAIL:  Failing row contains (3baf9659-d9f9-420e-a558-260349262f5b, Lock In, It is time to lock in and get it, null, 2025-06-30 09:16:23.417481, 2025-06-30 09:16:23.417487, null).\n\nThe above exception was the direct cause of the following exception:\n\nTraceback (most recent call last):\n  File \"/Users/Apple/TO-DO project/venv/lib/python3.12/site-packages/sqlalchemy/engine/base.py\", line 1963, in _exec_single_context\n    self.dialect.do_execute(\n  File \"/Users/Apple/TO-DO project/venv/lib/python3.12/site-packages/sqlalchemy/engine/default.py\", line 943, in do_execute\n    cursor.execute(statement, parameters)\n  File \"/Users/Apple/TO-DO project/venv/lib/python3.12/site-packages/sqlalchemy/dialects/postgresql/asyncpg.py\", line 580, in execute\n    self._adapt_connection.await_(\n  File \"/Users/Apple/TO-DO project/venv/lib/python3.12/site-packages/sqlalchemy/util/_concurrency_py3k.py\", line 132, in await_only\n    return current.parent.switch(awaitable)  # type: ignore[no-any-return,attr-defined] # noqa: E501\n           ^^^^^^^^^^^^^^^^^^^^^^^^^^^^^^^^\n  File \"/Users/Apple/TO-DO project/venv/lib/python3.12/site-packages/sqlalchemy/util/_concurrency_py3k.py\", line 196, in greenlet_spawn\n    value = await result\n            ^^^^^^^^^^^^\n  File \"/Users/Apple/TO-DO project/venv/lib/python3.12/site-packages/sqlalchemy/dialects/postgresql/asyncpg.py\", line 558, in _prepare_and_execute\n    self._handle_exception(error)\n  File \"/Users/Apple/TO-DO project/venv/lib/python3.12/site-packages/sqlalchemy/dialects/postgresql/asyncpg.py\", line 508, in _handle_exception\n    self._adapt_connection._handle_exception(error)\n  File \"/Users/Apple/TO-DO project/venv/lib/python3.12/site-packages/sqlalchemy/dialects/postgresql/asyncpg.py\", line 792, in _handle_exception\n    raise translated_error from error\nsqlalchemy.dialects.postgresql.asyncpg.AsyncAdapt_asyncpg_dbapi.IntegrityError: <class 'asyncpg.exceptions.NotNullViolationError'>: null value in column \"is_completed\" of relation \"todo_items\" violates not-null constraint\nDETAIL:  Failing row contains (3baf9659-d9f9-420e-a558-260349262f5b, Lock In, It is time to lock in and get it, null, 2025-06-30 09:16:23.417481, 2025-06-30 09:16:23.417487, null).\n\nThe above exception was the direct cause of the following exception:\n\nTraceback (most recent call last):\n  File \"/Users/Apple/TO-DO project/venv/lib/python3.12/site-packages/uvicorn/protocols/http/httptools_impl.py\", line 409, in run_asgi\n    result = await app(  # type: ignore[func-returns-value]\n             ^^^^^^^^^^^^^^^^^^^^^^^^^^^^^^^^^^^^^^^^^^^^^^\n  File \"/Users/Apple/TO-DO project/venv/lib/python3.12/site-packages/uvicorn/middleware/proxy_headers.py\", line 60, in __call__\n    return await self.app(scope, receive, send)\n           ^^^^^^^^^^^^^^^^^^^^^^^^^^^^^^^^^^^^\n  File \"/Users/Apple/TO-DO project/venv/lib/python3.12/site-packages/fastapi/applications.py\", line 1054, in __call__\n    await super().__call__(scope, receive, send)\n  File \"/Users/Apple/TO-DO project/venv/lib/python3.12/site-packages/starlette/applications.py\", line 112, in __call__\n    await self.middleware_stack(scope, receive, send)\n  File \"/Users/Apple/TO-DO project/venv/lib/python3.12/site-packages/starlette/middleware/errors.py\", line 187, in __call__\n    raise exc\n  File \"/Users/Apple/TO-DO project/venv/lib/python3.12/site-packages/starlette/middleware/errors.py\", line 165, in __call__\n    await self.app(scope, receive, _send)\n  File \"/Users/Apple/TO-DO project/venv/lib/python3.12/site-packages/starlette/middleware/exceptions.py\", line 62, in __call__\n    await wrap_app_handling_exceptions(self.app, conn)(scope, receive, send)\n  File \"/Users/Apple/TO-DO project/venv/lib/python3.12/site-packages/starlette/_exception_handler.py\", line 53, in wrapped_app\n    raise exc\n  File \"/Users/Apple/TO-DO project/venv/lib/python3.12/site-packages/starlette/_exception_handler.py\", line 42, in wrapped_app\n    await app(scope, receive, sender)\n  File \"/Users/Apple/TO-DO project/venv/lib/python3.12/site-packages/starlette/routing.py\", line 714, in __call__\n    await self.middleware_stack(scope, receive, send)\n  File \"/Users/Apple/TO-DO project/venv/lib/python3.12/site-packages/starlette/routing.py\", line 734, in app\n    await route.handle(scope, receive, send)\n  File \"/Users/Apple/TO-DO project/venv/lib/python3.12/site-packages/starlette/routing.py\", line 288, in handle\n    await self.app(scope, receive, send)\n  File \"/Users/Apple/TO-DO project/venv/lib/python3.12/site-packages/starlette/routing.py\", line 76, in app\n    await wrap_app_handling_exceptions(app, request)(scope, receive, send)\n  File \"/Users/Apple/TO-DO project/venv/lib/python3.12/site-packages/starlette/_exception_handler.py\", line 53, in wrapped_app\n    raise exc\n  File \"/Users/Apple/TO-DO project/venv/lib/python3.12/site-packages/starlette/_exception_handler.py\", line 42, in wrapped_app\n    await app(scope, receive, sender)\n  File \"/Users/Apple/TO-DO project/venv/lib/python3.12/site-packages/starlette/routing.py\", line 73, in app\n    response = await f(request)\n               ^^^^^^^^^^^^^^^^\n  File \"/Users/Apple/TO-DO project/venv/lib/python3.12/site-packages/fastapi/routing.py\", line 301, in app\n    raw_response = await run_endpoint_function(\n                   ^^^^^^^^^^^^^^^^^^^^^^^^^^^^\n  File \"/Users/Apple/TO-DO project/venv/lib/python3.12/site-packages/fastapi/routing.py\", line 212, in run_endpoint_function\n    return await dependant.call(**values)\n           ^^^^^^^^^^^^^^^^^^^^^^^^^^^^^^\n  File \"/Users/Apple/TO-DO project/src/v1/routes/todo.py\", line 26, in create_todo\n    todo = await todo_service.create_todo(todo_data=todo_data, session=session)\n           ^^^^^^^^^^^^^^^^^^^^^^^^^^^^^^^^^^^^^^^^^^^^^^^^^^^^^^^^^^^^^^^^^^^^\n  File \"/Users/Apple/TO-DO project/src/v1/service/todo.py\", line 21, in create_todo\n    await session.commit()\n  File \"/Users/Apple/TO-DO project/venv/lib/python3.12/site-packages/sqlalchemy/ext/asyncio/session.py\", line 1014, in commit\n    await greenlet_spawn(self.sync_session.commit)\n  File \"/Users/Apple/TO-DO project/venv/lib/python3.12/site-packages/sqlalchemy/util/_concurrency_py3k.py\", line 203, in greenlet_spawn\n    result = context.switch(value)\n             ^^^^^^^^^^^^^^^^^^^^^\n  File \"/Users/Apple/TO-DO project/venv/lib/python3.12/site-packages/sqlalchemy/orm/session.py\", line 2032, in commit\n    trans.commit(_to_root=True)\n  File \"<string>\", line 2, in commit\n  File \"/Users/Apple/TO-DO project/venv/lib/python3.12/site-packages/sqlalchemy/orm/state_changes.py\", line 139, in _go\n    ret_value = fn(self, *arg, **kw)\n                ^^^^^^^^^^^^^^^^^^^^\n  File \"/Users/Apple/TO-DO project/venv/lib/python3.12/site-packages/sqlalchemy/orm/session.py\", line 1313, in commit\n    self._prepare_impl()\n  File \"<string>\", line 2, in _prepare_impl\n  File \"/Users/Apple/TO-DO project/venv/lib/python3.12/site-packages/sqlalchemy/orm/state_changes.py\", line 139, in _go\n    ret_value = fn(self, *arg, **kw)\n                ^^^^^^^^^^^^^^^^^^^^\n  File \"/Users/Apple/TO-DO project/venv/lib/python3.12/site-packages/sqlalchemy/orm/session.py\", line 1288, in _prepare_impl\n    self.session.flush()\n  File \"/Users/Apple/TO-DO project/venv/lib/python3.12/site-packages/sqlalchemy/orm/session.py\", line 4345, in flush\n    self._flush(objects)\n  File \"/Users/Apple/TO-DO project/venv/lib/python3.12/site-packages/sqlalchemy/orm/session.py\", line 4480, in _flush\n    with util.safe_reraise():\n         ^^^^^^^^^^^^^^^^^^^\n  File \"/Users/Apple/TO-DO project/venv/lib/python3.12/site-packages/sqlalchemy/util/langhelpers.py\", line 224, in __exit__\n    raise exc_value.with_traceback(exc_tb)\n  File \"/Users/Apple/TO-DO project/venv/lib/python3.12/site-packages/sqlalchemy/orm/session.py\", line 4441, in _flush\n    flush_context.execute()\n  File \"/Users/Apple/TO-DO project/venv/lib/python3.12/site-packages/sqlalchemy/orm/unitofwork.py\", line 466, in execute\n    rec.execute(self)\n  File \"/Users/Apple/TO-DO project/venv/lib/python3.12/site-packages/sqlalchemy/orm/unitofwork.py\", line 642, in execute\n    util.preloaded.orm_persistence.save_obj(\n  File \"/Users/Apple/TO-DO project/venv/lib/python3.12/site-packages/sqlalchemy/orm/persistence.py\", line 93, in save_obj\n    _emit_insert_statements(\n  File \"/Users/Apple/TO-DO project/venv/lib/python3.12/site-packages/sqlalchemy/orm/persistence.py\", line 1233, in _emit_insert_statements\n    result = connection.execute(\n             ^^^^^^^^^^^^^^^^^^^\n  File \"/Users/Apple/TO-DO project/venv/lib/python3.12/site-packages/sqlalchemy/engine/base.py\", line 1415, in execute\n    return meth(\n           ^^^^^\n  File \"/Users/Apple/TO-DO project/venv/lib/python3.12/site-packages/sqlalchemy/sql/elements.py\", line 523, in _execute_on_connection\n    return connection._execute_clauseelement(\n           ^^^^^^^^^^^^^^^^^^^^^^^^^^^^^^^^^^\n  File \"/Users/Apple/TO-DO project/venv/lib/python3.12/site-packages/sqlalchemy/engine/base.py\", line 1637, in _execute_clauseelement\n    ret = self._execute_context(\n          ^^^^^^^^^^^^^^^^^^^^^^\n  File \"/Users/Apple/TO-DO project/venv/lib/python3.12/site-packages/sqlalchemy/engine/base.py\", line 1842, in _execute_context\n    return self._exec_single_context(\n           ^^^^^^^^^^^^^^^^^^^^^^^^^^\n  File \"/Users/Apple/TO-DO project/venv/lib/python3.12/site-packages/sqlalchemy/engine/base.py\", line 1982, in _exec_single_context\n    self._handle_dbapi_exception(\n  File \"/Users/Apple/TO-DO project/venv/lib/python3.12/site-packages/sqlalchemy/engine/base.py\", line 2351, in _handle_dbapi_exception\n    raise sqlalchemy_exception.with_traceback(exc_info[2]) from e\n  File \"/Users/Apple/TO-DO project/venv/lib/python3.12/site-packages/sqlalchemy/engine/base.py\", line 1963, in _exec_single_context\n    self.dialect.do_execute(\n  File \"/Users/Apple/TO-DO project/venv/lib/python3.12/site-packages/sqlalchemy/engine/default.py\", line 943, in do_execute\n    cursor.execute(statement, parameters)\n  File \"/Users/Apple/TO-DO project/venv/lib/python3.12/site-packages/sqlalchemy/dialects/postgresql/asyncpg.py\", line 580, in execute\n    self._adapt_connection.await_(\n  File \"/Users/Apple/TO-DO project/venv/lib/python3.12/site-packages/sqlalchemy/util/_concurrency_py3k.py\", line 132, in await_only\n    return current.parent.switch(awaitable)  # type: ignore[no-any-return,attr-defined] # noqa: E501\n           ^^^^^^^^^^^^^^^^^^^^^^^^^^^^^^^^\n  File \"/Users/Apple/TO-DO project/venv/lib/python3.12/site-packages/sqlalchemy/util/_concurrency_py3k.py\", line 196, in greenlet_spawn\n    value = await result\n            ^^^^^^^^^^^^\n  File \"/Users/Apple/TO-DO project/venv/lib/python3.12/site-packages/sqlalchemy/dialects/postgresql/asyncpg.py\", line 558, in _prepare_and_execute\n    self._handle_exception(error)\n  File \"/Users/Apple/TO-DO project/venv/lib/python3.12/site-packages/sqlalchemy/dialects/postgresql/asyncpg.py\", line 508, in _handle_exception\n    self._adapt_connection._handle_exception(error)\n  File \"/Users/Apple/TO-DO project/venv/lib/python3.12/site-packages/sqlalchemy/dialects/postgresql/asyncpg.py\", line 792, in _handle_exception\n    raise translated_error from error\nsqlalchemy.exc.IntegrityError: (sqlalchemy.dialects.postgresql.asyncpg.IntegrityError) <class 'asyncpg.exceptions.NotNullViolationError'>: null value in column \"is_completed\" of relation \"todo_items\" violates not-null constraint\nDETAIL:  Failing row contains (3baf9659-d9f9-420e-a558-260349262f5b, Lock In, It is time to lock in and get it, null, 2025-06-30 09:16:23.417481, 2025-06-30 09:16:23.417487, null).\n[SQL: INSERT INTO todo_items (todo_uid, title, description, created_at, updated_at, user_uid) VALUES ($1::UUID, $2::VARCHAR, $3::VARCHAR, $4::TIMESTAMP WITHOUT TIME ZONE, $5::TIMESTAMP WITHOUT TIME ZONE, $6::UUID)]\n[parameters: (UUID('3baf9659-d9f9-420e-a558-260349262f5b'), 'Lock In', 'It is time to lock in and get it', datetime.datetime(2025, 6, 30, 9, 16, 23, 417481), datetime.datetime(2025, 6, 30, 9, 16, 23, 417487), None)]\n(Background on this error at: https://sqlalche.me/e/20/gkpj)"}
{"asctime": "2025-06-30 09:22:54", "msecs": 920.0, "levelname": "INFO", "name": "uvicorn.error", "lineno": 263, "message": "Shutting down"}
{"asctime": "2025-06-30 09:22:55", "msecs": 42.0, "levelname": "INFO", "name": "uvicorn.error", "lineno": 67, "message": "Waiting for application shutdown."}
{"asctime": "2025-06-30 09:22:55", "msecs": 208.0, "levelname": "INFO", "name": "uvicorn.error", "lineno": 76, "message": "Application shutdown complete."}
{"asctime": "2025-06-30 09:22:55", "msecs": 211.0, "levelname": "INFO", "name": "uvicorn.error", "lineno": 93, "message": "Finished server process [10420]", "color_message": "Finished server process [\u001b[36m%d\u001b[0m]"}
{"asctime": "2025-06-30 09:22:58", "msecs": 510.0, "levelname": "INFO", "name": "src", "lineno": 24, "message": "Logging works!!!"}
{"asctime": "2025-06-30 09:23:02", "msecs": 501.0, "levelname": "INFO", "name": "uvicorn.error", "lineno": 62, "message": "Application startup complete."}
{"asctime": "2025-06-30 09:23:02", "msecs": 506.0, "levelname": "INFO", "name": "uvicorn.error", "lineno": 215, "message": "Uvicorn running on http://127.0.0.1:8000 (Press CTRL+C to quit)", "color_message": "Uvicorn running on \u001b[1m%s://%s:%d\u001b[0m (Press CTRL+C to quit)"}
{"asctime": "2025-06-30 09:23:07", "msecs": 498.0, "levelname": "WARNING", "name": "passlib.handlers.bcrypt", "lineno": 622, "message": "(trapped) error reading bcrypt version", "exc_info": "Traceback (most recent call last):\n  File \"/Users/Apple/TO-DO project/venv/lib/python3.12/site-packages/passlib/handlers/bcrypt.py\", line 620, in _load_backend_mixin\n    version = _bcrypt.__about__.__version__\n              ^^^^^^^^^^^^^^^^^\nAttributeError: module 'bcrypt' has no attribute '__about__'"}
{"asctime": "2025-06-30 09:23:07", "msecs": 506.0, "levelname": "DEBUG", "name": "passlib.handlers.bcrypt", "lineno": 625, "message": "detected 'bcrypt' backend, version '<unknown>'"}
{"asctime": "2025-06-30 09:23:07", "msecs": 508.0, "levelname": "DEBUG", "name": "passlib.handlers.bcrypt", "lineno": 406, "message": "'bcrypt' backend lacks $2$ support, enabling workaround"}
{"asctime": "2025-06-30 09:23:07", "msecs": 962.0, "levelname": "INFO", "name": "uvicorn.access", "lineno": 476, "message": "127.0.0.1:56624 - \"POST /api/v1/auth/login HTTP/1.1\" 200"}
{"asctime": "2025-06-30 09:23:27", "msecs": 436.0, "levelname": "INFO", "name": "uvicorn.access", "lineno": 476, "message": "127.0.0.1:56632 - \"POST /api/v1/todo HTTP/1.1\" 307"}
{"asctime": "2025-06-30 09:23:27", "msecs": 444.0, "levelname": "DEBUG", "name": "src.utils.utils", "lineno": 41, "message": "Decoding Token here"}
{"asctime": "2025-06-30 09:23:27", "msecs": 450.0, "levelname": "INFO", "name": "uvicorn.access", "lineno": 476, "message": "127.0.0.1:56632 - \"POST /api/v1/todo/ HTTP/1.1\" 422"}
{"asctime": "2025-06-30 09:23:57", "msecs": 987.0, "levelname": "INFO", "name": "uvicorn.error", "lineno": 263, "message": "Shutting down"}
{"asctime": "2025-06-30 09:23:58", "msecs": 96.0, "levelname": "INFO", "name": "uvicorn.error", "lineno": 67, "message": "Waiting for application shutdown."}
{"asctime": "2025-06-30 09:23:58", "msecs": 247.0, "levelname": "INFO", "name": "uvicorn.error", "lineno": 76, "message": "Application shutdown complete."}
{"asctime": "2025-06-30 09:23:58", "msecs": 250.0, "levelname": "INFO", "name": "uvicorn.error", "lineno": 93, "message": "Finished server process [11151]", "color_message": "Finished server process [\u001b[36m%d\u001b[0m]"}
{"asctime": "2025-06-30 09:24:00", "msecs": 900.0, "levelname": "INFO", "name": "src", "lineno": 24, "message": "Logging works!!!"}
{"asctime": "2025-06-30 09:24:04", "msecs": 353.0, "levelname": "INFO", "name": "uvicorn.error", "lineno": 62, "message": "Application startup complete."}
{"asctime": "2025-06-30 09:24:04", "msecs": 357.0, "levelname": "INFO", "name": "uvicorn.error", "lineno": 215, "message": "Uvicorn running on http://127.0.0.1:8000 (Press CTRL+C to quit)", "color_message": "Uvicorn running on \u001b[1m%s://%s:%d\u001b[0m (Press CTRL+C to quit)"}
{"asctime": "2025-06-30 09:24:07", "msecs": 545.0, "levelname": "WARNING", "name": "passlib.handlers.bcrypt", "lineno": 622, "message": "(trapped) error reading bcrypt version", "exc_info": "Traceback (most recent call last):\n  File \"/Users/Apple/TO-DO project/venv/lib/python3.12/site-packages/passlib/handlers/bcrypt.py\", line 620, in _load_backend_mixin\n    version = _bcrypt.__about__.__version__\n              ^^^^^^^^^^^^^^^^^\nAttributeError: module 'bcrypt' has no attribute '__about__'"}
{"asctime": "2025-06-30 09:24:07", "msecs": 554.0, "levelname": "DEBUG", "name": "passlib.handlers.bcrypt", "lineno": 625, "message": "detected 'bcrypt' backend, version '<unknown>'"}
{"asctime": "2025-06-30 09:24:07", "msecs": 556.0, "levelname": "DEBUG", "name": "passlib.handlers.bcrypt", "lineno": 406, "message": "'bcrypt' backend lacks $2$ support, enabling workaround"}
{"asctime": "2025-06-30 09:24:07", "msecs": 974.0, "levelname": "INFO", "name": "uvicorn.access", "lineno": 476, "message": "127.0.0.1:56651 - \"POST /api/v1/auth/login HTTP/1.1\" 200"}
{"asctime": "2025-06-30 09:24:23", "msecs": 506.0, "levelname": "INFO", "name": "uvicorn.access", "lineno": 476, "message": "127.0.0.1:56661 - \"POST /api/v1/todo HTTP/1.1\" 307"}
{"asctime": "2025-06-30 09:24:23", "msecs": 514.0, "levelname": "DEBUG", "name": "src.utils.utils", "lineno": 41, "message": "Decoding Token here"}
{"asctime": "2025-06-30 09:24:24", "msecs": 54.0, "levelname": "INFO", "name": "uvicorn.access", "lineno": 476, "message": "127.0.0.1:56661 - \"POST /api/v1/todo/ HTTP/1.1\" 500"}
{"asctime": "2025-06-30 09:24:24", "msecs": 57.0, "levelname": "ERROR", "name": "uvicorn.error", "lineno": 414, "message": "Exception in ASGI application\n", "exc_info": "Traceback (most recent call last):\n  File \"/Users/Apple/TO-DO project/venv/lib/python3.12/site-packages/sqlalchemy/dialects/postgresql/asyncpg.py\", line 545, in _prepare_and_execute\n    self._rows = deque(await prepared_stmt.fetch(*parameters))\n                       ^^^^^^^^^^^^^^^^^^^^^^^^^^^^^^^^^^^^^^\n  File \"/Users/Apple/TO-DO project/venv/lib/python3.12/site-packages/asyncpg/prepared_stmt.py\", line 176, in fetch\n    data = await self.__bind_execute(args, 0, timeout)\n           ^^^^^^^^^^^^^^^^^^^^^^^^^^^^^^^^^^^^^^^^^^^\n  File \"/Users/Apple/TO-DO project/venv/lib/python3.12/site-packages/asyncpg/prepared_stmt.py\", line 267, in __bind_execute\n    data, status, _ = await self.__do_execute(\n                      ^^^^^^^^^^^^^^^^^^^^^^^^\n  File \"/Users/Apple/TO-DO project/venv/lib/python3.12/site-packages/asyncpg/prepared_stmt.py\", line 256, in __do_execute\n    return await executor(protocol)\n           ^^^^^^^^^^^^^^^^^^^^^^^^\n  File \"asyncpg/protocol/protocol.pyx\", line 206, in bind_execute\nasyncpg.exceptions.NotNullViolationError: null value in column \"is_completed\" of relation \"todo_items\" violates not-null constraint\nDETAIL:  Failing row contains (a79925cc-d707-4bd5-a1b3-2f48525840d8, Lock In, It is time to lock in and get it, null, 2025-06-30 09:24:23.521295, 2025-06-30 09:24:23.521301, null).\n\nThe above exception was the direct cause of the following exception:\n\nTraceback (most recent call last):\n  File \"/Users/Apple/TO-DO project/venv/lib/python3.12/site-packages/sqlalchemy/engine/base.py\", line 1963, in _exec_single_context\n    self.dialect.do_execute(\n  File \"/Users/Apple/TO-DO project/venv/lib/python3.12/site-packages/sqlalchemy/engine/default.py\", line 943, in do_execute\n    cursor.execute(statement, parameters)\n  File \"/Users/Apple/TO-DO project/venv/lib/python3.12/site-packages/sqlalchemy/dialects/postgresql/asyncpg.py\", line 580, in execute\n    self._adapt_connection.await_(\n  File \"/Users/Apple/TO-DO project/venv/lib/python3.12/site-packages/sqlalchemy/util/_concurrency_py3k.py\", line 132, in await_only\n    return current.parent.switch(awaitable)  # type: ignore[no-any-return,attr-defined] # noqa: E501\n           ^^^^^^^^^^^^^^^^^^^^^^^^^^^^^^^^\n  File \"/Users/Apple/TO-DO project/venv/lib/python3.12/site-packages/sqlalchemy/util/_concurrency_py3k.py\", line 196, in greenlet_spawn\n    value = await result\n            ^^^^^^^^^^^^\n  File \"/Users/Apple/TO-DO project/venv/lib/python3.12/site-packages/sqlalchemy/dialects/postgresql/asyncpg.py\", line 558, in _prepare_and_execute\n    self._handle_exception(error)\n  File \"/Users/Apple/TO-DO project/venv/lib/python3.12/site-packages/sqlalchemy/dialects/postgresql/asyncpg.py\", line 508, in _handle_exception\n    self._adapt_connection._handle_exception(error)\n  File \"/Users/Apple/TO-DO project/venv/lib/python3.12/site-packages/sqlalchemy/dialects/postgresql/asyncpg.py\", line 792, in _handle_exception\n    raise translated_error from error\nsqlalchemy.dialects.postgresql.asyncpg.AsyncAdapt_asyncpg_dbapi.IntegrityError: <class 'asyncpg.exceptions.NotNullViolationError'>: null value in column \"is_completed\" of relation \"todo_items\" violates not-null constraint\nDETAIL:  Failing row contains (a79925cc-d707-4bd5-a1b3-2f48525840d8, Lock In, It is time to lock in and get it, null, 2025-06-30 09:24:23.521295, 2025-06-30 09:24:23.521301, null).\n\nThe above exception was the direct cause of the following exception:\n\nTraceback (most recent call last):\n  File \"/Users/Apple/TO-DO project/venv/lib/python3.12/site-packages/uvicorn/protocols/http/httptools_impl.py\", line 409, in run_asgi\n    result = await app(  # type: ignore[func-returns-value]\n             ^^^^^^^^^^^^^^^^^^^^^^^^^^^^^^^^^^^^^^^^^^^^^^\n  File \"/Users/Apple/TO-DO project/venv/lib/python3.12/site-packages/uvicorn/middleware/proxy_headers.py\", line 60, in __call__\n    return await self.app(scope, receive, send)\n           ^^^^^^^^^^^^^^^^^^^^^^^^^^^^^^^^^^^^\n  File \"/Users/Apple/TO-DO project/venv/lib/python3.12/site-packages/fastapi/applications.py\", line 1054, in __call__\n    await super().__call__(scope, receive, send)\n  File \"/Users/Apple/TO-DO project/venv/lib/python3.12/site-packages/starlette/applications.py\", line 112, in __call__\n    await self.middleware_stack(scope, receive, send)\n  File \"/Users/Apple/TO-DO project/venv/lib/python3.12/site-packages/starlette/middleware/errors.py\", line 187, in __call__\n    raise exc\n  File \"/Users/Apple/TO-DO project/venv/lib/python3.12/site-packages/starlette/middleware/errors.py\", line 165, in __call__\n    await self.app(scope, receive, _send)\n  File \"/Users/Apple/TO-DO project/venv/lib/python3.12/site-packages/starlette/middleware/exceptions.py\", line 62, in __call__\n    await wrap_app_handling_exceptions(self.app, conn)(scope, receive, send)\n  File \"/Users/Apple/TO-DO project/venv/lib/python3.12/site-packages/starlette/_exception_handler.py\", line 53, in wrapped_app\n    raise exc\n  File \"/Users/Apple/TO-DO project/venv/lib/python3.12/site-packages/starlette/_exception_handler.py\", line 42, in wrapped_app\n    await app(scope, receive, sender)\n  File \"/Users/Apple/TO-DO project/venv/lib/python3.12/site-packages/starlette/routing.py\", line 714, in __call__\n    await self.middleware_stack(scope, receive, send)\n  File \"/Users/Apple/TO-DO project/venv/lib/python3.12/site-packages/starlette/routing.py\", line 734, in app\n    await route.handle(scope, receive, send)\n  File \"/Users/Apple/TO-DO project/venv/lib/python3.12/site-packages/starlette/routing.py\", line 288, in handle\n    await self.app(scope, receive, send)\n  File \"/Users/Apple/TO-DO project/venv/lib/python3.12/site-packages/starlette/routing.py\", line 76, in app\n    await wrap_app_handling_exceptions(app, request)(scope, receive, send)\n  File \"/Users/Apple/TO-DO project/venv/lib/python3.12/site-packages/starlette/_exception_handler.py\", line 53, in wrapped_app\n    raise exc\n  File \"/Users/Apple/TO-DO project/venv/lib/python3.12/site-packages/starlette/_exception_handler.py\", line 42, in wrapped_app\n    await app(scope, receive, sender)\n  File \"/Users/Apple/TO-DO project/venv/lib/python3.12/site-packages/starlette/routing.py\", line 73, in app\n    response = await f(request)\n               ^^^^^^^^^^^^^^^^\n  File \"/Users/Apple/TO-DO project/venv/lib/python3.12/site-packages/fastapi/routing.py\", line 301, in app\n    raw_response = await run_endpoint_function(\n                   ^^^^^^^^^^^^^^^^^^^^^^^^^^^^\n  File \"/Users/Apple/TO-DO project/venv/lib/python3.12/site-packages/fastapi/routing.py\", line 212, in run_endpoint_function\n    return await dependant.call(**values)\n           ^^^^^^^^^^^^^^^^^^^^^^^^^^^^^^\n  File \"/Users/Apple/TO-DO project/src/v1/routes/todo.py\", line 26, in create_todo\n    todo = await todo_service.create_todo(todo_data=todo_data, session=session)\n           ^^^^^^^^^^^^^^^^^^^^^^^^^^^^^^^^^^^^^^^^^^^^^^^^^^^^^^^^^^^^^^^^^^^^\n  File \"/Users/Apple/TO-DO project/src/v1/service/todo.py\", line 21, in create_todo\n    await session.commit()\n  File \"/Users/Apple/TO-DO project/venv/lib/python3.12/site-packages/sqlalchemy/ext/asyncio/session.py\", line 1014, in commit\n    await greenlet_spawn(self.sync_session.commit)\n  File \"/Users/Apple/TO-DO project/venv/lib/python3.12/site-packages/sqlalchemy/util/_concurrency_py3k.py\", line 203, in greenlet_spawn\n    result = context.switch(value)\n             ^^^^^^^^^^^^^^^^^^^^^\n  File \"/Users/Apple/TO-DO project/venv/lib/python3.12/site-packages/sqlalchemy/orm/session.py\", line 2032, in commit\n    trans.commit(_to_root=True)\n  File \"<string>\", line 2, in commit\n  File \"/Users/Apple/TO-DO project/venv/lib/python3.12/site-packages/sqlalchemy/orm/state_changes.py\", line 139, in _go\n    ret_value = fn(self, *arg, **kw)\n                ^^^^^^^^^^^^^^^^^^^^\n  File \"/Users/Apple/TO-DO project/venv/lib/python3.12/site-packages/sqlalchemy/orm/session.py\", line 1313, in commit\n    self._prepare_impl()\n  File \"<string>\", line 2, in _prepare_impl\n  File \"/Users/Apple/TO-DO project/venv/lib/python3.12/site-packages/sqlalchemy/orm/state_changes.py\", line 139, in _go\n    ret_value = fn(self, *arg, **kw)\n                ^^^^^^^^^^^^^^^^^^^^\n  File \"/Users/Apple/TO-DO project/venv/lib/python3.12/site-packages/sqlalchemy/orm/session.py\", line 1288, in _prepare_impl\n    self.session.flush()\n  File \"/Users/Apple/TO-DO project/venv/lib/python3.12/site-packages/sqlalchemy/orm/session.py\", line 4345, in flush\n    self._flush(objects)\n  File \"/Users/Apple/TO-DO project/venv/lib/python3.12/site-packages/sqlalchemy/orm/session.py\", line 4480, in _flush\n    with util.safe_reraise():\n         ^^^^^^^^^^^^^^^^^^^\n  File \"/Users/Apple/TO-DO project/venv/lib/python3.12/site-packages/sqlalchemy/util/langhelpers.py\", line 224, in __exit__\n    raise exc_value.with_traceback(exc_tb)\n  File \"/Users/Apple/TO-DO project/venv/lib/python3.12/site-packages/sqlalchemy/orm/session.py\", line 4441, in _flush\n    flush_context.execute()\n  File \"/Users/Apple/TO-DO project/venv/lib/python3.12/site-packages/sqlalchemy/orm/unitofwork.py\", line 466, in execute\n    rec.execute(self)\n  File \"/Users/Apple/TO-DO project/venv/lib/python3.12/site-packages/sqlalchemy/orm/unitofwork.py\", line 642, in execute\n    util.preloaded.orm_persistence.save_obj(\n  File \"/Users/Apple/TO-DO project/venv/lib/python3.12/site-packages/sqlalchemy/orm/persistence.py\", line 93, in save_obj\n    _emit_insert_statements(\n  File \"/Users/Apple/TO-DO project/venv/lib/python3.12/site-packages/sqlalchemy/orm/persistence.py\", line 1233, in _emit_insert_statements\n    result = connection.execute(\n             ^^^^^^^^^^^^^^^^^^^\n  File \"/Users/Apple/TO-DO project/venv/lib/python3.12/site-packages/sqlalchemy/engine/base.py\", line 1415, in execute\n    return meth(\n           ^^^^^\n  File \"/Users/Apple/TO-DO project/venv/lib/python3.12/site-packages/sqlalchemy/sql/elements.py\", line 523, in _execute_on_connection\n    return connection._execute_clauseelement(\n           ^^^^^^^^^^^^^^^^^^^^^^^^^^^^^^^^^^\n  File \"/Users/Apple/TO-DO project/venv/lib/python3.12/site-packages/sqlalchemy/engine/base.py\", line 1637, in _execute_clauseelement\n    ret = self._execute_context(\n          ^^^^^^^^^^^^^^^^^^^^^^\n  File \"/Users/Apple/TO-DO project/venv/lib/python3.12/site-packages/sqlalchemy/engine/base.py\", line 1842, in _execute_context\n    return self._exec_single_context(\n           ^^^^^^^^^^^^^^^^^^^^^^^^^^\n  File \"/Users/Apple/TO-DO project/venv/lib/python3.12/site-packages/sqlalchemy/engine/base.py\", line 1982, in _exec_single_context\n    self._handle_dbapi_exception(\n  File \"/Users/Apple/TO-DO project/venv/lib/python3.12/site-packages/sqlalchemy/engine/base.py\", line 2351, in _handle_dbapi_exception\n    raise sqlalchemy_exception.with_traceback(exc_info[2]) from e\n  File \"/Users/Apple/TO-DO project/venv/lib/python3.12/site-packages/sqlalchemy/engine/base.py\", line 1963, in _exec_single_context\n    self.dialect.do_execute(\n  File \"/Users/Apple/TO-DO project/venv/lib/python3.12/site-packages/sqlalchemy/engine/default.py\", line 943, in do_execute\n    cursor.execute(statement, parameters)\n  File \"/Users/Apple/TO-DO project/venv/lib/python3.12/site-packages/sqlalchemy/dialects/postgresql/asyncpg.py\", line 580, in execute\n    self._adapt_connection.await_(\n  File \"/Users/Apple/TO-DO project/venv/lib/python3.12/site-packages/sqlalchemy/util/_concurrency_py3k.py\", line 132, in await_only\n    return current.parent.switch(awaitable)  # type: ignore[no-any-return,attr-defined] # noqa: E501\n           ^^^^^^^^^^^^^^^^^^^^^^^^^^^^^^^^\n  File \"/Users/Apple/TO-DO project/venv/lib/python3.12/site-packages/sqlalchemy/util/_concurrency_py3k.py\", line 196, in greenlet_spawn\n    value = await result\n            ^^^^^^^^^^^^\n  File \"/Users/Apple/TO-DO project/venv/lib/python3.12/site-packages/sqlalchemy/dialects/postgresql/asyncpg.py\", line 558, in _prepare_and_execute\n    self._handle_exception(error)\n  File \"/Users/Apple/TO-DO project/venv/lib/python3.12/site-packages/sqlalchemy/dialects/postgresql/asyncpg.py\", line 508, in _handle_exception\n    self._adapt_connection._handle_exception(error)\n  File \"/Users/Apple/TO-DO project/venv/lib/python3.12/site-packages/sqlalchemy/dialects/postgresql/asyncpg.py\", line 792, in _handle_exception\n    raise translated_error from error\nsqlalchemy.exc.IntegrityError: (sqlalchemy.dialects.postgresql.asyncpg.IntegrityError) <class 'asyncpg.exceptions.NotNullViolationError'>: null value in column \"is_completed\" of relation \"todo_items\" violates not-null constraint\nDETAIL:  Failing row contains (a79925cc-d707-4bd5-a1b3-2f48525840d8, Lock In, It is time to lock in and get it, null, 2025-06-30 09:24:23.521295, 2025-06-30 09:24:23.521301, null).\n[SQL: INSERT INTO todo_items (todo_uid, title, description, created_at, updated_at, user_uid) VALUES ($1::UUID, $2::VARCHAR, $3::VARCHAR, $4::TIMESTAMP WITHOUT TIME ZONE, $5::TIMESTAMP WITHOUT TIME ZONE, $6::UUID)]\n[parameters: (UUID('a79925cc-d707-4bd5-a1b3-2f48525840d8'), 'Lock In', 'It is time to lock in and get it', datetime.datetime(2025, 6, 30, 9, 24, 23, 521295), datetime.datetime(2025, 6, 30, 9, 24, 23, 521301), None)]\n(Background on this error at: https://sqlalche.me/e/20/gkpj)"}
{"asctime": "2025-06-30 09:32:52", "msecs": 169.0, "levelname": "INFO", "name": "uvicorn.access", "lineno": 476, "message": "127.0.0.1:56875 - \"POST /api/v1/auth/login HTTP/1.1\" 200"}
{"asctime": "2025-06-30 09:32:59", "msecs": 479.0, "levelname": "INFO", "name": "uvicorn.error", "lineno": 263, "message": "Shutting down"}
{"asctime": "2025-06-30 09:32:59", "msecs": 588.0, "levelname": "INFO", "name": "uvicorn.error", "lineno": 67, "message": "Waiting for application shutdown."}
{"asctime": "2025-06-30 09:32:59", "msecs": 754.0, "levelname": "INFO", "name": "uvicorn.error", "lineno": 76, "message": "Application shutdown complete."}
{"asctime": "2025-06-30 09:32:59", "msecs": 757.0, "levelname": "INFO", "name": "uvicorn.error", "lineno": 93, "message": "Finished server process [11235]", "color_message": "Finished server process [\u001b[36m%d\u001b[0m]"}
{"asctime": "2025-06-30 09:33:03", "msecs": 458.0, "levelname": "INFO", "name": "src", "lineno": 24, "message": "Logging works!!!"}
{"asctime": "2025-06-30 09:33:07", "msecs": 273.0, "levelname": "INFO", "name": "uvicorn.error", "lineno": 62, "message": "Application startup complete."}
{"asctime": "2025-06-30 09:33:07", "msecs": 279.0, "levelname": "INFO", "name": "uvicorn.error", "lineno": 215, "message": "Uvicorn running on http://127.0.0.1:8000 (Press CTRL+C to quit)", "color_message": "Uvicorn running on \u001b[1m%s://%s:%d\u001b[0m (Press CTRL+C to quit)"}
{"asctime": "2025-06-30 09:33:24", "msecs": 57.0, "levelname": "WARNING", "name": "passlib.handlers.bcrypt", "lineno": 622, "message": "(trapped) error reading bcrypt version", "exc_info": "Traceback (most recent call last):\n  File \"/Users/Apple/TO-DO project/venv/lib/python3.12/site-packages/passlib/handlers/bcrypt.py\", line 620, in _load_backend_mixin\n    version = _bcrypt.__about__.__version__\n              ^^^^^^^^^^^^^^^^^\nAttributeError: module 'bcrypt' has no attribute '__about__'"}
{"asctime": "2025-06-30 09:33:24", "msecs": 67.0, "levelname": "DEBUG", "name": "passlib.handlers.bcrypt", "lineno": 625, "message": "detected 'bcrypt' backend, version '<unknown>'"}
{"asctime": "2025-06-30 09:33:24", "msecs": 69.0, "levelname": "DEBUG", "name": "passlib.handlers.bcrypt", "lineno": 406, "message": "'bcrypt' backend lacks $2$ support, enabling workaround"}
{"asctime": "2025-06-30 09:33:24", "msecs": 493.0, "levelname": "INFO", "name": "uvicorn.access", "lineno": 476, "message": "127.0.0.1:56887 - \"POST /api/v1/auth/login HTTP/1.1\" 200"}
{"asctime": "2025-06-30 09:33:39", "msecs": 195.0, "levelname": "INFO", "name": "uvicorn.access", "lineno": 476, "message": "127.0.0.1:56893 - \"POST /api/v1/todo HTTP/1.1\" 307"}
{"asctime": "2025-06-30 09:33:39", "msecs": 233.0, "levelname": "DEBUG", "name": "src.utils.utils", "lineno": 41, "message": "Decoding Token here"}
{"asctime": "2025-06-30 09:33:39", "msecs": 236.0, "levelname": "INFO", "name": "uvicorn.access", "lineno": 476, "message": "127.0.0.1:56893 - \"POST /api/v1/todo/ HTTP/1.1\" 500"}
{"asctime": "2025-06-30 09:33:39", "msecs": 239.0, "levelname": "ERROR", "name": "uvicorn.error", "lineno": 414, "message": "Exception in ASGI application\n", "exc_info": "Traceback (most recent call last):\n  File \"/Users/Apple/TO-DO project/venv/lib/python3.12/site-packages/uvicorn/protocols/http/httptools_impl.py\", line 409, in run_asgi\n    result = await app(  # type: ignore[func-returns-value]\n             ^^^^^^^^^^^^^^^^^^^^^^^^^^^^^^^^^^^^^^^^^^^^^^\n  File \"/Users/Apple/TO-DO project/venv/lib/python3.12/site-packages/uvicorn/middleware/proxy_headers.py\", line 60, in __call__\n    return await self.app(scope, receive, send)\n           ^^^^^^^^^^^^^^^^^^^^^^^^^^^^^^^^^^^^\n  File \"/Users/Apple/TO-DO project/venv/lib/python3.12/site-packages/fastapi/applications.py\", line 1054, in __call__\n    await super().__call__(scope, receive, send)\n  File \"/Users/Apple/TO-DO project/venv/lib/python3.12/site-packages/starlette/applications.py\", line 112, in __call__\n    await self.middleware_stack(scope, receive, send)\n  File \"/Users/Apple/TO-DO project/venv/lib/python3.12/site-packages/starlette/middleware/errors.py\", line 187, in __call__\n    raise exc\n  File \"/Users/Apple/TO-DO project/venv/lib/python3.12/site-packages/starlette/middleware/errors.py\", line 165, in __call__\n    await self.app(scope, receive, _send)\n  File \"/Users/Apple/TO-DO project/venv/lib/python3.12/site-packages/starlette/middleware/exceptions.py\", line 62, in __call__\n    await wrap_app_handling_exceptions(self.app, conn)(scope, receive, send)\n  File \"/Users/Apple/TO-DO project/venv/lib/python3.12/site-packages/starlette/_exception_handler.py\", line 53, in wrapped_app\n    raise exc\n  File \"/Users/Apple/TO-DO project/venv/lib/python3.12/site-packages/starlette/_exception_handler.py\", line 42, in wrapped_app\n    await app(scope, receive, sender)\n  File \"/Users/Apple/TO-DO project/venv/lib/python3.12/site-packages/starlette/routing.py\", line 714, in __call__\n    await self.middleware_stack(scope, receive, send)\n  File \"/Users/Apple/TO-DO project/venv/lib/python3.12/site-packages/starlette/routing.py\", line 734, in app\n    await route.handle(scope, receive, send)\n  File \"/Users/Apple/TO-DO project/venv/lib/python3.12/site-packages/starlette/routing.py\", line 288, in handle\n    await self.app(scope, receive, send)\n  File \"/Users/Apple/TO-DO project/venv/lib/python3.12/site-packages/starlette/routing.py\", line 76, in app\n    await wrap_app_handling_exceptions(app, request)(scope, receive, send)\n  File \"/Users/Apple/TO-DO project/venv/lib/python3.12/site-packages/starlette/_exception_handler.py\", line 53, in wrapped_app\n    raise exc\n  File \"/Users/Apple/TO-DO project/venv/lib/python3.12/site-packages/starlette/_exception_handler.py\", line 42, in wrapped_app\n    await app(scope, receive, sender)\n  File \"/Users/Apple/TO-DO project/venv/lib/python3.12/site-packages/starlette/routing.py\", line 73, in app\n    response = await f(request)\n               ^^^^^^^^^^^^^^^^\n  File \"/Users/Apple/TO-DO project/venv/lib/python3.12/site-packages/fastapi/routing.py\", line 301, in app\n    raw_response = await run_endpoint_function(\n                   ^^^^^^^^^^^^^^^^^^^^^^^^^^^^\n  File \"/Users/Apple/TO-DO project/venv/lib/python3.12/site-packages/fastapi/routing.py\", line 212, in run_endpoint_function\n    return await dependant.call(**values)\n           ^^^^^^^^^^^^^^^^^^^^^^^^^^^^^^\n  File \"/Users/Apple/TO-DO project/src/v1/routes/todo.py\", line 26, in create_todo\n    user_uid = token_details.get(\"user\")[\"user_uid\"]\n               ~~~~~~~~~~~~~~~~~~~~~~~~~^^^^^^^^^^^^\nKeyError: 'user_uid'"}
{"asctime": "2025-06-30 09:34:53", "msecs": 961.0, "levelname": "INFO", "name": "uvicorn.error", "lineno": 263, "message": "Shutting down"}
{"asctime": "2025-06-30 09:34:54", "msecs": 74.0, "levelname": "INFO", "name": "uvicorn.error", "lineno": 67, "message": "Waiting for application shutdown."}
{"asctime": "2025-06-30 09:34:54", "msecs": 270.0, "levelname": "INFO", "name": "uvicorn.error", "lineno": 76, "message": "Application shutdown complete."}
{"asctime": "2025-06-30 09:34:54", "msecs": 273.0, "levelname": "INFO", "name": "uvicorn.error", "lineno": 93, "message": "Finished server process [11836]", "color_message": "Finished server process [\u001b[36m%d\u001b[0m]"}
{"asctime": "2025-06-30 09:35:01", "msecs": 745.0, "levelname": "INFO", "name": "src", "lineno": 24, "message": "Logging works!!!"}
{"asctime": "2025-06-30 09:35:05", "msecs": 758.0, "levelname": "INFO", "name": "uvicorn.error", "lineno": 62, "message": "Application startup complete."}
{"asctime": "2025-06-30 09:35:05", "msecs": 763.0, "levelname": "INFO", "name": "uvicorn.error", "lineno": 215, "message": "Uvicorn running on http://127.0.0.1:8000 (Press CTRL+C to quit)", "color_message": "Uvicorn running on \u001b[1m%s://%s:%d\u001b[0m (Press CTRL+C to quit)"}
{"asctime": "2025-06-30 09:35:09", "msecs": 637.0, "levelname": "WARNING", "name": "passlib.handlers.bcrypt", "lineno": 622, "message": "(trapped) error reading bcrypt version", "exc_info": "Traceback (most recent call last):\n  File \"/Users/Apple/TO-DO project/venv/lib/python3.12/site-packages/passlib/handlers/bcrypt.py\", line 620, in _load_backend_mixin\n    version = _bcrypt.__about__.__version__\n              ^^^^^^^^^^^^^^^^^\nAttributeError: module 'bcrypt' has no attribute '__about__'"}
{"asctime": "2025-06-30 09:35:09", "msecs": 645.0, "levelname": "DEBUG", "name": "passlib.handlers.bcrypt", "lineno": 625, "message": "detected 'bcrypt' backend, version '<unknown>'"}
{"asctime": "2025-06-30 09:35:09", "msecs": 647.0, "levelname": "DEBUG", "name": "passlib.handlers.bcrypt", "lineno": 406, "message": "'bcrypt' backend lacks $2$ support, enabling workaround"}
{"asctime": "2025-06-30 09:35:10", "msecs": 70.0, "levelname": "INFO", "name": "uvicorn.access", "lineno": 476, "message": "127.0.0.1:56940 - \"POST /api/v1/auth/login HTTP/1.1\" 200"}
{"asctime": "2025-06-30 09:35:22", "msecs": 296.0, "levelname": "INFO", "name": "uvicorn.access", "lineno": 476, "message": "127.0.0.1:56945 - \"POST /api/v1/todo HTTP/1.1\" 307"}
{"asctime": "2025-06-30 09:35:22", "msecs": 305.0, "levelname": "DEBUG", "name": "src.utils.utils", "lineno": 41, "message": "Decoding Token here"}
{"asctime": "2025-06-30 09:35:22", "msecs": 873.0, "levelname": "INFO", "name": "uvicorn.access", "lineno": 476, "message": "127.0.0.1:56945 - \"POST /api/v1/todo/ HTTP/1.1\" 500"}
{"asctime": "2025-06-30 09:35:22", "msecs": 876.0, "levelname": "ERROR", "name": "uvicorn.error", "lineno": 414, "message": "Exception in ASGI application\n", "exc_info": "Traceback (most recent call last):\n  File \"/Users/Apple/TO-DO project/venv/lib/python3.12/site-packages/sqlalchemy/dialects/postgresql/asyncpg.py\", line 545, in _prepare_and_execute\n    self._rows = deque(await prepared_stmt.fetch(*parameters))\n                       ^^^^^^^^^^^^^^^^^^^^^^^^^^^^^^^^^^^^^^\n  File \"/Users/Apple/TO-DO project/venv/lib/python3.12/site-packages/asyncpg/prepared_stmt.py\", line 176, in fetch\n    data = await self.__bind_execute(args, 0, timeout)\n           ^^^^^^^^^^^^^^^^^^^^^^^^^^^^^^^^^^^^^^^^^^^\n  File \"/Users/Apple/TO-DO project/venv/lib/python3.12/site-packages/asyncpg/prepared_stmt.py\", line 267, in __bind_execute\n    data, status, _ = await self.__do_execute(\n                      ^^^^^^^^^^^^^^^^^^^^^^^^\n  File \"/Users/Apple/TO-DO project/venv/lib/python3.12/site-packages/asyncpg/prepared_stmt.py\", line 256, in __do_execute\n    return await executor(protocol)\n           ^^^^^^^^^^^^^^^^^^^^^^^^\n  File \"asyncpg/protocol/protocol.pyx\", line 206, in bind_execute\nasyncpg.exceptions.NotNullViolationError: null value in column \"is_completed\" of relation \"todo_items\" violates not-null constraint\nDETAIL:  Failing row contains (1a36ab41-2b8a-4d3f-a29e-29ec548d9de2, Lock In, It is time to lock in and get it, null, 2025-06-30 09:35:22.326184, 2025-06-30 09:35:22.32619, null).\n\nThe above exception was the direct cause of the following exception:\n\nTraceback (most recent call last):\n  File \"/Users/Apple/TO-DO project/venv/lib/python3.12/site-packages/sqlalchemy/engine/base.py\", line 1963, in _exec_single_context\n    self.dialect.do_execute(\n  File \"/Users/Apple/TO-DO project/venv/lib/python3.12/site-packages/sqlalchemy/engine/default.py\", line 943, in do_execute\n    cursor.execute(statement, parameters)\n  File \"/Users/Apple/TO-DO project/venv/lib/python3.12/site-packages/sqlalchemy/dialects/postgresql/asyncpg.py\", line 580, in execute\n    self._adapt_connection.await_(\n  File \"/Users/Apple/TO-DO project/venv/lib/python3.12/site-packages/sqlalchemy/util/_concurrency_py3k.py\", line 132, in await_only\n    return current.parent.switch(awaitable)  # type: ignore[no-any-return,attr-defined] # noqa: E501\n           ^^^^^^^^^^^^^^^^^^^^^^^^^^^^^^^^\n  File \"/Users/Apple/TO-DO project/venv/lib/python3.12/site-packages/sqlalchemy/util/_concurrency_py3k.py\", line 196, in greenlet_spawn\n    value = await result\n            ^^^^^^^^^^^^\n  File \"/Users/Apple/TO-DO project/venv/lib/python3.12/site-packages/sqlalchemy/dialects/postgresql/asyncpg.py\", line 558, in _prepare_and_execute\n    self._handle_exception(error)\n  File \"/Users/Apple/TO-DO project/venv/lib/python3.12/site-packages/sqlalchemy/dialects/postgresql/asyncpg.py\", line 508, in _handle_exception\n    self._adapt_connection._handle_exception(error)\n  File \"/Users/Apple/TO-DO project/venv/lib/python3.12/site-packages/sqlalchemy/dialects/postgresql/asyncpg.py\", line 792, in _handle_exception\n    raise translated_error from error\nsqlalchemy.dialects.postgresql.asyncpg.AsyncAdapt_asyncpg_dbapi.IntegrityError: <class 'asyncpg.exceptions.NotNullViolationError'>: null value in column \"is_completed\" of relation \"todo_items\" violates not-null constraint\nDETAIL:  Failing row contains (1a36ab41-2b8a-4d3f-a29e-29ec548d9de2, Lock In, It is time to lock in and get it, null, 2025-06-30 09:35:22.326184, 2025-06-30 09:35:22.32619, null).\n\nThe above exception was the direct cause of the following exception:\n\nTraceback (most recent call last):\n  File \"/Users/Apple/TO-DO project/venv/lib/python3.12/site-packages/uvicorn/protocols/http/httptools_impl.py\", line 409, in run_asgi\n    result = await app(  # type: ignore[func-returns-value]\n             ^^^^^^^^^^^^^^^^^^^^^^^^^^^^^^^^^^^^^^^^^^^^^^\n  File \"/Users/Apple/TO-DO project/venv/lib/python3.12/site-packages/uvicorn/middleware/proxy_headers.py\", line 60, in __call__\n    return await self.app(scope, receive, send)\n           ^^^^^^^^^^^^^^^^^^^^^^^^^^^^^^^^^^^^\n  File \"/Users/Apple/TO-DO project/venv/lib/python3.12/site-packages/fastapi/applications.py\", line 1054, in __call__\n    await super().__call__(scope, receive, send)\n  File \"/Users/Apple/TO-DO project/venv/lib/python3.12/site-packages/starlette/applications.py\", line 112, in __call__\n    await self.middleware_stack(scope, receive, send)\n  File \"/Users/Apple/TO-DO project/venv/lib/python3.12/site-packages/starlette/middleware/errors.py\", line 187, in __call__\n    raise exc\n  File \"/Users/Apple/TO-DO project/venv/lib/python3.12/site-packages/starlette/middleware/errors.py\", line 165, in __call__\n    await self.app(scope, receive, _send)\n  File \"/Users/Apple/TO-DO project/venv/lib/python3.12/site-packages/starlette/middleware/exceptions.py\", line 62, in __call__\n    await wrap_app_handling_exceptions(self.app, conn)(scope, receive, send)\n  File \"/Users/Apple/TO-DO project/venv/lib/python3.12/site-packages/starlette/_exception_handler.py\", line 53, in wrapped_app\n    raise exc\n  File \"/Users/Apple/TO-DO project/venv/lib/python3.12/site-packages/starlette/_exception_handler.py\", line 42, in wrapped_app\n    await app(scope, receive, sender)\n  File \"/Users/Apple/TO-DO project/venv/lib/python3.12/site-packages/starlette/routing.py\", line 714, in __call__\n    await self.middleware_stack(scope, receive, send)\n  File \"/Users/Apple/TO-DO project/venv/lib/python3.12/site-packages/starlette/routing.py\", line 734, in app\n    await route.handle(scope, receive, send)\n  File \"/Users/Apple/TO-DO project/venv/lib/python3.12/site-packages/starlette/routing.py\", line 288, in handle\n    await self.app(scope, receive, send)\n  File \"/Users/Apple/TO-DO project/venv/lib/python3.12/site-packages/starlette/routing.py\", line 76, in app\n    await wrap_app_handling_exceptions(app, request)(scope, receive, send)\n  File \"/Users/Apple/TO-DO project/venv/lib/python3.12/site-packages/starlette/_exception_handler.py\", line 53, in wrapped_app\n    raise exc\n  File \"/Users/Apple/TO-DO project/venv/lib/python3.12/site-packages/starlette/_exception_handler.py\", line 42, in wrapped_app\n    await app(scope, receive, sender)\n  File \"/Users/Apple/TO-DO project/venv/lib/python3.12/site-packages/starlette/routing.py\", line 73, in app\n    response = await f(request)\n               ^^^^^^^^^^^^^^^^\n  File \"/Users/Apple/TO-DO project/venv/lib/python3.12/site-packages/fastapi/routing.py\", line 301, in app\n    raw_response = await run_endpoint_function(\n                   ^^^^^^^^^^^^^^^^^^^^^^^^^^^^\n  File \"/Users/Apple/TO-DO project/venv/lib/python3.12/site-packages/fastapi/routing.py\", line 212, in run_endpoint_function\n    return await dependant.call(**values)\n           ^^^^^^^^^^^^^^^^^^^^^^^^^^^^^^\n  File \"/Users/Apple/TO-DO project/src/v1/routes/todo.py\", line 27, in create_todo\n    todo = await todo_service.create_todo(todo_data=todo_data, user_uid=user_uid, session=session)\n           ^^^^^^^^^^^^^^^^^^^^^^^^^^^^^^^^^^^^^^^^^^^^^^^^^^^^^^^^^^^^^^^^^^^^^^^^^^^^^^^^^^^^^^^\n  File \"/Users/Apple/TO-DO project/src/v1/service/todo.py\", line 21, in create_todo\n    await session.commit()\n  File \"/Users/Apple/TO-DO project/venv/lib/python3.12/site-packages/sqlalchemy/ext/asyncio/session.py\", line 1014, in commit\n    await greenlet_spawn(self.sync_session.commit)\n  File \"/Users/Apple/TO-DO project/venv/lib/python3.12/site-packages/sqlalchemy/util/_concurrency_py3k.py\", line 203, in greenlet_spawn\n    result = context.switch(value)\n             ^^^^^^^^^^^^^^^^^^^^^\n  File \"/Users/Apple/TO-DO project/venv/lib/python3.12/site-packages/sqlalchemy/orm/session.py\", line 2032, in commit\n    trans.commit(_to_root=True)\n  File \"<string>\", line 2, in commit\n  File \"/Users/Apple/TO-DO project/venv/lib/python3.12/site-packages/sqlalchemy/orm/state_changes.py\", line 139, in _go\n    ret_value = fn(self, *arg, **kw)\n                ^^^^^^^^^^^^^^^^^^^^\n  File \"/Users/Apple/TO-DO project/venv/lib/python3.12/site-packages/sqlalchemy/orm/session.py\", line 1313, in commit\n    self._prepare_impl()\n  File \"<string>\", line 2, in _prepare_impl\n  File \"/Users/Apple/TO-DO project/venv/lib/python3.12/site-packages/sqlalchemy/orm/state_changes.py\", line 139, in _go\n    ret_value = fn(self, *arg, **kw)\n                ^^^^^^^^^^^^^^^^^^^^\n  File \"/Users/Apple/TO-DO project/venv/lib/python3.12/site-packages/sqlalchemy/orm/session.py\", line 1288, in _prepare_impl\n    self.session.flush()\n  File \"/Users/Apple/TO-DO project/venv/lib/python3.12/site-packages/sqlalchemy/orm/session.py\", line 4345, in flush\n    self._flush(objects)\n  File \"/Users/Apple/TO-DO project/venv/lib/python3.12/site-packages/sqlalchemy/orm/session.py\", line 4480, in _flush\n    with util.safe_reraise():\n         ^^^^^^^^^^^^^^^^^^^\n  File \"/Users/Apple/TO-DO project/venv/lib/python3.12/site-packages/sqlalchemy/util/langhelpers.py\", line 224, in __exit__\n    raise exc_value.with_traceback(exc_tb)\n  File \"/Users/Apple/TO-DO project/venv/lib/python3.12/site-packages/sqlalchemy/orm/session.py\", line 4441, in _flush\n    flush_context.execute()\n  File \"/Users/Apple/TO-DO project/venv/lib/python3.12/site-packages/sqlalchemy/orm/unitofwork.py\", line 466, in execute\n    rec.execute(self)\n  File \"/Users/Apple/TO-DO project/venv/lib/python3.12/site-packages/sqlalchemy/orm/unitofwork.py\", line 642, in execute\n    util.preloaded.orm_persistence.save_obj(\n  File \"/Users/Apple/TO-DO project/venv/lib/python3.12/site-packages/sqlalchemy/orm/persistence.py\", line 93, in save_obj\n    _emit_insert_statements(\n  File \"/Users/Apple/TO-DO project/venv/lib/python3.12/site-packages/sqlalchemy/orm/persistence.py\", line 1233, in _emit_insert_statements\n    result = connection.execute(\n             ^^^^^^^^^^^^^^^^^^^\n  File \"/Users/Apple/TO-DO project/venv/lib/python3.12/site-packages/sqlalchemy/engine/base.py\", line 1415, in execute\n    return meth(\n           ^^^^^\n  File \"/Users/Apple/TO-DO project/venv/lib/python3.12/site-packages/sqlalchemy/sql/elements.py\", line 523, in _execute_on_connection\n    return connection._execute_clauseelement(\n           ^^^^^^^^^^^^^^^^^^^^^^^^^^^^^^^^^^\n  File \"/Users/Apple/TO-DO project/venv/lib/python3.12/site-packages/sqlalchemy/engine/base.py\", line 1637, in _execute_clauseelement\n    ret = self._execute_context(\n          ^^^^^^^^^^^^^^^^^^^^^^\n  File \"/Users/Apple/TO-DO project/venv/lib/python3.12/site-packages/sqlalchemy/engine/base.py\", line 1842, in _execute_context\n    return self._exec_single_context(\n           ^^^^^^^^^^^^^^^^^^^^^^^^^^\n  File \"/Users/Apple/TO-DO project/venv/lib/python3.12/site-packages/sqlalchemy/engine/base.py\", line 1982, in _exec_single_context\n    self._handle_dbapi_exception(\n  File \"/Users/Apple/TO-DO project/venv/lib/python3.12/site-packages/sqlalchemy/engine/base.py\", line 2351, in _handle_dbapi_exception\n    raise sqlalchemy_exception.with_traceback(exc_info[2]) from e\n  File \"/Users/Apple/TO-DO project/venv/lib/python3.12/site-packages/sqlalchemy/engine/base.py\", line 1963, in _exec_single_context\n    self.dialect.do_execute(\n  File \"/Users/Apple/TO-DO project/venv/lib/python3.12/site-packages/sqlalchemy/engine/default.py\", line 943, in do_execute\n    cursor.execute(statement, parameters)\n  File \"/Users/Apple/TO-DO project/venv/lib/python3.12/site-packages/sqlalchemy/dialects/postgresql/asyncpg.py\", line 580, in execute\n    self._adapt_connection.await_(\n  File \"/Users/Apple/TO-DO project/venv/lib/python3.12/site-packages/sqlalchemy/util/_concurrency_py3k.py\", line 132, in await_only\n    return current.parent.switch(awaitable)  # type: ignore[no-any-return,attr-defined] # noqa: E501\n           ^^^^^^^^^^^^^^^^^^^^^^^^^^^^^^^^\n  File \"/Users/Apple/TO-DO project/venv/lib/python3.12/site-packages/sqlalchemy/util/_concurrency_py3k.py\", line 196, in greenlet_spawn\n    value = await result\n            ^^^^^^^^^^^^\n  File \"/Users/Apple/TO-DO project/venv/lib/python3.12/site-packages/sqlalchemy/dialects/postgresql/asyncpg.py\", line 558, in _prepare_and_execute\n    self._handle_exception(error)\n  File \"/Users/Apple/TO-DO project/venv/lib/python3.12/site-packages/sqlalchemy/dialects/postgresql/asyncpg.py\", line 508, in _handle_exception\n    self._adapt_connection._handle_exception(error)\n  File \"/Users/Apple/TO-DO project/venv/lib/python3.12/site-packages/sqlalchemy/dialects/postgresql/asyncpg.py\", line 792, in _handle_exception\n    raise translated_error from error\nsqlalchemy.exc.IntegrityError: (sqlalchemy.dialects.postgresql.asyncpg.IntegrityError) <class 'asyncpg.exceptions.NotNullViolationError'>: null value in column \"is_completed\" of relation \"todo_items\" violates not-null constraint\nDETAIL:  Failing row contains (1a36ab41-2b8a-4d3f-a29e-29ec548d9de2, Lock In, It is time to lock in and get it, null, 2025-06-30 09:35:22.326184, 2025-06-30 09:35:22.32619, null).\n[SQL: INSERT INTO todo_items (todo_uid, title, description, created_at, updated_at, user_uid) VALUES ($1::UUID, $2::VARCHAR, $3::VARCHAR, $4::TIMESTAMP WITHOUT TIME ZONE, $5::TIMESTAMP WITHOUT TIME ZONE, $6::UUID)]\n[parameters: (UUID('1a36ab41-2b8a-4d3f-a29e-29ec548d9de2'), 'Lock In', 'It is time to lock in and get it', datetime.datetime(2025, 6, 30, 9, 35, 22, 326184), datetime.datetime(2025, 6, 30, 9, 35, 22, 326190), None)]\n(Background on this error at: https://sqlalche.me/e/20/gkpj)"}
{"asctime": "2025-06-30 09:36:18", "msecs": 987.0, "levelname": "INFO", "name": "uvicorn.error", "lineno": 263, "message": "Shutting down"}
{"asctime": "2025-06-30 09:36:19", "msecs": 95.0, "levelname": "INFO", "name": "uvicorn.error", "lineno": 67, "message": "Waiting for application shutdown."}
{"asctime": "2025-06-30 09:36:19", "msecs": 241.0, "levelname": "INFO", "name": "uvicorn.error", "lineno": 76, "message": "Application shutdown complete."}
{"asctime": "2025-06-30 09:36:19", "msecs": 243.0, "levelname": "INFO", "name": "uvicorn.error", "lineno": 93, "message": "Finished server process [11940]", "color_message": "Finished server process [\u001b[36m%d\u001b[0m]"}
{"asctime": "2025-06-30 09:36:26", "msecs": 778.0, "levelname": "INFO", "name": "src", "lineno": 24, "message": "Logging works!!!"}
{"asctime": "2025-06-30 09:36:30", "msecs": 545.0, "levelname": "INFO", "name": "uvicorn.error", "lineno": 62, "message": "Application startup complete."}
{"asctime": "2025-06-30 09:36:30", "msecs": 549.0, "levelname": "INFO", "name": "uvicorn.error", "lineno": 215, "message": "Uvicorn running on http://127.0.0.1:8000 (Press CTRL+C to quit)", "color_message": "Uvicorn running on \u001b[1m%s://%s:%d\u001b[0m (Press CTRL+C to quit)"}
{"asctime": "2025-06-30 09:36:32", "msecs": 220.0, "levelname": "WARNING", "name": "passlib.handlers.bcrypt", "lineno": 622, "message": "(trapped) error reading bcrypt version", "exc_info": "Traceback (most recent call last):\n  File \"/Users/Apple/TO-DO project/venv/lib/python3.12/site-packages/passlib/handlers/bcrypt.py\", line 620, in _load_backend_mixin\n    version = _bcrypt.__about__.__version__\n              ^^^^^^^^^^^^^^^^^\nAttributeError: module 'bcrypt' has no attribute '__about__'"}
{"asctime": "2025-06-30 09:36:32", "msecs": 228.0, "levelname": "DEBUG", "name": "passlib.handlers.bcrypt", "lineno": 625, "message": "detected 'bcrypt' backend, version '<unknown>'"}
{"asctime": "2025-06-30 09:36:32", "msecs": 231.0, "levelname": "DEBUG", "name": "passlib.handlers.bcrypt", "lineno": 406, "message": "'bcrypt' backend lacks $2$ support, enabling workaround"}
{"asctime": "2025-06-30 09:36:32", "msecs": 653.0, "levelname": "INFO", "name": "uvicorn.access", "lineno": 476, "message": "127.0.0.1:56991 - \"POST /api/v1/auth/login HTTP/1.1\" 200"}
{"asctime": "2025-06-30 09:36:45", "msecs": 939.0, "levelname": "INFO", "name": "uvicorn.access", "lineno": 476, "message": "127.0.0.1:56998 - \"POST /api/v1/todo HTTP/1.1\" 307"}
{"asctime": "2025-06-30 09:36:45", "msecs": 946.0, "levelname": "DEBUG", "name": "src.utils.utils", "lineno": 41, "message": "Decoding Token here"}
{"asctime": "2025-06-30 09:36:45", "msecs": 955.0, "levelname": "INFO", "name": "uvicorn.access", "lineno": 476, "message": "127.0.0.1:56998 - \"POST /api/v1/todo/ HTTP/1.1\" 500"}
{"asctime": "2025-06-30 09:36:45", "msecs": 962.0, "levelname": "ERROR", "name": "uvicorn.error", "lineno": 414, "message": "Exception in ASGI application\n", "exc_info": "Traceback (most recent call last):\n  File \"/Users/Apple/TO-DO project/venv/lib/python3.12/site-packages/uvicorn/protocols/http/httptools_impl.py\", line 409, in run_asgi\n    result = await app(  # type: ignore[func-returns-value]\n             ^^^^^^^^^^^^^^^^^^^^^^^^^^^^^^^^^^^^^^^^^^^^^^\n  File \"/Users/Apple/TO-DO project/venv/lib/python3.12/site-packages/uvicorn/middleware/proxy_headers.py\", line 60, in __call__\n    return await self.app(scope, receive, send)\n           ^^^^^^^^^^^^^^^^^^^^^^^^^^^^^^^^^^^^\n  File \"/Users/Apple/TO-DO project/venv/lib/python3.12/site-packages/fastapi/applications.py\", line 1054, in __call__\n    await super().__call__(scope, receive, send)\n  File \"/Users/Apple/TO-DO project/venv/lib/python3.12/site-packages/starlette/applications.py\", line 112, in __call__\n    await self.middleware_stack(scope, receive, send)\n  File \"/Users/Apple/TO-DO project/venv/lib/python3.12/site-packages/starlette/middleware/errors.py\", line 187, in __call__\n    raise exc\n  File \"/Users/Apple/TO-DO project/venv/lib/python3.12/site-packages/starlette/middleware/errors.py\", line 165, in __call__\n    await self.app(scope, receive, _send)\n  File \"/Users/Apple/TO-DO project/venv/lib/python3.12/site-packages/starlette/middleware/exceptions.py\", line 62, in __call__\n    await wrap_app_handling_exceptions(self.app, conn)(scope, receive, send)\n  File \"/Users/Apple/TO-DO project/venv/lib/python3.12/site-packages/starlette/_exception_handler.py\", line 53, in wrapped_app\n    raise exc\n  File \"/Users/Apple/TO-DO project/venv/lib/python3.12/site-packages/starlette/_exception_handler.py\", line 42, in wrapped_app\n    await app(scope, receive, sender)\n  File \"/Users/Apple/TO-DO project/venv/lib/python3.12/site-packages/starlette/routing.py\", line 714, in __call__\n    await self.middleware_stack(scope, receive, send)\n  File \"/Users/Apple/TO-DO project/venv/lib/python3.12/site-packages/starlette/routing.py\", line 734, in app\n    await route.handle(scope, receive, send)\n  File \"/Users/Apple/TO-DO project/venv/lib/python3.12/site-packages/starlette/routing.py\", line 288, in handle\n    await self.app(scope, receive, send)\n  File \"/Users/Apple/TO-DO project/venv/lib/python3.12/site-packages/starlette/routing.py\", line 76, in app\n    await wrap_app_handling_exceptions(app, request)(scope, receive, send)\n  File \"/Users/Apple/TO-DO project/venv/lib/python3.12/site-packages/starlette/_exception_handler.py\", line 53, in wrapped_app\n    raise exc\n  File \"/Users/Apple/TO-DO project/venv/lib/python3.12/site-packages/starlette/_exception_handler.py\", line 42, in wrapped_app\n    await app(scope, receive, sender)\n  File \"/Users/Apple/TO-DO project/venv/lib/python3.12/site-packages/starlette/routing.py\", line 73, in app\n    response = await f(request)\n               ^^^^^^^^^^^^^^^^\n  File \"/Users/Apple/TO-DO project/venv/lib/python3.12/site-packages/fastapi/routing.py\", line 301, in app\n    raw_response = await run_endpoint_function(\n                   ^^^^^^^^^^^^^^^^^^^^^^^^^^^^\n  File \"/Users/Apple/TO-DO project/venv/lib/python3.12/site-packages/fastapi/routing.py\", line 212, in run_endpoint_function\n    return await dependant.call(**values)\n           ^^^^^^^^^^^^^^^^^^^^^^^^^^^^^^\n  File \"/Users/Apple/TO-DO project/src/v1/routes/todo.py\", line 30, in create_todo\n    logger.info(\"THis is user_uid %\", user_uid)\n  File \"/Library/Frameworks/Python.framework/Versions/3.12/lib/python3.12/logging/__init__.py\", line 1539, in info\n    self._log(INFO, msg, args, **kwargs)\n  File \"/Library/Frameworks/Python.framework/Versions/3.12/lib/python3.12/logging/__init__.py\", line 1684, in _log\n    self.handle(record)\n  File \"/Library/Frameworks/Python.framework/Versions/3.12/lib/python3.12/logging/__init__.py\", line 1700, in handle\n    self.callHandlers(record)\n  File \"/Library/Frameworks/Python.framework/Versions/3.12/lib/python3.12/logging/__init__.py\", line 1762, in callHandlers\n    hdlr.handle(record)\n  File \"/Library/Frameworks/Python.framework/Versions/3.12/lib/python3.12/logging/__init__.py\", line 1028, in handle\n    self.emit(record)\n  File \"/Users/Apple/TO-DO project/venv/lib/python3.12/site-packages/rich/logging.py\", line 134, in emit\n    message = self.format(record)\n              ^^^^^^^^^^^^^^^^^^^\n  File \"/Library/Frameworks/Python.framework/Versions/3.12/lib/python3.12/logging/__init__.py\", line 999, in format\n    return fmt.format(record)\n           ^^^^^^^^^^^^^^^^^^\n  File \"/Library/Frameworks/Python.framework/Versions/3.12/lib/python3.12/logging/__init__.py\", line 703, in format\n    record.message = record.getMessage()\n                     ^^^^^^^^^^^^^^^^^^^\n  File \"/Library/Frameworks/Python.framework/Versions/3.12/lib/python3.12/logging/__init__.py\", line 392, in getMessage\n    msg = msg % self.args\n          ~~~~^~~~~~~~~~~\nValueError: incomplete format"}
{"asctime": "2025-06-30 09:38:05", "msecs": 754.0, "levelname": "INFO", "name": "uvicorn.error", "lineno": 263, "message": "Shutting down"}
{"asctime": "2025-06-30 09:38:05", "msecs": 885.0, "levelname": "INFO", "name": "uvicorn.error", "lineno": 67, "message": "Waiting for application shutdown."}
{"asctime": "2025-06-30 09:38:06", "msecs": 51.0, "levelname": "INFO", "name": "uvicorn.error", "lineno": 76, "message": "Application shutdown complete."}
{"asctime": "2025-06-30 09:38:06", "msecs": 54.0, "levelname": "INFO", "name": "uvicorn.error", "lineno": 93, "message": "Finished server process [12060]", "color_message": "Finished server process [\u001b[36m%d\u001b[0m]"}
{"asctime": "2025-06-30 09:38:21", "msecs": 300.0, "levelname": "INFO", "name": "src", "lineno": 24, "message": "Logging works!!!"}
{"asctime": "2025-06-30 09:38:25", "msecs": 143.0, "levelname": "INFO", "name": "uvicorn.error", "lineno": 62, "message": "Application startup complete."}
{"asctime": "2025-06-30 09:38:27", "msecs": 608.0, "levelname": "WARNING", "name": "passlib.handlers.bcrypt", "lineno": 622, "message": "(trapped) error reading bcrypt version", "exc_info": "Traceback (most recent call last):\n  File \"/Users/Apple/TO-DO project/venv/lib/python3.12/site-packages/passlib/handlers/bcrypt.py\", line 620, in _load_backend_mixin\n    version = _bcrypt.__about__.__version__\n              ^^^^^^^^^^^^^^^^^\nAttributeError: module 'bcrypt' has no attribute '__about__'"}
{"asctime": "2025-06-30 09:38:27", "msecs": 616.0, "levelname": "DEBUG", "name": "passlib.handlers.bcrypt", "lineno": 625, "message": "detected 'bcrypt' backend, version '<unknown>'"}
{"asctime": "2025-06-30 09:38:27", "msecs": 618.0, "levelname": "DEBUG", "name": "passlib.handlers.bcrypt", "lineno": 406, "message": "'bcrypt' backend lacks $2$ support, enabling workaround"}
{"asctime": "2025-06-30 09:38:28", "msecs": 40.0, "levelname": "INFO", "name": "uvicorn.access", "lineno": 476, "message": "127.0.0.1:57041 - \"POST /api/v1/auth/login HTTP/1.1\" 200"}
{"asctime": "2025-06-30 09:38:44", "msecs": 824.0, "levelname": "INFO", "name": "uvicorn.access", "lineno": 476, "message": "127.0.0.1:57050 - \"POST /api/v1/todo HTTP/1.1\" 307"}
{"asctime": "2025-06-30 09:38:44", "msecs": 832.0, "levelname": "DEBUG", "name": "src.utils.utils", "lineno": 41, "message": "Decoding Token here"}
{"asctime": "2025-06-30 09:38:44", "msecs": 837.0, "levelname": "INFO", "name": "uvicorn.access", "lineno": 476, "message": "127.0.0.1:57050 - \"POST /api/v1/todo/ HTTP/1.1\" 500"}
{"asctime": "2025-06-30 09:38:44", "msecs": 838.0, "levelname": "ERROR", "name": "uvicorn.error", "lineno": 414, "message": "Exception in ASGI application\n", "exc_info": "Traceback (most recent call last):\n  File \"/Users/Apple/TO-DO project/venv/lib/python3.12/site-packages/uvicorn/protocols/http/httptools_impl.py\", line 409, in run_asgi\n    result = await app(  # type: ignore[func-returns-value]\n             ^^^^^^^^^^^^^^^^^^^^^^^^^^^^^^^^^^^^^^^^^^^^^^\n  File \"/Users/Apple/TO-DO project/venv/lib/python3.12/site-packages/uvicorn/middleware/proxy_headers.py\", line 60, in __call__\n    return await self.app(scope, receive, send)\n           ^^^^^^^^^^^^^^^^^^^^^^^^^^^^^^^^^^^^\n  File \"/Users/Apple/TO-DO project/venv/lib/python3.12/site-packages/fastapi/applications.py\", line 1054, in __call__\n    await super().__call__(scope, receive, send)\n  File \"/Users/Apple/TO-DO project/venv/lib/python3.12/site-packages/starlette/applications.py\", line 112, in __call__\n    await self.middleware_stack(scope, receive, send)\n  File \"/Users/Apple/TO-DO project/venv/lib/python3.12/site-packages/starlette/middleware/errors.py\", line 187, in __call__\n    raise exc\n  File \"/Users/Apple/TO-DO project/venv/lib/python3.12/site-packages/starlette/middleware/errors.py\", line 165, in __call__\n    await self.app(scope, receive, _send)\n  File \"/Users/Apple/TO-DO project/venv/lib/python3.12/site-packages/starlette/middleware/exceptions.py\", line 62, in __call__\n    await wrap_app_handling_exceptions(self.app, conn)(scope, receive, send)\n  File \"/Users/Apple/TO-DO project/venv/lib/python3.12/site-packages/starlette/_exception_handler.py\", line 53, in wrapped_app\n    raise exc\n  File \"/Users/Apple/TO-DO project/venv/lib/python3.12/site-packages/starlette/_exception_handler.py\", line 42, in wrapped_app\n    await app(scope, receive, sender)\n  File \"/Users/Apple/TO-DO project/venv/lib/python3.12/site-packages/starlette/routing.py\", line 714, in __call__\n    await self.middleware_stack(scope, receive, send)\n  File \"/Users/Apple/TO-DO project/venv/lib/python3.12/site-packages/starlette/routing.py\", line 734, in app\n    await route.handle(scope, receive, send)\n  File \"/Users/Apple/TO-DO project/venv/lib/python3.12/site-packages/starlette/routing.py\", line 288, in handle\n    await self.app(scope, receive, send)\n  File \"/Users/Apple/TO-DO project/venv/lib/python3.12/site-packages/starlette/routing.py\", line 76, in app\n    await wrap_app_handling_exceptions(app, request)(scope, receive, send)\n  File \"/Users/Apple/TO-DO project/venv/lib/python3.12/site-packages/starlette/_exception_handler.py\", line 53, in wrapped_app\n    raise exc\n  File \"/Users/Apple/TO-DO project/venv/lib/python3.12/site-packages/starlette/_exception_handler.py\", line 42, in wrapped_app\n    await app(scope, receive, sender)\n  File \"/Users/Apple/TO-DO project/venv/lib/python3.12/site-packages/starlette/routing.py\", line 73, in app\n    response = await f(request)\n               ^^^^^^^^^^^^^^^^\n  File \"/Users/Apple/TO-DO project/venv/lib/python3.12/site-packages/fastapi/routing.py\", line 301, in app\n    raw_response = await run_endpoint_function(\n                   ^^^^^^^^^^^^^^^^^^^^^^^^^^^^\n  File \"/Users/Apple/TO-DO project/venv/lib/python3.12/site-packages/fastapi/routing.py\", line 212, in run_endpoint_function\n    return await dependant.call(**values)\n           ^^^^^^^^^^^^^^^^^^^^^^^^^^^^^^\n  File \"/Users/Apple/TO-DO project/src/v1/routes/todo.py\", line 30, in create_todo\n    logger.debug(\"THis is user_uid\", user_uid)\n  File \"/Library/Frameworks/Python.framework/Versions/3.12/lib/python3.12/logging/__init__.py\", line 1527, in debug\n    self._log(DEBUG, msg, args, **kwargs)\n  File \"/Library/Frameworks/Python.framework/Versions/3.12/lib/python3.12/logging/__init__.py\", line 1684, in _log\n    self.handle(record)\n  File \"/Library/Frameworks/Python.framework/Versions/3.12/lib/python3.12/logging/__init__.py\", line 1700, in handle\n    self.callHandlers(record)\n  File \"/Library/Frameworks/Python.framework/Versions/3.12/lib/python3.12/logging/__init__.py\", line 1762, in callHandlers\n    hdlr.handle(record)\n  File \"/Library/Frameworks/Python.framework/Versions/3.12/lib/python3.12/logging/__init__.py\", line 1028, in handle\n    self.emit(record)\n  File \"/Users/Apple/TO-DO project/venv/lib/python3.12/site-packages/rich/logging.py\", line 134, in emit\n    message = self.format(record)\n              ^^^^^^^^^^^^^^^^^^^\n  File \"/Library/Frameworks/Python.framework/Versions/3.12/lib/python3.12/logging/__init__.py\", line 999, in format\n    return fmt.format(record)\n           ^^^^^^^^^^^^^^^^^^\n  File \"/Library/Frameworks/Python.framework/Versions/3.12/lib/python3.12/logging/__init__.py\", line 703, in format\n    record.message = record.getMessage()\n                     ^^^^^^^^^^^^^^^^^^^\n  File \"/Library/Frameworks/Python.framework/Versions/3.12/lib/python3.12/logging/__init__.py\", line 392, in getMessage\n    msg = msg % self.args\n          ~~~~^~~~~~~~~~~\nTypeError: not all arguments converted during string formatting"}
{"asctime": "2025-06-30 09:39:46", "msecs": 169.0, "levelname": "INFO", "name": "uvicorn.error", "lineno": 263, "message": "Shutting down"}
{"asctime": "2025-06-30 09:39:46", "msecs": 296.0, "levelname": "INFO", "name": "uvicorn.error", "lineno": 67, "message": "Waiting for application shutdown."}
{"asctime": "2025-06-30 09:39:46", "msecs": 466.0, "levelname": "INFO", "name": "uvicorn.error", "lineno": 76, "message": "Application shutdown complete."}
{"asctime": "2025-06-30 09:39:46", "msecs": 468.0, "levelname": "INFO", "name": "uvicorn.error", "lineno": 93, "message": "Finished server process [12197]", "color_message": "Finished server process [\u001b[36m%d\u001b[0m]"}
{"asctime": "2025-06-30 09:39:47", "msecs": 180.0, "levelname": "INFO", "name": "src", "lineno": 24, "message": "Logging works!!!"}
{"asctime": "2025-06-30 09:39:51", "msecs": 19.0, "levelname": "INFO", "name": "uvicorn.error", "lineno": 62, "message": "Application startup complete."}
{"asctime": "2025-06-30 09:39:51", "msecs": 656.0, "levelname": "INFO", "name": "src", "lineno": 24, "message": "Logging works!!!"}
{"asctime": "2025-06-30 09:39:55", "msecs": 141.0, "levelname": "INFO", "name": "uvicorn.error", "lineno": 62, "message": "Application startup complete."}
{"asctime": "2025-06-30 09:40:03", "msecs": 463.0, "levelname": "INFO", "name": "uvicorn.access", "lineno": 476, "message": "127.0.0.1:57084 - \"POST /api/v1/todo HTTP/1.1\" 307"}
{"asctime": "2025-06-30 09:40:03", "msecs": 469.0, "levelname": "DEBUG", "name": "src.utils.utils", "lineno": 41, "message": "Decoding Token here"}
{"asctime": "2025-06-30 09:40:03", "msecs": 472.0, "levelname": "DEBUG", "name": "src.v1.routes.todo", "lineno": 30, "message": "THis is user_uid fcb2a4ba-2803-42fd-b987-5c8729670dcc"}
{"asctime": "2025-06-30 09:40:04", "msecs": 12.0, "levelname": "INFO", "name": "uvicorn.access", "lineno": 476, "message": "127.0.0.1:57084 - \"POST /api/v1/todo/ HTTP/1.1\" 500"}
{"asctime": "2025-06-30 09:40:04", "msecs": 14.0, "levelname": "ERROR", "name": "uvicorn.error", "lineno": 414, "message": "Exception in ASGI application\n", "exc_info": "Traceback (most recent call last):\n  File \"/Users/Apple/TO-DO project/venv/lib/python3.12/site-packages/sqlalchemy/dialects/postgresql/asyncpg.py\", line 545, in _prepare_and_execute\n    self._rows = deque(await prepared_stmt.fetch(*parameters))\n                       ^^^^^^^^^^^^^^^^^^^^^^^^^^^^^^^^^^^^^^\n  File \"/Users/Apple/TO-DO project/venv/lib/python3.12/site-packages/asyncpg/prepared_stmt.py\", line 176, in fetch\n    data = await self.__bind_execute(args, 0, timeout)\n           ^^^^^^^^^^^^^^^^^^^^^^^^^^^^^^^^^^^^^^^^^^^\n  File \"/Users/Apple/TO-DO project/venv/lib/python3.12/site-packages/asyncpg/prepared_stmt.py\", line 267, in __bind_execute\n    data, status, _ = await self.__do_execute(\n                      ^^^^^^^^^^^^^^^^^^^^^^^^\n  File \"/Users/Apple/TO-DO project/venv/lib/python3.12/site-packages/asyncpg/prepared_stmt.py\", line 256, in __do_execute\n    return await executor(protocol)\n           ^^^^^^^^^^^^^^^^^^^^^^^^\n  File \"asyncpg/protocol/protocol.pyx\", line 206, in bind_execute\nasyncpg.exceptions.NotNullViolationError: null value in column \"is_completed\" of relation \"todo_items\" violates not-null constraint\nDETAIL:  Failing row contains (e65d584a-ed88-4c88-921a-4cc71097b125, Lock In, It is time to lock in and get it, null, 2025-06-30 09:40:03.479983, 2025-06-30 09:40:03.47999, null).\n\nThe above exception was the direct cause of the following exception:\n\nTraceback (most recent call last):\n  File \"/Users/Apple/TO-DO project/venv/lib/python3.12/site-packages/sqlalchemy/engine/base.py\", line 1963, in _exec_single_context\n    self.dialect.do_execute(\n  File \"/Users/Apple/TO-DO project/venv/lib/python3.12/site-packages/sqlalchemy/engine/default.py\", line 943, in do_execute\n    cursor.execute(statement, parameters)\n  File \"/Users/Apple/TO-DO project/venv/lib/python3.12/site-packages/sqlalchemy/dialects/postgresql/asyncpg.py\", line 580, in execute\n    self._adapt_connection.await_(\n  File \"/Users/Apple/TO-DO project/venv/lib/python3.12/site-packages/sqlalchemy/util/_concurrency_py3k.py\", line 132, in await_only\n    return current.parent.switch(awaitable)  # type: ignore[no-any-return,attr-defined] # noqa: E501\n           ^^^^^^^^^^^^^^^^^^^^^^^^^^^^^^^^\n  File \"/Users/Apple/TO-DO project/venv/lib/python3.12/site-packages/sqlalchemy/util/_concurrency_py3k.py\", line 196, in greenlet_spawn\n    value = await result\n            ^^^^^^^^^^^^\n  File \"/Users/Apple/TO-DO project/venv/lib/python3.12/site-packages/sqlalchemy/dialects/postgresql/asyncpg.py\", line 558, in _prepare_and_execute\n    self._handle_exception(error)\n  File \"/Users/Apple/TO-DO project/venv/lib/python3.12/site-packages/sqlalchemy/dialects/postgresql/asyncpg.py\", line 508, in _handle_exception\n    self._adapt_connection._handle_exception(error)\n  File \"/Users/Apple/TO-DO project/venv/lib/python3.12/site-packages/sqlalchemy/dialects/postgresql/asyncpg.py\", line 792, in _handle_exception\n    raise translated_error from error\nsqlalchemy.dialects.postgresql.asyncpg.AsyncAdapt_asyncpg_dbapi.IntegrityError: <class 'asyncpg.exceptions.NotNullViolationError'>: null value in column \"is_completed\" of relation \"todo_items\" violates not-null constraint\nDETAIL:  Failing row contains (e65d584a-ed88-4c88-921a-4cc71097b125, Lock In, It is time to lock in and get it, null, 2025-06-30 09:40:03.479983, 2025-06-30 09:40:03.47999, null).\n\nThe above exception was the direct cause of the following exception:\n\nTraceback (most recent call last):\n  File \"/Users/Apple/TO-DO project/venv/lib/python3.12/site-packages/uvicorn/protocols/http/httptools_impl.py\", line 409, in run_asgi\n    result = await app(  # type: ignore[func-returns-value]\n             ^^^^^^^^^^^^^^^^^^^^^^^^^^^^^^^^^^^^^^^^^^^^^^\n  File \"/Users/Apple/TO-DO project/venv/lib/python3.12/site-packages/uvicorn/middleware/proxy_headers.py\", line 60, in __call__\n    return await self.app(scope, receive, send)\n           ^^^^^^^^^^^^^^^^^^^^^^^^^^^^^^^^^^^^\n  File \"/Users/Apple/TO-DO project/venv/lib/python3.12/site-packages/fastapi/applications.py\", line 1054, in __call__\n    await super().__call__(scope, receive, send)\n  File \"/Users/Apple/TO-DO project/venv/lib/python3.12/site-packages/starlette/applications.py\", line 112, in __call__\n    await self.middleware_stack(scope, receive, send)\n  File \"/Users/Apple/TO-DO project/venv/lib/python3.12/site-packages/starlette/middleware/errors.py\", line 187, in __call__\n    raise exc\n  File \"/Users/Apple/TO-DO project/venv/lib/python3.12/site-packages/starlette/middleware/errors.py\", line 165, in __call__\n    await self.app(scope, receive, _send)\n  File \"/Users/Apple/TO-DO project/venv/lib/python3.12/site-packages/starlette/middleware/exceptions.py\", line 62, in __call__\n    await wrap_app_handling_exceptions(self.app, conn)(scope, receive, send)\n  File \"/Users/Apple/TO-DO project/venv/lib/python3.12/site-packages/starlette/_exception_handler.py\", line 53, in wrapped_app\n    raise exc\n  File \"/Users/Apple/TO-DO project/venv/lib/python3.12/site-packages/starlette/_exception_handler.py\", line 42, in wrapped_app\n    await app(scope, receive, sender)\n  File \"/Users/Apple/TO-DO project/venv/lib/python3.12/site-packages/starlette/routing.py\", line 714, in __call__\n    await self.middleware_stack(scope, receive, send)\n  File \"/Users/Apple/TO-DO project/venv/lib/python3.12/site-packages/starlette/routing.py\", line 734, in app\n    await route.handle(scope, receive, send)\n  File \"/Users/Apple/TO-DO project/venv/lib/python3.12/site-packages/starlette/routing.py\", line 288, in handle\n    await self.app(scope, receive, send)\n  File \"/Users/Apple/TO-DO project/venv/lib/python3.12/site-packages/starlette/routing.py\", line 76, in app\n    await wrap_app_handling_exceptions(app, request)(scope, receive, send)\n  File \"/Users/Apple/TO-DO project/venv/lib/python3.12/site-packages/starlette/_exception_handler.py\", line 53, in wrapped_app\n    raise exc\n  File \"/Users/Apple/TO-DO project/venv/lib/python3.12/site-packages/starlette/_exception_handler.py\", line 42, in wrapped_app\n    await app(scope, receive, sender)\n  File \"/Users/Apple/TO-DO project/venv/lib/python3.12/site-packages/starlette/routing.py\", line 73, in app\n    response = await f(request)\n               ^^^^^^^^^^^^^^^^\n  File \"/Users/Apple/TO-DO project/venv/lib/python3.12/site-packages/fastapi/routing.py\", line 301, in app\n    raw_response = await run_endpoint_function(\n                   ^^^^^^^^^^^^^^^^^^^^^^^^^^^^\n  File \"/Users/Apple/TO-DO project/venv/lib/python3.12/site-packages/fastapi/routing.py\", line 212, in run_endpoint_function\n    return await dependant.call(**values)\n           ^^^^^^^^^^^^^^^^^^^^^^^^^^^^^^\n  File \"/Users/Apple/TO-DO project/src/v1/routes/todo.py\", line 31, in create_todo\n    todo = await todo_service.create_todo(todo_data=todo_data, user_uid=user_uid, session=session)\n           ^^^^^^^^^^^^^^^^^^^^^^^^^^^^^^^^^^^^^^^^^^^^^^^^^^^^^^^^^^^^^^^^^^^^^^^^^^^^^^^^^^^^^^^\n  File \"/Users/Apple/TO-DO project/src/v1/service/todo.py\", line 21, in create_todo\n    await session.commit()\n  File \"/Users/Apple/TO-DO project/venv/lib/python3.12/site-packages/sqlalchemy/ext/asyncio/session.py\", line 1014, in commit\n    await greenlet_spawn(self.sync_session.commit)\n  File \"/Users/Apple/TO-DO project/venv/lib/python3.12/site-packages/sqlalchemy/util/_concurrency_py3k.py\", line 203, in greenlet_spawn\n    result = context.switch(value)\n             ^^^^^^^^^^^^^^^^^^^^^\n  File \"/Users/Apple/TO-DO project/venv/lib/python3.12/site-packages/sqlalchemy/orm/session.py\", line 2032, in commit\n    trans.commit(_to_root=True)\n  File \"<string>\", line 2, in commit\n  File \"/Users/Apple/TO-DO project/venv/lib/python3.12/site-packages/sqlalchemy/orm/state_changes.py\", line 139, in _go\n    ret_value = fn(self, *arg, **kw)\n                ^^^^^^^^^^^^^^^^^^^^\n  File \"/Users/Apple/TO-DO project/venv/lib/python3.12/site-packages/sqlalchemy/orm/session.py\", line 1313, in commit\n    self._prepare_impl()\n  File \"<string>\", line 2, in _prepare_impl\n  File \"/Users/Apple/TO-DO project/venv/lib/python3.12/site-packages/sqlalchemy/orm/state_changes.py\", line 139, in _go\n    ret_value = fn(self, *arg, **kw)\n                ^^^^^^^^^^^^^^^^^^^^\n  File \"/Users/Apple/TO-DO project/venv/lib/python3.12/site-packages/sqlalchemy/orm/session.py\", line 1288, in _prepare_impl\n    self.session.flush()\n  File \"/Users/Apple/TO-DO project/venv/lib/python3.12/site-packages/sqlalchemy/orm/session.py\", line 4345, in flush\n    self._flush(objects)\n  File \"/Users/Apple/TO-DO project/venv/lib/python3.12/site-packages/sqlalchemy/orm/session.py\", line 4480, in _flush\n    with util.safe_reraise():\n         ^^^^^^^^^^^^^^^^^^^\n  File \"/Users/Apple/TO-DO project/venv/lib/python3.12/site-packages/sqlalchemy/util/langhelpers.py\", line 224, in __exit__\n    raise exc_value.with_traceback(exc_tb)\n  File \"/Users/Apple/TO-DO project/venv/lib/python3.12/site-packages/sqlalchemy/orm/session.py\", line 4441, in _flush\n    flush_context.execute()\n  File \"/Users/Apple/TO-DO project/venv/lib/python3.12/site-packages/sqlalchemy/orm/unitofwork.py\", line 466, in execute\n    rec.execute(self)\n  File \"/Users/Apple/TO-DO project/venv/lib/python3.12/site-packages/sqlalchemy/orm/unitofwork.py\", line 642, in execute\n    util.preloaded.orm_persistence.save_obj(\n  File \"/Users/Apple/TO-DO project/venv/lib/python3.12/site-packages/sqlalchemy/orm/persistence.py\", line 93, in save_obj\n    _emit_insert_statements(\n  File \"/Users/Apple/TO-DO project/venv/lib/python3.12/site-packages/sqlalchemy/orm/persistence.py\", line 1233, in _emit_insert_statements\n    result = connection.execute(\n             ^^^^^^^^^^^^^^^^^^^\n  File \"/Users/Apple/TO-DO project/venv/lib/python3.12/site-packages/sqlalchemy/engine/base.py\", line 1415, in execute\n    return meth(\n           ^^^^^\n  File \"/Users/Apple/TO-DO project/venv/lib/python3.12/site-packages/sqlalchemy/sql/elements.py\", line 523, in _execute_on_connection\n    return connection._execute_clauseelement(\n           ^^^^^^^^^^^^^^^^^^^^^^^^^^^^^^^^^^\n  File \"/Users/Apple/TO-DO project/venv/lib/python3.12/site-packages/sqlalchemy/engine/base.py\", line 1637, in _execute_clauseelement\n    ret = self._execute_context(\n          ^^^^^^^^^^^^^^^^^^^^^^\n  File \"/Users/Apple/TO-DO project/venv/lib/python3.12/site-packages/sqlalchemy/engine/base.py\", line 1842, in _execute_context\n    return self._exec_single_context(\n           ^^^^^^^^^^^^^^^^^^^^^^^^^^\n  File \"/Users/Apple/TO-DO project/venv/lib/python3.12/site-packages/sqlalchemy/engine/base.py\", line 1982, in _exec_single_context\n    self._handle_dbapi_exception(\n  File \"/Users/Apple/TO-DO project/venv/lib/python3.12/site-packages/sqlalchemy/engine/base.py\", line 2351, in _handle_dbapi_exception\n    raise sqlalchemy_exception.with_traceback(exc_info[2]) from e\n  File \"/Users/Apple/TO-DO project/venv/lib/python3.12/site-packages/sqlalchemy/engine/base.py\", line 1963, in _exec_single_context\n    self.dialect.do_execute(\n  File \"/Users/Apple/TO-DO project/venv/lib/python3.12/site-packages/sqlalchemy/engine/default.py\", line 943, in do_execute\n    cursor.execute(statement, parameters)\n  File \"/Users/Apple/TO-DO project/venv/lib/python3.12/site-packages/sqlalchemy/dialects/postgresql/asyncpg.py\", line 580, in execute\n    self._adapt_connection.await_(\n  File \"/Users/Apple/TO-DO project/venv/lib/python3.12/site-packages/sqlalchemy/util/_concurrency_py3k.py\", line 132, in await_only\n    return current.parent.switch(awaitable)  # type: ignore[no-any-return,attr-defined] # noqa: E501\n           ^^^^^^^^^^^^^^^^^^^^^^^^^^^^^^^^\n  File \"/Users/Apple/TO-DO project/venv/lib/python3.12/site-packages/sqlalchemy/util/_concurrency_py3k.py\", line 196, in greenlet_spawn\n    value = await result\n            ^^^^^^^^^^^^\n  File \"/Users/Apple/TO-DO project/venv/lib/python3.12/site-packages/sqlalchemy/dialects/postgresql/asyncpg.py\", line 558, in _prepare_and_execute\n    self._handle_exception(error)\n  File \"/Users/Apple/TO-DO project/venv/lib/python3.12/site-packages/sqlalchemy/dialects/postgresql/asyncpg.py\", line 508, in _handle_exception\n    self._adapt_connection._handle_exception(error)\n  File \"/Users/Apple/TO-DO project/venv/lib/python3.12/site-packages/sqlalchemy/dialects/postgresql/asyncpg.py\", line 792, in _handle_exception\n    raise translated_error from error\nsqlalchemy.exc.IntegrityError: (sqlalchemy.dialects.postgresql.asyncpg.IntegrityError) <class 'asyncpg.exceptions.NotNullViolationError'>: null value in column \"is_completed\" of relation \"todo_items\" violates not-null constraint\nDETAIL:  Failing row contains (e65d584a-ed88-4c88-921a-4cc71097b125, Lock In, It is time to lock in and get it, null, 2025-06-30 09:40:03.479983, 2025-06-30 09:40:03.47999, null).\n[SQL: INSERT INTO todo_items (todo_uid, title, description, created_at, updated_at, user_uid) VALUES ($1::UUID, $2::VARCHAR, $3::VARCHAR, $4::TIMESTAMP WITHOUT TIME ZONE, $5::TIMESTAMP WITHOUT TIME ZONE, $6::UUID)]\n[parameters: (UUID('e65d584a-ed88-4c88-921a-4cc71097b125'), 'Lock In', 'It is time to lock in and get it', datetime.datetime(2025, 6, 30, 9, 40, 3, 479983), datetime.datetime(2025, 6, 30, 9, 40, 3, 479990), None)]\n(Background on this error at: https://sqlalche.me/e/20/gkpj)"}
{"asctime": "2025-06-30 09:42:44", "msecs": 260.0, "levelname": "INFO", "name": "uvicorn.error", "lineno": 263, "message": "Shutting down"}
{"asctime": "2025-06-30 09:42:44", "msecs": 381.0, "levelname": "INFO", "name": "uvicorn.error", "lineno": 67, "message": "Waiting for application shutdown."}
{"asctime": "2025-06-30 09:42:44", "msecs": 544.0, "levelname": "INFO", "name": "uvicorn.error", "lineno": 76, "message": "Application shutdown complete."}
{"asctime": "2025-06-30 09:42:44", "msecs": 546.0, "levelname": "INFO", "name": "uvicorn.error", "lineno": 93, "message": "Finished server process [12327]", "color_message": "Finished server process [\u001b[36m%d\u001b[0m]"}
{"asctime": "2025-06-30 09:43:09", "msecs": 60.0, "levelname": "INFO", "name": "src", "lineno": 24, "message": "Logging works!!!"}
{"asctime": "2025-06-30 09:43:12", "msecs": 767.0, "levelname": "INFO", "name": "uvicorn.error", "lineno": 62, "message": "Application startup complete."}
{"asctime": "2025-06-30 09:44:00", "msecs": 998.0, "levelname": "INFO", "name": "uvicorn.error", "lineno": 263, "message": "Shutting down"}
{"asctime": "2025-06-30 09:44:01", "msecs": 104.0, "levelname": "INFO", "name": "uvicorn.error", "lineno": 67, "message": "Waiting for application shutdown."}
{"asctime": "2025-06-30 09:44:01", "msecs": 241.0, "levelname": "INFO", "name": "uvicorn.error", "lineno": 76, "message": "Application shutdown complete."}
{"asctime": "2025-06-30 09:44:01", "msecs": 242.0, "levelname": "INFO", "name": "uvicorn.error", "lineno": 93, "message": "Finished server process [12492]", "color_message": "Finished server process [\u001b[36m%d\u001b[0m]"}
{"asctime": "2025-06-30 09:44:01", "msecs": 850.0, "levelname": "INFO", "name": "src", "lineno": 24, "message": "Logging works!!!"}
{"asctime": "2025-06-30 09:44:05", "msecs": 270.0, "levelname": "INFO", "name": "uvicorn.error", "lineno": 62, "message": "Application startup complete."}
{"asctime": "2025-06-30 09:44:54", "msecs": 158.0, "levelname": "INFO", "name": "src", "lineno": 24, "message": "Logging works!!!"}
{"asctime": "2025-06-30 09:44:57", "msecs": 969.0, "levelname": "INFO", "name": "uvicorn.error", "lineno": 62, "message": "Application startup complete."}
{"asctime": "2025-06-30 09:44:57", "msecs": 975.0, "levelname": "INFO", "name": "uvicorn.error", "lineno": 215, "message": "Uvicorn running on http://127.0.0.1:8000 (Press CTRL+C to quit)", "color_message": "Uvicorn running on \u001b[1m%s://%s:%d\u001b[0m (Press CTRL+C to quit)"}
{"asctime": "2025-06-30 09:45:01", "msecs": 894.0, "levelname": "WARNING", "name": "passlib.handlers.bcrypt", "lineno": 622, "message": "(trapped) error reading bcrypt version", "exc_info": "Traceback (most recent call last):\n  File \"/Users/Apple/TO-DO project/venv/lib/python3.12/site-packages/passlib/handlers/bcrypt.py\", line 620, in _load_backend_mixin\n    version = _bcrypt.__about__.__version__\n              ^^^^^^^^^^^^^^^^^\nAttributeError: module 'bcrypt' has no attribute '__about__'"}
{"asctime": "2025-06-30 09:45:01", "msecs": 901.0, "levelname": "DEBUG", "name": "passlib.handlers.bcrypt", "lineno": 625, "message": "detected 'bcrypt' backend, version '<unknown>'"}
{"asctime": "2025-06-30 09:45:01", "msecs": 902.0, "levelname": "DEBUG", "name": "passlib.handlers.bcrypt", "lineno": 406, "message": "'bcrypt' backend lacks $2$ support, enabling workaround"}
{"asctime": "2025-06-30 09:45:02", "msecs": 329.0, "levelname": "INFO", "name": "uvicorn.access", "lineno": 476, "message": "127.0.0.1:57244 - \"POST /api/v1/auth/login HTTP/1.1\" 200"}
{"asctime": "2025-06-30 09:45:13", "msecs": 154.0, "levelname": "INFO", "name": "uvicorn.access", "lineno": 476, "message": "127.0.0.1:57254 - \"POST /api/v1/todo HTTP/1.1\" 307"}
{"asctime": "2025-06-30 09:45:13", "msecs": 161.0, "levelname": "DEBUG", "name": "src.utils.utils", "lineno": 41, "message": "Decoding Token here"}
{"asctime": "2025-06-30 09:45:13", "msecs": 163.0, "levelname": "DEBUG", "name": "src.v1.routes.todo", "lineno": 30, "message": "THis is user_uid fcb2a4ba-2803-42fd-b987-5c8729670dcc"}
{"asctime": "2025-06-30 09:45:14", "msecs": 282.0, "levelname": "INFO", "name": "uvicorn.access", "lineno": 476, "message": "127.0.0.1:57254 - \"POST /api/v1/todo/ HTTP/1.1\" 201"}
{"asctime": "2025-06-30 09:47:03", "msecs": 774.0, "levelname": "INFO", "name": "uvicorn.access", "lineno": 476, "message": "127.0.0.1:57292 - \"GET /api/v1/todos/search?Lock HTTP/1.1\" 404"}
{"asctime": "2025-06-30 09:47:50", "msecs": 153.0, "levelname": "INFO", "name": "uvicorn.access", "lineno": 476, "message": "127.0.0.1:57307 - \"GET /api/v1/todos/search?Lock HTTP/1.1\" 404"}
{"asctime": "2025-06-30 09:55:02", "msecs": 271.0, "levelname": "INFO", "name": "uvicorn.access", "lineno": 476, "message": "127.0.0.1:57447 - \"GET /api/v1/todos/search?search_term=lock HTTP/1.1\" 404"}
{"asctime": "2025-06-30 09:55:05", "msecs": 359.0, "levelname": "INFO", "name": "uvicorn.error", "lineno": 263, "message": "Shutting down"}
{"asctime": "2025-06-30 09:55:05", "msecs": 473.0, "levelname": "INFO", "name": "uvicorn.error", "lineno": 67, "message": "Waiting for application shutdown."}
{"asctime": "2025-06-30 09:55:05", "msecs": 666.0, "levelname": "INFO", "name": "uvicorn.error", "lineno": 76, "message": "Application shutdown complete."}
{"asctime": "2025-06-30 09:55:05", "msecs": 669.0, "levelname": "INFO", "name": "uvicorn.error", "lineno": 93, "message": "Finished server process [12676]", "color_message": "Finished server process [\u001b[36m%d\u001b[0m]"}
{"asctime": "2025-06-30 09:55:09", "msecs": 98.0, "levelname": "INFO", "name": "src", "lineno": 24, "message": "Logging works!!!"}
{"asctime": "2025-06-30 09:55:13", "msecs": 457.0, "levelname": "INFO", "name": "uvicorn.error", "lineno": 62, "message": "Application startup complete."}
{"asctime": "2025-06-30 09:55:13", "msecs": 460.0, "levelname": "INFO", "name": "uvicorn.error", "lineno": 215, "message": "Uvicorn running on http://127.0.0.1:8000 (Press CTRL+C to quit)", "color_message": "Uvicorn running on \u001b[1m%s://%s:%d\u001b[0m (Press CTRL+C to quit)"}
{"asctime": "2025-06-30 09:55:14", "msecs": 886.0, "levelname": "WARNING", "name": "passlib.handlers.bcrypt", "lineno": 622, "message": "(trapped) error reading bcrypt version", "exc_info": "Traceback (most recent call last):\n  File \"/Users/Apple/TO-DO project/venv/lib/python3.12/site-packages/passlib/handlers/bcrypt.py\", line 620, in _load_backend_mixin\n    version = _bcrypt.__about__.__version__\n              ^^^^^^^^^^^^^^^^^\nAttributeError: module 'bcrypt' has no attribute '__about__'"}
{"asctime": "2025-06-30 09:55:14", "msecs": 893.0, "levelname": "DEBUG", "name": "passlib.handlers.bcrypt", "lineno": 625, "message": "detected 'bcrypt' backend, version '<unknown>'"}
{"asctime": "2025-06-30 09:55:14", "msecs": 895.0, "levelname": "DEBUG", "name": "passlib.handlers.bcrypt", "lineno": 406, "message": "'bcrypt' backend lacks $2$ support, enabling workaround"}
{"asctime": "2025-06-30 09:55:15", "msecs": 316.0, "levelname": "INFO", "name": "uvicorn.access", "lineno": 476, "message": "127.0.0.1:57457 - \"POST /api/v1/auth/login HTTP/1.1\" 200"}
{"asctime": "2025-06-30 09:55:26", "msecs": 786.0, "levelname": "INFO", "name": "uvicorn.access", "lineno": 476, "message": "127.0.0.1:57463 - \"GET /api/v1/todos/search?search_term=lock HTTP/1.1\" 404"}
{"asctime": "2025-06-30 09:57:42", "msecs": 327.0, "levelname": "INFO", "name": "uvicorn.error", "lineno": 263, "message": "Shutting down"}
{"asctime": "2025-06-30 09:57:42", "msecs": 456.0, "levelname": "INFO", "name": "uvicorn.error", "lineno": 67, "message": "Waiting for application shutdown."}
{"asctime": "2025-06-30 09:57:42", "msecs": 635.0, "levelname": "INFO", "name": "uvicorn.error", "lineno": 76, "message": "Application shutdown complete."}
{"asctime": "2025-06-30 09:57:42", "msecs": 637.0, "levelname": "INFO", "name": "uvicorn.error", "lineno": 93, "message": "Finished server process [13230]", "color_message": "Finished server process [\u001b[36m%d\u001b[0m]"}
{"asctime": "2025-06-30 09:57:51", "msecs": 549.0, "levelname": "INFO", "name": "src", "lineno": 24, "message": "Logging works!!!"}
{"asctime": "2025-06-30 09:57:55", "msecs": 710.0, "levelname": "INFO", "name": "uvicorn.error", "lineno": 62, "message": "Application startup complete."}
{"asctime": "2025-06-30 09:57:55", "msecs": 714.0, "levelname": "INFO", "name": "uvicorn.error", "lineno": 215, "message": "Uvicorn running on http://127.0.0.1:8000 (Press CTRL+C to quit)", "color_message": "Uvicorn running on \u001b[1m%s://%s:%d\u001b[0m (Press CTRL+C to quit)"}
{"asctime": "2025-06-30 09:57:58", "msecs": 295.0, "levelname": "WARNING", "name": "passlib.handlers.bcrypt", "lineno": 622, "message": "(trapped) error reading bcrypt version", "exc_info": "Traceback (most recent call last):\n  File \"/Users/Apple/TO-DO project/venv/lib/python3.12/site-packages/passlib/handlers/bcrypt.py\", line 620, in _load_backend_mixin\n    version = _bcrypt.__about__.__version__\n              ^^^^^^^^^^^^^^^^^\nAttributeError: module 'bcrypt' has no attribute '__about__'"}
{"asctime": "2025-06-30 09:57:58", "msecs": 302.0, "levelname": "DEBUG", "name": "passlib.handlers.bcrypt", "lineno": 625, "message": "detected 'bcrypt' backend, version '<unknown>'"}
{"asctime": "2025-06-30 09:57:58", "msecs": 304.0, "levelname": "DEBUG", "name": "passlib.handlers.bcrypt", "lineno": 406, "message": "'bcrypt' backend lacks $2$ support, enabling workaround"}
{"asctime": "2025-06-30 09:57:58", "msecs": 738.0, "levelname": "INFO", "name": "uvicorn.access", "lineno": 476, "message": "127.0.0.1:57541 - \"POST /api/v1/auth/login HTTP/1.1\" 200"}
{"asctime": "2025-06-30 09:58:08", "msecs": 437.0, "levelname": "INFO", "name": "uvicorn.access", "lineno": 476, "message": "127.0.0.1:57545 - \"GET /api/v1/todos/search?search_term=lock HTTP/1.1\" 404"}
{"asctime": "2025-06-30 10:01:12", "msecs": 276.0, "levelname": "INFO", "name": "uvicorn.error", "lineno": 263, "message": "Shutting down"}
{"asctime": "2025-06-30 10:01:12", "msecs": 396.0, "levelname": "INFO", "name": "uvicorn.error", "lineno": 67, "message": "Waiting for application shutdown."}
{"asctime": "2025-06-30 10:01:12", "msecs": 573.0, "levelname": "INFO", "name": "uvicorn.error", "lineno": 76, "message": "Application shutdown complete."}
{"asctime": "2025-06-30 10:01:12", "msecs": 576.0, "levelname": "INFO", "name": "uvicorn.error", "lineno": 93, "message": "Finished server process [13425]", "color_message": "Finished server process [\u001b[36m%d\u001b[0m]"}
{"asctime": "2025-06-30 10:01:16", "msecs": 570.0, "levelname": "INFO", "name": "src", "lineno": 24, "message": "Logging works!!!"}
{"asctime": "2025-06-30 10:01:20", "msecs": 782.0, "levelname": "INFO", "name": "uvicorn.error", "lineno": 62, "message": "Application startup complete."}
{"asctime": "2025-06-30 10:01:20", "msecs": 785.0, "levelname": "INFO", "name": "uvicorn.error", "lineno": 215, "message": "Uvicorn running on http://127.0.0.1:8000 (Press CTRL+C to quit)", "color_message": "Uvicorn running on \u001b[1m%s://%s:%d\u001b[0m (Press CTRL+C to quit)"}
{"asctime": "2025-06-30 10:01:25", "msecs": 549.0, "levelname": "WARNING", "name": "passlib.handlers.bcrypt", "lineno": 622, "message": "(trapped) error reading bcrypt version", "exc_info": "Traceback (most recent call last):\n  File \"/Users/Apple/TO-DO project/venv/lib/python3.12/site-packages/passlib/handlers/bcrypt.py\", line 620, in _load_backend_mixin\n    version = _bcrypt.__about__.__version__\n              ^^^^^^^^^^^^^^^^^\nAttributeError: module 'bcrypt' has no attribute '__about__'"}
{"asctime": "2025-06-30 10:01:25", "msecs": 557.0, "levelname": "DEBUG", "name": "passlib.handlers.bcrypt", "lineno": 625, "message": "detected 'bcrypt' backend, version '<unknown>'"}
{"asctime": "2025-06-30 10:01:25", "msecs": 559.0, "levelname": "DEBUG", "name": "passlib.handlers.bcrypt", "lineno": 406, "message": "'bcrypt' backend lacks $2$ support, enabling workaround"}
{"asctime": "2025-06-30 10:01:25", "msecs": 985.0, "levelname": "INFO", "name": "uvicorn.access", "lineno": 476, "message": "127.0.0.1:57601 - \"POST /api/v1/auth/login HTTP/1.1\" 200"}
{"asctime": "2025-06-30 10:01:50", "msecs": 489.0, "levelname": "DEBUG", "name": "src.utils.utils", "lineno": 41, "message": "Decoding Token here"}
{"asctime": "2025-06-30 10:01:50", "msecs": 491.0, "levelname": "DEBUG", "name": "src.v1.routes.todo", "lineno": 44, "message": "Search term lock"}
{"asctime": "2025-06-30 10:01:51", "msecs": 61.0, "levelname": "INFO", "name": "uvicorn.access", "lineno": 476, "message": "127.0.0.1:57610 - \"GET /api/v1/todo/search?search_term=lock HTTP/1.1\" 500"}
{"asctime": "2025-06-30 10:01:51", "msecs": 64.0, "levelname": "ERROR", "name": "uvicorn.error", "lineno": 414, "message": "Exception in ASGI application\n", "exc_info": "Traceback (most recent call last):\n  File \"/Users/Apple/TO-DO project/venv/lib/python3.12/site-packages/uvicorn/protocols/http/httptools_impl.py\", line 409, in run_asgi\n    result = await app(  # type: ignore[func-returns-value]\n             ^^^^^^^^^^^^^^^^^^^^^^^^^^^^^^^^^^^^^^^^^^^^^^\n  File \"/Users/Apple/TO-DO project/venv/lib/python3.12/site-packages/uvicorn/middleware/proxy_headers.py\", line 60, in __call__\n    return await self.app(scope, receive, send)\n           ^^^^^^^^^^^^^^^^^^^^^^^^^^^^^^^^^^^^\n  File \"/Users/Apple/TO-DO project/venv/lib/python3.12/site-packages/fastapi/applications.py\", line 1054, in __call__\n    await super().__call__(scope, receive, send)\n  File \"/Users/Apple/TO-DO project/venv/lib/python3.12/site-packages/starlette/applications.py\", line 112, in __call__\n    await self.middleware_stack(scope, receive, send)\n  File \"/Users/Apple/TO-DO project/venv/lib/python3.12/site-packages/starlette/middleware/errors.py\", line 187, in __call__\n    raise exc\n  File \"/Users/Apple/TO-DO project/venv/lib/python3.12/site-packages/starlette/middleware/errors.py\", line 165, in __call__\n    await self.app(scope, receive, _send)\n  File \"/Users/Apple/TO-DO project/venv/lib/python3.12/site-packages/starlette/middleware/exceptions.py\", line 62, in __call__\n    await wrap_app_handling_exceptions(self.app, conn)(scope, receive, send)\n  File \"/Users/Apple/TO-DO project/venv/lib/python3.12/site-packages/starlette/_exception_handler.py\", line 53, in wrapped_app\n    raise exc\n  File \"/Users/Apple/TO-DO project/venv/lib/python3.12/site-packages/starlette/_exception_handler.py\", line 42, in wrapped_app\n    await app(scope, receive, sender)\n  File \"/Users/Apple/TO-DO project/venv/lib/python3.12/site-packages/starlette/routing.py\", line 714, in __call__\n    await self.middleware_stack(scope, receive, send)\n  File \"/Users/Apple/TO-DO project/venv/lib/python3.12/site-packages/starlette/routing.py\", line 734, in app\n    await route.handle(scope, receive, send)\n  File \"/Users/Apple/TO-DO project/venv/lib/python3.12/site-packages/starlette/routing.py\", line 288, in handle\n    await self.app(scope, receive, send)\n  File \"/Users/Apple/TO-DO project/venv/lib/python3.12/site-packages/starlette/routing.py\", line 76, in app\n    await wrap_app_handling_exceptions(app, request)(scope, receive, send)\n  File \"/Users/Apple/TO-DO project/venv/lib/python3.12/site-packages/starlette/_exception_handler.py\", line 53, in wrapped_app\n    raise exc\n  File \"/Users/Apple/TO-DO project/venv/lib/python3.12/site-packages/starlette/_exception_handler.py\", line 42, in wrapped_app\n    await app(scope, receive, sender)\n  File \"/Users/Apple/TO-DO project/venv/lib/python3.12/site-packages/starlette/routing.py\", line 73, in app\n    response = await f(request)\n               ^^^^^^^^^^^^^^^^\n  File \"/Users/Apple/TO-DO project/venv/lib/python3.12/site-packages/fastapi/routing.py\", line 301, in app\n    raw_response = await run_endpoint_function(\n                   ^^^^^^^^^^^^^^^^^^^^^^^^^^^^\n  File \"/Users/Apple/TO-DO project/venv/lib/python3.12/site-packages/fastapi/routing.py\", line 212, in run_endpoint_function\n    return await dependant.call(**values)\n           ^^^^^^^^^^^^^^^^^^^^^^^^^^^^^^\n  File \"/Users/Apple/TO-DO project/src/v1/routes/todo.py\", line 45, in search_todos\n    todos = await todo_service.search_todos(search_term=search_term, session=session)\n            ^^^^^^^^^^^^^^^^^^^^^^^^^^^^^^^^^^^^^^^^^^^^^^^^^^^^^^^^^^^^^^^^^^^^^^^^^\n  File \"/Users/Apple/TO-DO project/src/v1/service/todo.py\", line 76, in search_todos\n    todos = result.scalars().all()\n            ^^^^^^^^^^^^^^\nAttributeError: 'ScalarResult' object has no attribute 'scalars'"}
{"asctime": "2025-06-30 10:02:05", "msecs": 673.0, "levelname": "DEBUG", "name": "src.utils.utils", "lineno": 41, "message": "Decoding Token here"}
{"asctime": "2025-06-30 10:02:05", "msecs": 683.0, "levelname": "DEBUG", "name": "src.v1.routes.todo", "lineno": 44, "message": "Search term lock"}
{"asctime": "2025-06-30 10:02:06", "msecs": 98.0, "levelname": "INFO", "name": "uvicorn.access", "lineno": 476, "message": "127.0.0.1:57623 - \"GET /api/v1/todo/search?search_term=lock HTTP/1.1\" 500"}
{"asctime": "2025-06-30 10:02:06", "msecs": 100.0, "levelname": "ERROR", "name": "uvicorn.error", "lineno": 414, "message": "Exception in ASGI application\n", "exc_info": "Traceback (most recent call last):\n  File \"/Users/Apple/TO-DO project/venv/lib/python3.12/site-packages/uvicorn/protocols/http/httptools_impl.py\", line 409, in run_asgi\n    result = await app(  # type: ignore[func-returns-value]\n             ^^^^^^^^^^^^^^^^^^^^^^^^^^^^^^^^^^^^^^^^^^^^^^\n  File \"/Users/Apple/TO-DO project/venv/lib/python3.12/site-packages/uvicorn/middleware/proxy_headers.py\", line 60, in __call__\n    return await self.app(scope, receive, send)\n           ^^^^^^^^^^^^^^^^^^^^^^^^^^^^^^^^^^^^\n  File \"/Users/Apple/TO-DO project/venv/lib/python3.12/site-packages/fastapi/applications.py\", line 1054, in __call__\n    await super().__call__(scope, receive, send)\n  File \"/Users/Apple/TO-DO project/venv/lib/python3.12/site-packages/starlette/applications.py\", line 112, in __call__\n    await self.middleware_stack(scope, receive, send)\n  File \"/Users/Apple/TO-DO project/venv/lib/python3.12/site-packages/starlette/middleware/errors.py\", line 187, in __call__\n    raise exc\n  File \"/Users/Apple/TO-DO project/venv/lib/python3.12/site-packages/starlette/middleware/errors.py\", line 165, in __call__\n    await self.app(scope, receive, _send)\n  File \"/Users/Apple/TO-DO project/venv/lib/python3.12/site-packages/starlette/middleware/exceptions.py\", line 62, in __call__\n    await wrap_app_handling_exceptions(self.app, conn)(scope, receive, send)\n  File \"/Users/Apple/TO-DO project/venv/lib/python3.12/site-packages/starlette/_exception_handler.py\", line 53, in wrapped_app\n    raise exc\n  File \"/Users/Apple/TO-DO project/venv/lib/python3.12/site-packages/starlette/_exception_handler.py\", line 42, in wrapped_app\n    await app(scope, receive, sender)\n  File \"/Users/Apple/TO-DO project/venv/lib/python3.12/site-packages/starlette/routing.py\", line 714, in __call__\n    await self.middleware_stack(scope, receive, send)\n  File \"/Users/Apple/TO-DO project/venv/lib/python3.12/site-packages/starlette/routing.py\", line 734, in app\n    await route.handle(scope, receive, send)\n  File \"/Users/Apple/TO-DO project/venv/lib/python3.12/site-packages/starlette/routing.py\", line 288, in handle\n    await self.app(scope, receive, send)\n  File \"/Users/Apple/TO-DO project/venv/lib/python3.12/site-packages/starlette/routing.py\", line 76, in app\n    await wrap_app_handling_exceptions(app, request)(scope, receive, send)\n  File \"/Users/Apple/TO-DO project/venv/lib/python3.12/site-packages/starlette/_exception_handler.py\", line 53, in wrapped_app\n    raise exc\n  File \"/Users/Apple/TO-DO project/venv/lib/python3.12/site-packages/starlette/_exception_handler.py\", line 42, in wrapped_app\n    await app(scope, receive, sender)\n  File \"/Users/Apple/TO-DO project/venv/lib/python3.12/site-packages/starlette/routing.py\", line 73, in app\n    response = await f(request)\n               ^^^^^^^^^^^^^^^^\n  File \"/Users/Apple/TO-DO project/venv/lib/python3.12/site-packages/fastapi/routing.py\", line 301, in app\n    raw_response = await run_endpoint_function(\n                   ^^^^^^^^^^^^^^^^^^^^^^^^^^^^\n  File \"/Users/Apple/TO-DO project/venv/lib/python3.12/site-packages/fastapi/routing.py\", line 212, in run_endpoint_function\n    return await dependant.call(**values)\n           ^^^^^^^^^^^^^^^^^^^^^^^^^^^^^^\n  File \"/Users/Apple/TO-DO project/src/v1/routes/todo.py\", line 45, in search_todos\n    todos = await todo_service.search_todos(search_term=search_term, session=session)\n            ^^^^^^^^^^^^^^^^^^^^^^^^^^^^^^^^^^^^^^^^^^^^^^^^^^^^^^^^^^^^^^^^^^^^^^^^^\n  File \"/Users/Apple/TO-DO project/src/v1/service/todo.py\", line 76, in search_todos\n    todos = result.all()\n            ^^^^^^^^^^^^^\nAttributeError: 'ScalarResult' object has no attribute 'scalars'"}
{"asctime": "2025-06-30 10:02:10", "msecs": 411.0, "levelname": "INFO", "name": "uvicorn.error", "lineno": 263, "message": "Shutting down"}
{"asctime": "2025-06-30 10:02:10", "msecs": 530.0, "levelname": "INFO", "name": "uvicorn.error", "lineno": 67, "message": "Waiting for application shutdown."}
{"asctime": "2025-06-30 10:02:10", "msecs": 683.0, "levelname": "INFO", "name": "uvicorn.error", "lineno": 76, "message": "Application shutdown complete."}
{"asctime": "2025-06-30 10:02:10", "msecs": 685.0, "levelname": "INFO", "name": "uvicorn.error", "lineno": 93, "message": "Finished server process [13613]", "color_message": "Finished server process [\u001b[36m%d\u001b[0m]"}
{"asctime": "2025-06-30 10:02:17", "msecs": 228.0, "levelname": "INFO", "name": "src", "lineno": 24, "message": "Logging works!!!"}
{"asctime": "2025-06-30 10:02:20", "msecs": 776.0, "levelname": "INFO", "name": "uvicorn.error", "lineno": 62, "message": "Application startup complete."}
{"asctime": "2025-06-30 10:02:25", "msecs": 118.0, "levelname": "WARNING", "name": "passlib.handlers.bcrypt", "lineno": 622, "message": "(trapped) error reading bcrypt version", "exc_info": "Traceback (most recent call last):\n  File \"/Users/Apple/TO-DO project/venv/lib/python3.12/site-packages/passlib/handlers/bcrypt.py\", line 620, in _load_backend_mixin\n    version = _bcrypt.__about__.__version__\n              ^^^^^^^^^^^^^^^^^\nAttributeError: module 'bcrypt' has no attribute '__about__'"}
{"asctime": "2025-06-30 10:02:25", "msecs": 126.0, "levelname": "DEBUG", "name": "passlib.handlers.bcrypt", "lineno": 625, "message": "detected 'bcrypt' backend, version '<unknown>'"}
{"asctime": "2025-06-30 10:02:25", "msecs": 128.0, "levelname": "DEBUG", "name": "passlib.handlers.bcrypt", "lineno": 406, "message": "'bcrypt' backend lacks $2$ support, enabling workaround"}
{"asctime": "2025-06-30 10:02:25", "msecs": 565.0, "levelname": "INFO", "name": "uvicorn.access", "lineno": 476, "message": "127.0.0.1:57635 - \"POST /api/v1/auth/login HTTP/1.1\" 200"}
{"asctime": "2025-06-30 10:02:36", "msecs": 80.0, "levelname": "DEBUG", "name": "src.utils.utils", "lineno": 41, "message": "Decoding Token here"}
{"asctime": "2025-06-30 10:02:36", "msecs": 83.0, "levelname": "DEBUG", "name": "src.v1.routes.todo", "lineno": 44, "message": "Search term lock"}
{"asctime": "2025-06-30 10:02:36", "msecs": 638.0, "levelname": "INFO", "name": "uvicorn.access", "lineno": 476, "message": "127.0.0.1:57639 - \"GET /api/v1/todo/search?search_term=lock HTTP/1.1\" 200"}
{"asctime": "2025-06-30 10:03:09", "msecs": 688.0, "levelname": "INFO", "name": "uvicorn.error", "lineno": 263, "message": "Shutting down"}
{"asctime": "2025-06-30 10:03:09", "msecs": 802.0, "levelname": "INFO", "name": "uvicorn.error", "lineno": 67, "message": "Waiting for application shutdown."}
{"asctime": "2025-06-30 10:03:09", "msecs": 949.0, "levelname": "INFO", "name": "uvicorn.error", "lineno": 76, "message": "Application shutdown complete."}
{"asctime": "2025-06-30 10:03:09", "msecs": 950.0, "levelname": "INFO", "name": "uvicorn.error", "lineno": 93, "message": "Finished server process [13688]", "color_message": "Finished server process [\u001b[36m%d\u001b[0m]"}
{"asctime": "2025-06-30 10:03:10", "msecs": 522.0, "levelname": "INFO", "name": "src", "lineno": 24, "message": "Logging works!!!"}
{"asctime": "2025-06-30 10:03:14", "msecs": 591.0, "levelname": "INFO", "name": "uvicorn.error", "lineno": 62, "message": "Application startup complete."}
{"asctime": "2025-06-30 10:03:48", "msecs": 71.0, "levelname": "INFO", "name": "uvicorn.access", "lineno": 476, "message": "127.0.0.1:57655 - \"GET /api/v1/todo HTTP/1.1\" 307"}
{"asctime": "2025-06-30 10:03:48", "msecs": 150.0, "levelname": "DEBUG", "name": "src.utils.utils", "lineno": 41, "message": "Decoding Token here"}
{"asctime": "2025-06-30 10:03:48", "msecs": 701.0, "levelname": "INFO", "name": "uvicorn.access", "lineno": 476, "message": "127.0.0.1:57655 - \"GET /api/v1/todo/ HTTP/1.1\" 200"}
{"asctime": "2025-06-30 10:03:59", "msecs": 921.0, "levelname": "DEBUG", "name": "src.utils.utils", "lineno": 41, "message": "Decoding Token here"}
{"asctime": "2025-06-30 10:04:00", "msecs": 465.0, "levelname": "INFO", "name": "uvicorn.access", "lineno": 476, "message": "127.0.0.1:57663 - \"GET /api/v1/todo/2c0f4216-09bc-49ae-b527-e7e8e484c8ed HTTP/1.1\" 200"}
{"asctime": "2025-06-30 10:05:06", "msecs": 0.0, "levelname": "DEBUG", "name": "src.utils.utils", "lineno": 41, "message": "Decoding Token here"}
{"asctime": "2025-06-30 10:05:07", "msecs": 105.0, "levelname": "INFO", "name": "uvicorn.access", "lineno": 476, "message": "127.0.0.1:57680 - \"PUT /api/v1/todo/2c0f4216-09bc-49ae-b527-e7e8e484c8ed HTTP/1.1\" 200"}
{"asctime": "2025-06-30 10:05:19", "msecs": 691.0, "levelname": "DEBUG", "name": "src.utils.utils", "lineno": 41, "message": "Decoding Token here"}
{"asctime": "2025-06-30 10:05:20", "msecs": 117.0, "levelname": "INFO", "name": "uvicorn.access", "lineno": 476, "message": "127.0.0.1:57686 - \"GET /api/v1/todo/2c0f4216-09bc-49ae-b527-e7e8e484c8ed HTTP/1.1\" 200"}
{"asctime": "2025-06-30 10:05:50", "msecs": 868.0, "levelname": "INFO", "name": "uvicorn.error", "lineno": 263, "message": "Shutting down"}
{"asctime": "2025-06-30 10:05:50", "msecs": 973.0, "levelname": "INFO", "name": "uvicorn.error", "lineno": 67, "message": "Waiting for application shutdown."}
{"asctime": "2025-06-30 10:05:51", "msecs": 118.0, "levelname": "INFO", "name": "uvicorn.error", "lineno": 76, "message": "Application shutdown complete."}
{"asctime": "2025-06-30 10:05:51", "msecs": 120.0, "levelname": "INFO", "name": "uvicorn.error", "lineno": 93, "message": "Finished server process [13747]", "color_message": "Finished server process [\u001b[36m%d\u001b[0m]"}
{"asctime": "2025-06-30 10:05:51", "msecs": 883.0, "levelname": "INFO", "name": "src", "lineno": 24, "message": "Logging works!!!"}
{"asctime": "2025-06-30 10:05:55", "msecs": 956.0, "levelname": "INFO", "name": "uvicorn.error", "lineno": 62, "message": "Application startup complete."}
{"asctime": "2025-06-30 10:05:56", "msecs": 394.0, "levelname": "INFO", "name": "src", "lineno": 24, "message": "Logging works!!!"}
{"asctime": "2025-06-30 10:05:59", "msecs": 882.0, "levelname": "INFO", "name": "uvicorn.error", "lineno": 62, "message": "Application startup complete."}
{"asctime": "2025-06-30 10:05:59", "msecs": 887.0, "levelname": "DEBUG", "name": "src.utils.utils", "lineno": 41, "message": "Decoding Token here"}
{"asctime": "2025-06-30 10:06:00", "msecs": 305.0, "levelname": "INFO", "name": "uvicorn.access", "lineno": 476, "message": "127.0.0.1:57702 - \"GET /api/v1/todo/count HTTP/1.1\" 500"}
{"asctime": "2025-06-30 10:06:00", "msecs": 307.0, "levelname": "ERROR", "name": "uvicorn.error", "lineno": 414, "message": "Exception in ASGI application\n", "exc_info": "Traceback (most recent call last):\n  File \"asyncpg/protocol/prepared_stmt.pyx\", line 175, in asyncpg.protocol.protocol.PreparedStatementState._encode_bind_msg\n  File \"asyncpg/protocol/codecs/base.pyx\", line 227, in asyncpg.protocol.protocol.Codec.encode\n  File \"asyncpg/protocol/codecs/base.pyx\", line 129, in asyncpg.protocol.protocol.Codec.encode_scalar\n  File \"asyncpg/pgproto/./codecs/uuid.pyx\", line 16, in asyncpg.pgproto.pgproto.uuid_encode\n  File \"asyncpg/pgproto/./uuid.pyx\", line 88, in asyncpg.pgproto.pgproto.pg_uuid_bytes_from_str\nValueError: invalid UUID 'count': length must be between 32..36 characters, got 5\n\nThe above exception was the direct cause of the following exception:\n\nTraceback (most recent call last):\n  File \"/Users/Apple/TO-DO project/venv/lib/python3.12/site-packages/sqlalchemy/dialects/postgresql/asyncpg.py\", line 545, in _prepare_and_execute\n    self._rows = deque(await prepared_stmt.fetch(*parameters))\n                       ^^^^^^^^^^^^^^^^^^^^^^^^^^^^^^^^^^^^^^\n  File \"/Users/Apple/TO-DO project/venv/lib/python3.12/site-packages/asyncpg/prepared_stmt.py\", line 176, in fetch\n    data = await self.__bind_execute(args, 0, timeout)\n           ^^^^^^^^^^^^^^^^^^^^^^^^^^^^^^^^^^^^^^^^^^^\n  File \"/Users/Apple/TO-DO project/venv/lib/python3.12/site-packages/asyncpg/prepared_stmt.py\", line 267, in __bind_execute\n    data, status, _ = await self.__do_execute(\n                      ^^^^^^^^^^^^^^^^^^^^^^^^\n  File \"/Users/Apple/TO-DO project/venv/lib/python3.12/site-packages/asyncpg/prepared_stmt.py\", line 256, in __do_execute\n    return await executor(protocol)\n           ^^^^^^^^^^^^^^^^^^^^^^^^\n  File \"asyncpg/protocol/protocol.pyx\", line 185, in bind_execute\n  File \"asyncpg/protocol/prepared_stmt.pyx\", line 204, in asyncpg.protocol.protocol.PreparedStatementState._encode_bind_msg\nasyncpg.exceptions.DataError: invalid input for query argument $1: 'count' (invalid UUID 'count': length must be between 32..36 characters, got 5)\n\nThe above exception was the direct cause of the following exception:\n\nTraceback (most recent call last):\n  File \"/Users/Apple/TO-DO project/venv/lib/python3.12/site-packages/sqlalchemy/engine/base.py\", line 1963, in _exec_single_context\n    self.dialect.do_execute(\n  File \"/Users/Apple/TO-DO project/venv/lib/python3.12/site-packages/sqlalchemy/engine/default.py\", line 943, in do_execute\n    cursor.execute(statement, parameters)\n  File \"/Users/Apple/TO-DO project/venv/lib/python3.12/site-packages/sqlalchemy/dialects/postgresql/asyncpg.py\", line 580, in execute\n    self._adapt_connection.await_(\n  File \"/Users/Apple/TO-DO project/venv/lib/python3.12/site-packages/sqlalchemy/util/_concurrency_py3k.py\", line 132, in await_only\n    return current.parent.switch(awaitable)  # type: ignore[no-any-return,attr-defined] # noqa: E501\n           ^^^^^^^^^^^^^^^^^^^^^^^^^^^^^^^^\n  File \"/Users/Apple/TO-DO project/venv/lib/python3.12/site-packages/sqlalchemy/util/_concurrency_py3k.py\", line 196, in greenlet_spawn\n    value = await result\n            ^^^^^^^^^^^^\n  File \"/Users/Apple/TO-DO project/venv/lib/python3.12/site-packages/sqlalchemy/dialects/postgresql/asyncpg.py\", line 558, in _prepare_and_execute\n    self._handle_exception(error)\n  File \"/Users/Apple/TO-DO project/venv/lib/python3.12/site-packages/sqlalchemy/dialects/postgresql/asyncpg.py\", line 508, in _handle_exception\n    self._adapt_connection._handle_exception(error)\n  File \"/Users/Apple/TO-DO project/venv/lib/python3.12/site-packages/sqlalchemy/dialects/postgresql/asyncpg.py\", line 792, in _handle_exception\n    raise translated_error from error\nsqlalchemy.dialects.postgresql.asyncpg.AsyncAdapt_asyncpg_dbapi.Error: <class 'asyncpg.exceptions.DataError'>: invalid input for query argument $1: 'count' (invalid UUID 'count': length must be between 32..36 characters, got 5)\n\nThe above exception was the direct cause of the following exception:\n\nTraceback (most recent call last):\n  File \"/Users/Apple/TO-DO project/venv/lib/python3.12/site-packages/uvicorn/protocols/http/httptools_impl.py\", line 409, in run_asgi\n    result = await app(  # type: ignore[func-returns-value]\n             ^^^^^^^^^^^^^^^^^^^^^^^^^^^^^^^^^^^^^^^^^^^^^^\n  File \"/Users/Apple/TO-DO project/venv/lib/python3.12/site-packages/uvicorn/middleware/proxy_headers.py\", line 60, in __call__\n    return await self.app(scope, receive, send)\n           ^^^^^^^^^^^^^^^^^^^^^^^^^^^^^^^^^^^^\n  File \"/Users/Apple/TO-DO project/venv/lib/python3.12/site-packages/fastapi/applications.py\", line 1054, in __call__\n    await super().__call__(scope, receive, send)\n  File \"/Users/Apple/TO-DO project/venv/lib/python3.12/site-packages/starlette/applications.py\", line 112, in __call__\n    await self.middleware_stack(scope, receive, send)\n  File \"/Users/Apple/TO-DO project/venv/lib/python3.12/site-packages/starlette/middleware/errors.py\", line 187, in __call__\n    raise exc\n  File \"/Users/Apple/TO-DO project/venv/lib/python3.12/site-packages/starlette/middleware/errors.py\", line 165, in __call__\n    await self.app(scope, receive, _send)\n  File \"/Users/Apple/TO-DO project/venv/lib/python3.12/site-packages/starlette/middleware/exceptions.py\", line 62, in __call__\n    await wrap_app_handling_exceptions(self.app, conn)(scope, receive, send)\n  File \"/Users/Apple/TO-DO project/venv/lib/python3.12/site-packages/starlette/_exception_handler.py\", line 53, in wrapped_app\n    raise exc\n  File \"/Users/Apple/TO-DO project/venv/lib/python3.12/site-packages/starlette/_exception_handler.py\", line 42, in wrapped_app\n    await app(scope, receive, sender)\n  File \"/Users/Apple/TO-DO project/venv/lib/python3.12/site-packages/starlette/routing.py\", line 714, in __call__\n    await self.middleware_stack(scope, receive, send)\n  File \"/Users/Apple/TO-DO project/venv/lib/python3.12/site-packages/starlette/routing.py\", line 734, in app\n    await route.handle(scope, receive, send)\n  File \"/Users/Apple/TO-DO project/venv/lib/python3.12/site-packages/starlette/routing.py\", line 288, in handle\n    await self.app(scope, receive, send)\n  File \"/Users/Apple/TO-DO project/venv/lib/python3.12/site-packages/starlette/routing.py\", line 76, in app\n    await wrap_app_handling_exceptions(app, request)(scope, receive, send)\n  File \"/Users/Apple/TO-DO project/venv/lib/python3.12/site-packages/starlette/_exception_handler.py\", line 53, in wrapped_app\n    raise exc\n  File \"/Users/Apple/TO-DO project/venv/lib/python3.12/site-packages/starlette/_exception_handler.py\", line 42, in wrapped_app\n    await app(scope, receive, sender)\n  File \"/Users/Apple/TO-DO project/venv/lib/python3.12/site-packages/starlette/routing.py\", line 73, in app\n    response = await f(request)\n               ^^^^^^^^^^^^^^^^\n  File \"/Users/Apple/TO-DO project/venv/lib/python3.12/site-packages/fastapi/routing.py\", line 301, in app\n    raw_response = await run_endpoint_function(\n                   ^^^^^^^^^^^^^^^^^^^^^^^^^^^^\n  File \"/Users/Apple/TO-DO project/venv/lib/python3.12/site-packages/fastapi/routing.py\", line 212, in run_endpoint_function\n    return await dependant.call(**values)\n           ^^^^^^^^^^^^^^^^^^^^^^^^^^^^^^\n  File \"/Users/Apple/TO-DO project/src/v1/routes/todo.py\", line 58, in get_todo\n    todo = await todo_service.get_todo_by_uid(todo_uid=todo_uid, session=session)\n           ^^^^^^^^^^^^^^^^^^^^^^^^^^^^^^^^^^^^^^^^^^^^^^^^^^^^^^^^^^^^^^^^^^^^^^\n  File \"/Users/Apple/TO-DO project/src/v1/service/todo.py\", line 13, in get_todo_by_uid\n    result = await session.exec(statement)\n             ^^^^^^^^^^^^^^^^^^^^^^^^^^^^^\n  File \"/Users/Apple/TO-DO project/venv/lib/python3.12/site-packages/sqlmodel/ext/asyncio/session.py\", line 81, in exec\n    result = await greenlet_spawn(\n             ^^^^^^^^^^^^^^^^^^^^^\n  File \"/Users/Apple/TO-DO project/venv/lib/python3.12/site-packages/sqlalchemy/util/_concurrency_py3k.py\", line 201, in greenlet_spawn\n    result = context.throw(*sys.exc_info())\n             ^^^^^^^^^^^^^^^^^^^^^^^^^^^^^^\n  File \"/Users/Apple/TO-DO project/venv/lib/python3.12/site-packages/sqlmodel/orm/session.py\", line 66, in exec\n    results = super().execute(\n              ^^^^^^^^^^^^^^^^\n  File \"/Users/Apple/TO-DO project/venv/lib/python3.12/site-packages/sqlalchemy/orm/session.py\", line 2365, in execute\n    return self._execute_internal(\n           ^^^^^^^^^^^^^^^^^^^^^^^\n  File \"/Users/Apple/TO-DO project/venv/lib/python3.12/site-packages/sqlalchemy/orm/session.py\", line 2251, in _execute_internal\n    result: Result[Any] = compile_state_cls.orm_execute_statement(\n                          ^^^^^^^^^^^^^^^^^^^^^^^^^^^^^^^^^^^^^^^^\n  File \"/Users/Apple/TO-DO project/venv/lib/python3.12/site-packages/sqlalchemy/orm/context.py\", line 306, in orm_execute_statement\n    result = conn.execute(\n             ^^^^^^^^^^^^^\n  File \"/Users/Apple/TO-DO project/venv/lib/python3.12/site-packages/sqlalchemy/engine/base.py\", line 1415, in execute\n    return meth(\n           ^^^^^\n  File \"/Users/Apple/TO-DO project/venv/lib/python3.12/site-packages/sqlalchemy/sql/elements.py\", line 523, in _execute_on_connection\n    return connection._execute_clauseelement(\n           ^^^^^^^^^^^^^^^^^^^^^^^^^^^^^^^^^^\n  File \"/Users/Apple/TO-DO project/venv/lib/python3.12/site-packages/sqlalchemy/engine/base.py\", line 1637, in _execute_clauseelement\n    ret = self._execute_context(\n          ^^^^^^^^^^^^^^^^^^^^^^\n  File \"/Users/Apple/TO-DO project/venv/lib/python3.12/site-packages/sqlalchemy/engine/base.py\", line 1842, in _execute_context\n    return self._exec_single_context(\n           ^^^^^^^^^^^^^^^^^^^^^^^^^^\n  File \"/Users/Apple/TO-DO project/venv/lib/python3.12/site-packages/sqlalchemy/engine/base.py\", line 1982, in _exec_single_context\n    self._handle_dbapi_exception(\n  File \"/Users/Apple/TO-DO project/venv/lib/python3.12/site-packages/sqlalchemy/engine/base.py\", line 2351, in _handle_dbapi_exception\n    raise sqlalchemy_exception.with_traceback(exc_info[2]) from e\n  File \"/Users/Apple/TO-DO project/venv/lib/python3.12/site-packages/sqlalchemy/engine/base.py\", line 1963, in _exec_single_context\n    self.dialect.do_execute(\n  File \"/Users/Apple/TO-DO project/venv/lib/python3.12/site-packages/sqlalchemy/engine/default.py\", line 943, in do_execute\n    cursor.execute(statement, parameters)\n  File \"/Users/Apple/TO-DO project/venv/lib/python3.12/site-packages/sqlalchemy/dialects/postgresql/asyncpg.py\", line 580, in execute\n    self._adapt_connection.await_(\n  File \"/Users/Apple/TO-DO project/venv/lib/python3.12/site-packages/sqlalchemy/util/_concurrency_py3k.py\", line 132, in await_only\n    return current.parent.switch(awaitable)  # type: ignore[no-any-return,attr-defined] # noqa: E501\n           ^^^^^^^^^^^^^^^^^^^^^^^^^^^^^^^^\n  File \"/Users/Apple/TO-DO project/venv/lib/python3.12/site-packages/sqlalchemy/util/_concurrency_py3k.py\", line 196, in greenlet_spawn\n    value = await result\n            ^^^^^^^^^^^^\n  File \"/Users/Apple/TO-DO project/venv/lib/python3.12/site-packages/sqlalchemy/dialects/postgresql/asyncpg.py\", line 558, in _prepare_and_execute\n    self._handle_exception(error)\n  File \"/Users/Apple/TO-DO project/venv/lib/python3.12/site-packages/sqlalchemy/dialects/postgresql/asyncpg.py\", line 508, in _handle_exception\n    self._adapt_connection._handle_exception(error)\n  File \"/Users/Apple/TO-DO project/venv/lib/python3.12/site-packages/sqlalchemy/dialects/postgresql/asyncpg.py\", line 792, in _handle_exception\n    raise translated_error from error\nsqlalchemy.exc.DBAPIError: (sqlalchemy.dialects.postgresql.asyncpg.Error) <class 'asyncpg.exceptions.DataError'>: invalid input for query argument $1: 'count' (invalid UUID 'count': length must be between 32..36 characters, got 5)\n[SQL: SELECT todo_items.todo_uid, todo_items.title, todo_items.description, todo_items.created_at, todo_items.updated_at, todo_items.user_uid \nFROM todo_items \nWHERE todo_items.todo_uid = $1::UUID]\n[parameters: ('count',)]\n(Background on this error at: https://sqlalche.me/e/20/dbapi)"}
{"asctime": "2025-06-30 10:07:18", "msecs": 582.0, "levelname": "INFO", "name": "uvicorn.error", "lineno": 263, "message": "Shutting down"}
{"asctime": "2025-06-30 10:07:18", "msecs": 713.0, "levelname": "INFO", "name": "uvicorn.error", "lineno": 67, "message": "Waiting for application shutdown."}
{"asctime": "2025-06-30 10:07:18", "msecs": 872.0, "levelname": "INFO", "name": "uvicorn.error", "lineno": 76, "message": "Application shutdown complete."}
{"asctime": "2025-06-30 10:07:18", "msecs": 873.0, "levelname": "INFO", "name": "uvicorn.error", "lineno": 93, "message": "Finished server process [13902]", "color_message": "Finished server process [\u001b[36m%d\u001b[0m]"}
{"asctime": "2025-06-30 10:07:19", "msecs": 423.0, "levelname": "INFO", "name": "src", "lineno": 24, "message": "Logging works!!!"}
{"asctime": "2025-06-30 10:07:23", "msecs": 485.0, "levelname": "INFO", "name": "uvicorn.error", "lineno": 62, "message": "Application startup complete."}
{"asctime": "2025-06-30 10:07:23", "msecs": 935.0, "levelname": "INFO", "name": "src", "lineno": 24, "message": "Logging works!!!"}
{"asctime": "2025-06-30 10:07:27", "msecs": 320.0, "levelname": "INFO", "name": "uvicorn.error", "lineno": 62, "message": "Application startup complete."}
{"asctime": "2025-06-30 10:07:32", "msecs": 401.0, "levelname": "DEBUG", "name": "src.utils.utils", "lineno": 41, "message": "Decoding Token here"}
{"asctime": "2025-06-30 10:07:32", "msecs": 805.0, "levelname": "INFO", "name": "uvicorn.access", "lineno": 476, "message": "127.0.0.1:57736 - \"GET /api/v1/todo/count HTTP/1.1\" 500"}
{"asctime": "2025-06-30 10:07:32", "msecs": 809.0, "levelname": "ERROR", "name": "uvicorn.error", "lineno": 414, "message": "Exception in ASGI application\n", "exc_info": "Traceback (most recent call last):\n  File \"asyncpg/protocol/prepared_stmt.pyx\", line 175, in asyncpg.protocol.protocol.PreparedStatementState._encode_bind_msg\n  File \"asyncpg/protocol/codecs/base.pyx\", line 227, in asyncpg.protocol.protocol.Codec.encode\n  File \"asyncpg/protocol/codecs/base.pyx\", line 129, in asyncpg.protocol.protocol.Codec.encode_scalar\n  File \"asyncpg/pgproto/./codecs/uuid.pyx\", line 16, in asyncpg.pgproto.pgproto.uuid_encode\n  File \"asyncpg/pgproto/./uuid.pyx\", line 88, in asyncpg.pgproto.pgproto.pg_uuid_bytes_from_str\nValueError: invalid UUID 'count': length must be between 32..36 characters, got 5\n\nThe above exception was the direct cause of the following exception:\n\nTraceback (most recent call last):\n  File \"/Users/Apple/TO-DO project/venv/lib/python3.12/site-packages/sqlalchemy/dialects/postgresql/asyncpg.py\", line 545, in _prepare_and_execute\n    self._rows = deque(await prepared_stmt.fetch(*parameters))\n                       ^^^^^^^^^^^^^^^^^^^^^^^^^^^^^^^^^^^^^^\n  File \"/Users/Apple/TO-DO project/venv/lib/python3.12/site-packages/asyncpg/prepared_stmt.py\", line 176, in fetch\n    data = await self.__bind_execute(args, 0, timeout)\n           ^^^^^^^^^^^^^^^^^^^^^^^^^^^^^^^^^^^^^^^^^^^\n  File \"/Users/Apple/TO-DO project/venv/lib/python3.12/site-packages/asyncpg/prepared_stmt.py\", line 267, in __bind_execute\n    data, status, _ = await self.__do_execute(\n                      ^^^^^^^^^^^^^^^^^^^^^^^^\n  File \"/Users/Apple/TO-DO project/venv/lib/python3.12/site-packages/asyncpg/prepared_stmt.py\", line 256, in __do_execute\n    return await executor(protocol)\n           ^^^^^^^^^^^^^^^^^^^^^^^^\n  File \"asyncpg/protocol/protocol.pyx\", line 185, in bind_execute\n  File \"asyncpg/protocol/prepared_stmt.pyx\", line 204, in asyncpg.protocol.protocol.PreparedStatementState._encode_bind_msg\nasyncpg.exceptions.DataError: invalid input for query argument $1: 'count' (invalid UUID 'count': length must be between 32..36 characters, got 5)\n\nThe above exception was the direct cause of the following exception:\n\nTraceback (most recent call last):\n  File \"/Users/Apple/TO-DO project/venv/lib/python3.12/site-packages/sqlalchemy/engine/base.py\", line 1963, in _exec_single_context\n    self.dialect.do_execute(\n  File \"/Users/Apple/TO-DO project/venv/lib/python3.12/site-packages/sqlalchemy/engine/default.py\", line 943, in do_execute\n    cursor.execute(statement, parameters)\n  File \"/Users/Apple/TO-DO project/venv/lib/python3.12/site-packages/sqlalchemy/dialects/postgresql/asyncpg.py\", line 580, in execute\n    self._adapt_connection.await_(\n  File \"/Users/Apple/TO-DO project/venv/lib/python3.12/site-packages/sqlalchemy/util/_concurrency_py3k.py\", line 132, in await_only\n    return current.parent.switch(awaitable)  # type: ignore[no-any-return,attr-defined] # noqa: E501\n           ^^^^^^^^^^^^^^^^^^^^^^^^^^^^^^^^\n  File \"/Users/Apple/TO-DO project/venv/lib/python3.12/site-packages/sqlalchemy/util/_concurrency_py3k.py\", line 196, in greenlet_spawn\n    value = await result\n            ^^^^^^^^^^^^\n  File \"/Users/Apple/TO-DO project/venv/lib/python3.12/site-packages/sqlalchemy/dialects/postgresql/asyncpg.py\", line 558, in _prepare_and_execute\n    self._handle_exception(error)\n  File \"/Users/Apple/TO-DO project/venv/lib/python3.12/site-packages/sqlalchemy/dialects/postgresql/asyncpg.py\", line 508, in _handle_exception\n    self._adapt_connection._handle_exception(error)\n  File \"/Users/Apple/TO-DO project/venv/lib/python3.12/site-packages/sqlalchemy/dialects/postgresql/asyncpg.py\", line 792, in _handle_exception\n    raise translated_error from error\nsqlalchemy.dialects.postgresql.asyncpg.AsyncAdapt_asyncpg_dbapi.Error: <class 'asyncpg.exceptions.DataError'>: invalid input for query argument $1: 'count' (invalid UUID 'count': length must be between 32..36 characters, got 5)\n\nThe above exception was the direct cause of the following exception:\n\nTraceback (most recent call last):\n  File \"/Users/Apple/TO-DO project/venv/lib/python3.12/site-packages/uvicorn/protocols/http/httptools_impl.py\", line 409, in run_asgi\n    result = await app(  # type: ignore[func-returns-value]\n             ^^^^^^^^^^^^^^^^^^^^^^^^^^^^^^^^^^^^^^^^^^^^^^\n  File \"/Users/Apple/TO-DO project/venv/lib/python3.12/site-packages/uvicorn/middleware/proxy_headers.py\", line 60, in __call__\n    return await self.app(scope, receive, send)\n           ^^^^^^^^^^^^^^^^^^^^^^^^^^^^^^^^^^^^\n  File \"/Users/Apple/TO-DO project/venv/lib/python3.12/site-packages/fastapi/applications.py\", line 1054, in __call__\n    await super().__call__(scope, receive, send)\n  File \"/Users/Apple/TO-DO project/venv/lib/python3.12/site-packages/starlette/applications.py\", line 112, in __call__\n    await self.middleware_stack(scope, receive, send)\n  File \"/Users/Apple/TO-DO project/venv/lib/python3.12/site-packages/starlette/middleware/errors.py\", line 187, in __call__\n    raise exc\n  File \"/Users/Apple/TO-DO project/venv/lib/python3.12/site-packages/starlette/middleware/errors.py\", line 165, in __call__\n    await self.app(scope, receive, _send)\n  File \"/Users/Apple/TO-DO project/venv/lib/python3.12/site-packages/starlette/middleware/exceptions.py\", line 62, in __call__\n    await wrap_app_handling_exceptions(self.app, conn)(scope, receive, send)\n  File \"/Users/Apple/TO-DO project/venv/lib/python3.12/site-packages/starlette/_exception_handler.py\", line 53, in wrapped_app\n    raise exc\n  File \"/Users/Apple/TO-DO project/venv/lib/python3.12/site-packages/starlette/_exception_handler.py\", line 42, in wrapped_app\n    await app(scope, receive, sender)\n  File \"/Users/Apple/TO-DO project/venv/lib/python3.12/site-packages/starlette/routing.py\", line 714, in __call__\n    await self.middleware_stack(scope, receive, send)\n  File \"/Users/Apple/TO-DO project/venv/lib/python3.12/site-packages/starlette/routing.py\", line 734, in app\n    await route.handle(scope, receive, send)\n  File \"/Users/Apple/TO-DO project/venv/lib/python3.12/site-packages/starlette/routing.py\", line 288, in handle\n    await self.app(scope, receive, send)\n  File \"/Users/Apple/TO-DO project/venv/lib/python3.12/site-packages/starlette/routing.py\", line 76, in app\n    await wrap_app_handling_exceptions(app, request)(scope, receive, send)\n  File \"/Users/Apple/TO-DO project/venv/lib/python3.12/site-packages/starlette/_exception_handler.py\", line 53, in wrapped_app\n    raise exc\n  File \"/Users/Apple/TO-DO project/venv/lib/python3.12/site-packages/starlette/_exception_handler.py\", line 42, in wrapped_app\n    await app(scope, receive, sender)\n  File \"/Users/Apple/TO-DO project/venv/lib/python3.12/site-packages/starlette/routing.py\", line 73, in app\n    response = await f(request)\n               ^^^^^^^^^^^^^^^^\n  File \"/Users/Apple/TO-DO project/venv/lib/python3.12/site-packages/fastapi/routing.py\", line 301, in app\n    raw_response = await run_endpoint_function(\n                   ^^^^^^^^^^^^^^^^^^^^^^^^^^^^\n  File \"/Users/Apple/TO-DO project/venv/lib/python3.12/site-packages/fastapi/routing.py\", line 212, in run_endpoint_function\n    return await dependant.call(**values)\n           ^^^^^^^^^^^^^^^^^^^^^^^^^^^^^^\n  File \"/Users/Apple/TO-DO project/src/v1/routes/todo.py\", line 58, in get_todo\n    todo = await todo_service.get_todo_by_uid(todo_uid=todo_uid, session=session)\n           ^^^^^^^^^^^^^^^^^^^^^^^^^^^^^^^^^^^^^^^^^^^^^^^^^^^^^^^^^^^^^^^^^^^^^^\n  File \"/Users/Apple/TO-DO project/src/v1/service/todo.py\", line 13, in get_todo_by_uid\n    result = await session.exec(statement)\n             ^^^^^^^^^^^^^^^^^^^^^^^^^^^^^\n  File \"/Users/Apple/TO-DO project/venv/lib/python3.12/site-packages/sqlmodel/ext/asyncio/session.py\", line 81, in exec\n    result = await greenlet_spawn(\n             ^^^^^^^^^^^^^^^^^^^^^\n  File \"/Users/Apple/TO-DO project/venv/lib/python3.12/site-packages/sqlalchemy/util/_concurrency_py3k.py\", line 201, in greenlet_spawn\n    result = context.throw(*sys.exc_info())\n             ^^^^^^^^^^^^^^^^^^^^^^^^^^^^^^\n  File \"/Users/Apple/TO-DO project/venv/lib/python3.12/site-packages/sqlmodel/orm/session.py\", line 66, in exec\n    results = super().execute(\n              ^^^^^^^^^^^^^^^^\n  File \"/Users/Apple/TO-DO project/venv/lib/python3.12/site-packages/sqlalchemy/orm/session.py\", line 2365, in execute\n    return self._execute_internal(\n           ^^^^^^^^^^^^^^^^^^^^^^^\n  File \"/Users/Apple/TO-DO project/venv/lib/python3.12/site-packages/sqlalchemy/orm/session.py\", line 2251, in _execute_internal\n    result: Result[Any] = compile_state_cls.orm_execute_statement(\n                          ^^^^^^^^^^^^^^^^^^^^^^^^^^^^^^^^^^^^^^^^\n  File \"/Users/Apple/TO-DO project/venv/lib/python3.12/site-packages/sqlalchemy/orm/context.py\", line 306, in orm_execute_statement\n    result = conn.execute(\n             ^^^^^^^^^^^^^\n  File \"/Users/Apple/TO-DO project/venv/lib/python3.12/site-packages/sqlalchemy/engine/base.py\", line 1415, in execute\n    return meth(\n           ^^^^^\n  File \"/Users/Apple/TO-DO project/venv/lib/python3.12/site-packages/sqlalchemy/sql/elements.py\", line 523, in _execute_on_connection\n    return connection._execute_clauseelement(\n           ^^^^^^^^^^^^^^^^^^^^^^^^^^^^^^^^^^\n  File \"/Users/Apple/TO-DO project/venv/lib/python3.12/site-packages/sqlalchemy/engine/base.py\", line 1637, in _execute_clauseelement\n    ret = self._execute_context(\n          ^^^^^^^^^^^^^^^^^^^^^^\n  File \"/Users/Apple/TO-DO project/venv/lib/python3.12/site-packages/sqlalchemy/engine/base.py\", line 1842, in _execute_context\n    return self._exec_single_context(\n           ^^^^^^^^^^^^^^^^^^^^^^^^^^\n  File \"/Users/Apple/TO-DO project/venv/lib/python3.12/site-packages/sqlalchemy/engine/base.py\", line 1982, in _exec_single_context\n    self._handle_dbapi_exception(\n  File \"/Users/Apple/TO-DO project/venv/lib/python3.12/site-packages/sqlalchemy/engine/base.py\", line 2351, in _handle_dbapi_exception\n    raise sqlalchemy_exception.with_traceback(exc_info[2]) from e\n  File \"/Users/Apple/TO-DO project/venv/lib/python3.12/site-packages/sqlalchemy/engine/base.py\", line 1963, in _exec_single_context\n    self.dialect.do_execute(\n  File \"/Users/Apple/TO-DO project/venv/lib/python3.12/site-packages/sqlalchemy/engine/default.py\", line 943, in do_execute\n    cursor.execute(statement, parameters)\n  File \"/Users/Apple/TO-DO project/venv/lib/python3.12/site-packages/sqlalchemy/dialects/postgresql/asyncpg.py\", line 580, in execute\n    self._adapt_connection.await_(\n  File \"/Users/Apple/TO-DO project/venv/lib/python3.12/site-packages/sqlalchemy/util/_concurrency_py3k.py\", line 132, in await_only\n    return current.parent.switch(awaitable)  # type: ignore[no-any-return,attr-defined] # noqa: E501\n           ^^^^^^^^^^^^^^^^^^^^^^^^^^^^^^^^\n  File \"/Users/Apple/TO-DO project/venv/lib/python3.12/site-packages/sqlalchemy/util/_concurrency_py3k.py\", line 196, in greenlet_spawn\n    value = await result\n            ^^^^^^^^^^^^\n  File \"/Users/Apple/TO-DO project/venv/lib/python3.12/site-packages/sqlalchemy/dialects/postgresql/asyncpg.py\", line 558, in _prepare_and_execute\n    self._handle_exception(error)\n  File \"/Users/Apple/TO-DO project/venv/lib/python3.12/site-packages/sqlalchemy/dialects/postgresql/asyncpg.py\", line 508, in _handle_exception\n    self._adapt_connection._handle_exception(error)\n  File \"/Users/Apple/TO-DO project/venv/lib/python3.12/site-packages/sqlalchemy/dialects/postgresql/asyncpg.py\", line 792, in _handle_exception\n    raise translated_error from error\nsqlalchemy.exc.DBAPIError: (sqlalchemy.dialects.postgresql.asyncpg.Error) <class 'asyncpg.exceptions.DataError'>: invalid input for query argument $1: 'count' (invalid UUID 'count': length must be between 32..36 characters, got 5)\n[SQL: SELECT todo_items.todo_uid, todo_items.title, todo_items.description, todo_items.created_at, todo_items.updated_at, todo_items.user_uid \nFROM todo_items \nWHERE todo_items.todo_uid = $1::UUID]\n[parameters: ('count',)]\n(Background on this error at: https://sqlalche.me/e/20/dbapi)"}
{"asctime": "2025-06-30 10:08:58", "msecs": 46.0, "levelname": "INFO", "name": "uvicorn.error", "lineno": 263, "message": "Shutting down"}
{"asctime": "2025-06-30 10:08:58", "msecs": 186.0, "levelname": "INFO", "name": "uvicorn.error", "lineno": 67, "message": "Waiting for application shutdown."}
{"asctime": "2025-06-30 10:08:58", "msecs": 340.0, "levelname": "INFO", "name": "uvicorn.error", "lineno": 76, "message": "Application shutdown complete."}
{"asctime": "2025-06-30 10:08:58", "msecs": 342.0, "levelname": "INFO", "name": "uvicorn.error", "lineno": 93, "message": "Finished server process [13989]", "color_message": "Finished server process [\u001b[36m%d\u001b[0m]"}
{"asctime": "2025-06-30 10:08:59", "msecs": 29.0, "levelname": "INFO", "name": "src", "lineno": 24, "message": "Logging works!!!"}
{"asctime": "2025-06-30 10:09:03", "msecs": 254.0, "levelname": "INFO", "name": "uvicorn.error", "lineno": 62, "message": "Application startup complete."}
{"asctime": "2025-06-30 10:09:03", "msecs": 683.0, "levelname": "INFO", "name": "src", "lineno": 24, "message": "Logging works!!!"}
{"asctime": "2025-06-30 10:09:07", "msecs": 60.0, "levelname": "INFO", "name": "uvicorn.error", "lineno": 62, "message": "Application startup complete."}
{"asctime": "2025-06-30 10:09:08", "msecs": 482.0, "levelname": "INFO", "name": "uvicorn.error", "lineno": 263, "message": "Shutting down"}
{"asctime": "2025-06-30 10:09:08", "msecs": 584.0, "levelname": "INFO", "name": "uvicorn.error", "lineno": 67, "message": "Waiting for application shutdown."}
{"asctime": "2025-06-30 10:09:08", "msecs": 728.0, "levelname": "INFO", "name": "uvicorn.error", "lineno": 76, "message": "Application shutdown complete."}
{"asctime": "2025-06-30 10:09:08", "msecs": 728.0, "levelname": "INFO", "name": "uvicorn.error", "lineno": 93, "message": "Finished server process [14080]", "color_message": "Finished server process [\u001b[36m%d\u001b[0m]"}
{"asctime": "2025-06-30 10:09:36", "msecs": 996.0, "levelname": "INFO", "name": "src", "lineno": 24, "message": "Logging works!!!"}
{"asctime": "2025-06-30 10:09:40", "msecs": 463.0, "levelname": "INFO", "name": "uvicorn.error", "lineno": 62, "message": "Application startup complete."}
{"asctime": "2025-06-30 10:09:52", "msecs": 926.0, "levelname": "INFO", "name": "src", "lineno": 24, "message": "Logging works!!!"}
{"asctime": "2025-06-30 10:09:56", "msecs": 432.0, "levelname": "INFO", "name": "uvicorn.error", "lineno": 62, "message": "Application startup complete."}
{"asctime": "2025-06-30 10:09:56", "msecs": 871.0, "levelname": "INFO", "name": "src", "lineno": 24, "message": "Logging works!!!"}
{"asctime": "2025-06-30 10:10:00", "msecs": 297.0, "levelname": "INFO", "name": "uvicorn.error", "lineno": 62, "message": "Application startup complete."}
{"asctime": "2025-06-30 10:10:03", "msecs": 838.0, "levelname": "INFO", "name": "uvicorn.error", "lineno": 263, "message": "Shutting down"}
{"asctime": "2025-06-30 10:10:03", "msecs": 941.0, "levelname": "INFO", "name": "uvicorn.error", "lineno": 67, "message": "Waiting for application shutdown."}
{"asctime": "2025-06-30 10:10:04", "msecs": 93.0, "levelname": "INFO", "name": "uvicorn.error", "lineno": 76, "message": "Application shutdown complete."}
{"asctime": "2025-06-30 10:10:04", "msecs": 94.0, "levelname": "INFO", "name": "uvicorn.error", "lineno": 93, "message": "Finished server process [14217]", "color_message": "Finished server process [\u001b[36m%d\u001b[0m]"}
{"asctime": "2025-06-30 10:10:04", "msecs": 623.0, "levelname": "INFO", "name": "src", "lineno": 24, "message": "Logging works!!!"}
{"asctime": "2025-06-30 10:10:08", "msecs": 472.0, "levelname": "INFO", "name": "uvicorn.error", "lineno": 62, "message": "Application startup complete."}
{"asctime": "2025-06-30 10:10:08", "msecs": 916.0, "levelname": "INFO", "name": "src", "lineno": 24, "message": "Logging works!!!"}
{"asctime": "2025-06-30 10:10:12", "msecs": 425.0, "levelname": "INFO", "name": "uvicorn.error", "lineno": 62, "message": "Application startup complete."}
{"asctime": "2025-06-30 10:10:12", "msecs": 872.0, "levelname": "INFO", "name": "src", "lineno": 24, "message": "Logging works!!!"}
{"asctime": "2025-06-30 10:10:16", "msecs": 357.0, "levelname": "INFO", "name": "uvicorn.error", "lineno": 62, "message": "Application startup complete."}
{"asctime": "2025-06-30 10:10:16", "msecs": 779.0, "levelname": "INFO", "name": "src", "lineno": 24, "message": "Logging works!!!"}
{"asctime": "2025-06-30 10:10:21", "msecs": 13.0, "levelname": "INFO", "name": "uvicorn.error", "lineno": 62, "message": "Application startup complete."}
{"asctime": "2025-06-30 10:10:33", "msecs": 970.0, "levelname": "DEBUG", "name": "src.utils.utils", "lineno": 41, "message": "Decoding Token here"}
{"asctime": "2025-06-30 10:10:34", "msecs": 398.0, "levelname": "INFO", "name": "uvicorn.access", "lineno": 476, "message": "127.0.0.1:57819 - \"GET /api/v1/todo/count_todos HTTP/1.1\" 500"}
{"asctime": "2025-06-30 10:10:34", "msecs": 401.0, "levelname": "ERROR", "name": "uvicorn.error", "lineno": 414, "message": "Exception in ASGI application\n", "exc_info": "Traceback (most recent call last):\n  File \"asyncpg/protocol/prepared_stmt.pyx\", line 175, in asyncpg.protocol.protocol.PreparedStatementState._encode_bind_msg\n  File \"asyncpg/protocol/codecs/base.pyx\", line 227, in asyncpg.protocol.protocol.Codec.encode\n  File \"asyncpg/protocol/codecs/base.pyx\", line 129, in asyncpg.protocol.protocol.Codec.encode_scalar\n  File \"asyncpg/pgproto/./codecs/uuid.pyx\", line 16, in asyncpg.pgproto.pgproto.uuid_encode\n  File \"asyncpg/pgproto/./uuid.pyx\", line 88, in asyncpg.pgproto.pgproto.pg_uuid_bytes_from_str\nValueError: invalid UUID 'count_todos': length must be between 32..36 characters, got 11\n\nThe above exception was the direct cause of the following exception:\n\nTraceback (most recent call last):\n  File \"/Users/Apple/TO-DO project/venv/lib/python3.12/site-packages/sqlalchemy/dialects/postgresql/asyncpg.py\", line 545, in _prepare_and_execute\n    self._rows = deque(await prepared_stmt.fetch(*parameters))\n                       ^^^^^^^^^^^^^^^^^^^^^^^^^^^^^^^^^^^^^^\n  File \"/Users/Apple/TO-DO project/venv/lib/python3.12/site-packages/asyncpg/prepared_stmt.py\", line 176, in fetch\n    data = await self.__bind_execute(args, 0, timeout)\n           ^^^^^^^^^^^^^^^^^^^^^^^^^^^^^^^^^^^^^^^^^^^\n  File \"/Users/Apple/TO-DO project/venv/lib/python3.12/site-packages/asyncpg/prepared_stmt.py\", line 267, in __bind_execute\n    data, status, _ = await self.__do_execute(\n                      ^^^^^^^^^^^^^^^^^^^^^^^^\n  File \"/Users/Apple/TO-DO project/venv/lib/python3.12/site-packages/asyncpg/prepared_stmt.py\", line 256, in __do_execute\n    return await executor(protocol)\n           ^^^^^^^^^^^^^^^^^^^^^^^^\n  File \"asyncpg/protocol/protocol.pyx\", line 185, in bind_execute\n  File \"asyncpg/protocol/prepared_stmt.pyx\", line 204, in asyncpg.protocol.protocol.PreparedStatementState._encode_bind_msg\nasyncpg.exceptions.DataError: invalid input for query argument $1: 'count_todos' (invalid UUID 'count_todos': length must be between 32..36 characters, got 11)\n\nThe above exception was the direct cause of the following exception:\n\nTraceback (most recent call last):\n  File \"/Users/Apple/TO-DO project/venv/lib/python3.12/site-packages/sqlalchemy/engine/base.py\", line 1963, in _exec_single_context\n    self.dialect.do_execute(\n  File \"/Users/Apple/TO-DO project/venv/lib/python3.12/site-packages/sqlalchemy/engine/default.py\", line 943, in do_execute\n    cursor.execute(statement, parameters)\n  File \"/Users/Apple/TO-DO project/venv/lib/python3.12/site-packages/sqlalchemy/dialects/postgresql/asyncpg.py\", line 580, in execute\n    self._adapt_connection.await_(\n  File \"/Users/Apple/TO-DO project/venv/lib/python3.12/site-packages/sqlalchemy/util/_concurrency_py3k.py\", line 132, in await_only\n    return current.parent.switch(awaitable)  # type: ignore[no-any-return,attr-defined] # noqa: E501\n           ^^^^^^^^^^^^^^^^^^^^^^^^^^^^^^^^\n  File \"/Users/Apple/TO-DO project/venv/lib/python3.12/site-packages/sqlalchemy/util/_concurrency_py3k.py\", line 196, in greenlet_spawn\n    value = await result\n            ^^^^^^^^^^^^\n  File \"/Users/Apple/TO-DO project/venv/lib/python3.12/site-packages/sqlalchemy/dialects/postgresql/asyncpg.py\", line 558, in _prepare_and_execute\n    self._handle_exception(error)\n  File \"/Users/Apple/TO-DO project/venv/lib/python3.12/site-packages/sqlalchemy/dialects/postgresql/asyncpg.py\", line 508, in _handle_exception\n    self._adapt_connection._handle_exception(error)\n  File \"/Users/Apple/TO-DO project/venv/lib/python3.12/site-packages/sqlalchemy/dialects/postgresql/asyncpg.py\", line 792, in _handle_exception\n    raise translated_error from error\nsqlalchemy.dialects.postgresql.asyncpg.AsyncAdapt_asyncpg_dbapi.Error: <class 'asyncpg.exceptions.DataError'>: invalid input for query argument $1: 'count_todos' (invalid UUID 'count_todos': length must be between 32..36 characters, got 11)\n\nThe above exception was the direct cause of the following exception:\n\nTraceback (most recent call last):\n  File \"/Users/Apple/TO-DO project/venv/lib/python3.12/site-packages/uvicorn/protocols/http/httptools_impl.py\", line 409, in run_asgi\n    result = await app(  # type: ignore[func-returns-value]\n             ^^^^^^^^^^^^^^^^^^^^^^^^^^^^^^^^^^^^^^^^^^^^^^\n  File \"/Users/Apple/TO-DO project/venv/lib/python3.12/site-packages/uvicorn/middleware/proxy_headers.py\", line 60, in __call__\n    return await self.app(scope, receive, send)\n           ^^^^^^^^^^^^^^^^^^^^^^^^^^^^^^^^^^^^\n  File \"/Users/Apple/TO-DO project/venv/lib/python3.12/site-packages/fastapi/applications.py\", line 1054, in __call__\n    await super().__call__(scope, receive, send)\n  File \"/Users/Apple/TO-DO project/venv/lib/python3.12/site-packages/starlette/applications.py\", line 112, in __call__\n    await self.middleware_stack(scope, receive, send)\n  File \"/Users/Apple/TO-DO project/venv/lib/python3.12/site-packages/starlette/middleware/errors.py\", line 187, in __call__\n    raise exc\n  File \"/Users/Apple/TO-DO project/venv/lib/python3.12/site-packages/starlette/middleware/errors.py\", line 165, in __call__\n    await self.app(scope, receive, _send)\n  File \"/Users/Apple/TO-DO project/venv/lib/python3.12/site-packages/starlette/middleware/exceptions.py\", line 62, in __call__\n    await wrap_app_handling_exceptions(self.app, conn)(scope, receive, send)\n  File \"/Users/Apple/TO-DO project/venv/lib/python3.12/site-packages/starlette/_exception_handler.py\", line 53, in wrapped_app\n    raise exc\n  File \"/Users/Apple/TO-DO project/venv/lib/python3.12/site-packages/starlette/_exception_handler.py\", line 42, in wrapped_app\n    await app(scope, receive, sender)\n  File \"/Users/Apple/TO-DO project/venv/lib/python3.12/site-packages/starlette/routing.py\", line 714, in __call__\n    await self.middleware_stack(scope, receive, send)\n  File \"/Users/Apple/TO-DO project/venv/lib/python3.12/site-packages/starlette/routing.py\", line 734, in app\n    await route.handle(scope, receive, send)\n  File \"/Users/Apple/TO-DO project/venv/lib/python3.12/site-packages/starlette/routing.py\", line 288, in handle\n    await self.app(scope, receive, send)\n  File \"/Users/Apple/TO-DO project/venv/lib/python3.12/site-packages/starlette/routing.py\", line 76, in app\n    await wrap_app_handling_exceptions(app, request)(scope, receive, send)\n  File \"/Users/Apple/TO-DO project/venv/lib/python3.12/site-packages/starlette/_exception_handler.py\", line 53, in wrapped_app\n    raise exc\n  File \"/Users/Apple/TO-DO project/venv/lib/python3.12/site-packages/starlette/_exception_handler.py\", line 42, in wrapped_app\n    await app(scope, receive, sender)\n  File \"/Users/Apple/TO-DO project/venv/lib/python3.12/site-packages/starlette/routing.py\", line 73, in app\n    response = await f(request)\n               ^^^^^^^^^^^^^^^^\n  File \"/Users/Apple/TO-DO project/venv/lib/python3.12/site-packages/fastapi/routing.py\", line 301, in app\n    raw_response = await run_endpoint_function(\n                   ^^^^^^^^^^^^^^^^^^^^^^^^^^^^\n  File \"/Users/Apple/TO-DO project/venv/lib/python3.12/site-packages/fastapi/routing.py\", line 212, in run_endpoint_function\n    return await dependant.call(**values)\n           ^^^^^^^^^^^^^^^^^^^^^^^^^^^^^^\n  File \"/Users/Apple/TO-DO project/src/v1/routes/todo.py\", line 58, in get_todo\n    todo = await todo_service.get_todo_by_uid(todo_uid=todo_uid, session=session)\n           ^^^^^^^^^^^^^^^^^^^^^^^^^^^^^^^^^^^^^^^^^^^^^^^^^^^^^^^^^^^^^^^^^^^^^^\n  File \"/Users/Apple/TO-DO project/src/v1/service/todo.py\", line 13, in get_todo_by_uid\n    result = await session.exec(statement)\n             ^^^^^^^^^^^^^^^^^^^^^^^^^^^^^\n  File \"/Users/Apple/TO-DO project/venv/lib/python3.12/site-packages/sqlmodel/ext/asyncio/session.py\", line 81, in exec\n    result = await greenlet_spawn(\n             ^^^^^^^^^^^^^^^^^^^^^\n  File \"/Users/Apple/TO-DO project/venv/lib/python3.12/site-packages/sqlalchemy/util/_concurrency_py3k.py\", line 201, in greenlet_spawn\n    result = context.throw(*sys.exc_info())\n             ^^^^^^^^^^^^^^^^^^^^^^^^^^^^^^\n  File \"/Users/Apple/TO-DO project/venv/lib/python3.12/site-packages/sqlmodel/orm/session.py\", line 66, in exec\n    results = super().execute(\n              ^^^^^^^^^^^^^^^^\n  File \"/Users/Apple/TO-DO project/venv/lib/python3.12/site-packages/sqlalchemy/orm/session.py\", line 2365, in execute\n    return self._execute_internal(\n           ^^^^^^^^^^^^^^^^^^^^^^^\n  File \"/Users/Apple/TO-DO project/venv/lib/python3.12/site-packages/sqlalchemy/orm/session.py\", line 2251, in _execute_internal\n    result: Result[Any] = compile_state_cls.orm_execute_statement(\n                          ^^^^^^^^^^^^^^^^^^^^^^^^^^^^^^^^^^^^^^^^\n  File \"/Users/Apple/TO-DO project/venv/lib/python3.12/site-packages/sqlalchemy/orm/context.py\", line 306, in orm_execute_statement\n    result = conn.execute(\n             ^^^^^^^^^^^^^\n  File \"/Users/Apple/TO-DO project/venv/lib/python3.12/site-packages/sqlalchemy/engine/base.py\", line 1415, in execute\n    return meth(\n           ^^^^^\n  File \"/Users/Apple/TO-DO project/venv/lib/python3.12/site-packages/sqlalchemy/sql/elements.py\", line 523, in _execute_on_connection\n    return connection._execute_clauseelement(\n           ^^^^^^^^^^^^^^^^^^^^^^^^^^^^^^^^^^\n  File \"/Users/Apple/TO-DO project/venv/lib/python3.12/site-packages/sqlalchemy/engine/base.py\", line 1637, in _execute_clauseelement\n    ret = self._execute_context(\n          ^^^^^^^^^^^^^^^^^^^^^^\n  File \"/Users/Apple/TO-DO project/venv/lib/python3.12/site-packages/sqlalchemy/engine/base.py\", line 1842, in _execute_context\n    return self._exec_single_context(\n           ^^^^^^^^^^^^^^^^^^^^^^^^^^\n  File \"/Users/Apple/TO-DO project/venv/lib/python3.12/site-packages/sqlalchemy/engine/base.py\", line 1982, in _exec_single_context\n    self._handle_dbapi_exception(\n  File \"/Users/Apple/TO-DO project/venv/lib/python3.12/site-packages/sqlalchemy/engine/base.py\", line 2351, in _handle_dbapi_exception\n    raise sqlalchemy_exception.with_traceback(exc_info[2]) from e\n  File \"/Users/Apple/TO-DO project/venv/lib/python3.12/site-packages/sqlalchemy/engine/base.py\", line 1963, in _exec_single_context\n    self.dialect.do_execute(\n  File \"/Users/Apple/TO-DO project/venv/lib/python3.12/site-packages/sqlalchemy/engine/default.py\", line 943, in do_execute\n    cursor.execute(statement, parameters)\n  File \"/Users/Apple/TO-DO project/venv/lib/python3.12/site-packages/sqlalchemy/dialects/postgresql/asyncpg.py\", line 580, in execute\n    self._adapt_connection.await_(\n  File \"/Users/Apple/TO-DO project/venv/lib/python3.12/site-packages/sqlalchemy/util/_concurrency_py3k.py\", line 132, in await_only\n    return current.parent.switch(awaitable)  # type: ignore[no-any-return,attr-defined] # noqa: E501\n           ^^^^^^^^^^^^^^^^^^^^^^^^^^^^^^^^\n  File \"/Users/Apple/TO-DO project/venv/lib/python3.12/site-packages/sqlalchemy/util/_concurrency_py3k.py\", line 196, in greenlet_spawn\n    value = await result\n            ^^^^^^^^^^^^\n  File \"/Users/Apple/TO-DO project/venv/lib/python3.12/site-packages/sqlalchemy/dialects/postgresql/asyncpg.py\", line 558, in _prepare_and_execute\n    self._handle_exception(error)\n  File \"/Users/Apple/TO-DO project/venv/lib/python3.12/site-packages/sqlalchemy/dialects/postgresql/asyncpg.py\", line 508, in _handle_exception\n    self._adapt_connection._handle_exception(error)\n  File \"/Users/Apple/TO-DO project/venv/lib/python3.12/site-packages/sqlalchemy/dialects/postgresql/asyncpg.py\", line 792, in _handle_exception\n    raise translated_error from error\nsqlalchemy.exc.DBAPIError: (sqlalchemy.dialects.postgresql.asyncpg.Error) <class 'asyncpg.exceptions.DataError'>: invalid input for query argument $1: 'count_todos' (invalid UUID 'count_todos': length must be between 32..36 characters, got 11)\n[SQL: SELECT todo_items.todo_uid, todo_items.title, todo_items.description, todo_items.created_at, todo_items.updated_at, todo_items.user_uid \nFROM todo_items \nWHERE todo_items.todo_uid = $1::UUID]\n[parameters: ('count_todos',)]\n(Background on this error at: https://sqlalche.me/e/20/dbapi)"}
{"asctime": "2025-06-30 10:12:34", "msecs": 306.0, "levelname": "INFO", "name": "uvicorn.error", "lineno": 263, "message": "Shutting down"}
{"asctime": "2025-06-30 10:12:34", "msecs": 502.0, "levelname": "INFO", "name": "uvicorn.error", "lineno": 67, "message": "Waiting for application shutdown."}
{"asctime": "2025-06-30 10:12:34", "msecs": 786.0, "levelname": "INFO", "name": "uvicorn.error", "lineno": 76, "message": "Application shutdown complete."}
{"asctime": "2025-06-30 10:12:34", "msecs": 791.0, "levelname": "INFO", "name": "uvicorn.error", "lineno": 93, "message": "Finished server process [14257]", "color_message": "Finished server process [\u001b[36m%d\u001b[0m]"}
{"asctime": "2025-06-30 10:13:06", "msecs": 835.0, "levelname": "INFO", "name": "src", "lineno": 24, "message": "Logging works!!!"}
{"asctime": "2025-06-30 10:13:10", "msecs": 693.0, "levelname": "INFO", "name": "uvicorn.error", "lineno": 62, "message": "Application startup complete."}
{"asctime": "2025-06-30 10:13:13", "msecs": 729.0, "levelname": "INFO", "name": "uvicorn.error", "lineno": 263, "message": "Shutting down"}
{"asctime": "2025-06-30 10:13:13", "msecs": 832.0, "levelname": "INFO", "name": "uvicorn.error", "lineno": 67, "message": "Waiting for application shutdown."}
{"asctime": "2025-06-30 10:13:13", "msecs": 969.0, "levelname": "INFO", "name": "uvicorn.error", "lineno": 76, "message": "Application shutdown complete."}
{"asctime": "2025-06-30 10:13:13", "msecs": 971.0, "levelname": "INFO", "name": "uvicorn.error", "lineno": 93, "message": "Finished server process [14458]", "color_message": "Finished server process [\u001b[36m%d\u001b[0m]"}
{"asctime": "2025-06-30 10:13:14", "msecs": 604.0, "levelname": "INFO", "name": "src", "lineno": 24, "message": "Logging works!!!"}
{"asctime": "2025-06-30 10:13:17", "msecs": 983.0, "levelname": "INFO", "name": "uvicorn.error", "lineno": 62, "message": "Application startup complete."}
{"asctime": "2025-06-30 10:13:18", "msecs": 86.0, "levelname": "INFO", "name": "uvicorn.error", "lineno": 263, "message": "Shutting down"}
{"asctime": "2025-06-30 10:13:18", "msecs": 188.0, "levelname": "INFO", "name": "uvicorn.error", "lineno": 67, "message": "Waiting for application shutdown."}
{"asctime": "2025-06-30 10:13:18", "msecs": 326.0, "levelname": "INFO", "name": "uvicorn.error", "lineno": 76, "message": "Application shutdown complete."}
{"asctime": "2025-06-30 10:13:18", "msecs": 328.0, "levelname": "INFO", "name": "uvicorn.error", "lineno": 93, "message": "Finished server process [14471]", "color_message": "Finished server process [\u001b[36m%d\u001b[0m]"}
{"asctime": "2025-06-30 10:13:18", "msecs": 742.0, "levelname": "INFO", "name": "src", "lineno": 24, "message": "Logging works!!!"}
{"asctime": "2025-06-30 10:13:22", "msecs": 204.0, "levelname": "INFO", "name": "uvicorn.error", "lineno": 62, "message": "Application startup complete."}
{"asctime": "2025-06-30 10:13:22", "msecs": 699.0, "levelname": "INFO", "name": "src", "lineno": 24, "message": "Logging works!!!"}
{"asctime": "2025-06-30 10:13:26", "msecs": 236.0, "levelname": "INFO", "name": "uvicorn.error", "lineno": 62, "message": "Application startup complete."}
{"asctime": "2025-06-30 10:13:56", "msecs": 58.0, "levelname": "INFO", "name": "uvicorn.error", "lineno": 263, "message": "Shutting down"}
{"asctime": "2025-06-30 10:13:56", "msecs": 164.0, "levelname": "INFO", "name": "uvicorn.error", "lineno": 67, "message": "Waiting for application shutdown."}
{"asctime": "2025-06-30 10:13:56", "msecs": 304.0, "levelname": "INFO", "name": "uvicorn.error", "lineno": 76, "message": "Application shutdown complete."}
{"asctime": "2025-06-30 10:13:56", "msecs": 306.0, "levelname": "INFO", "name": "uvicorn.error", "lineno": 93, "message": "Finished server process [14487]", "color_message": "Finished server process [\u001b[36m%d\u001b[0m]"}
{"asctime": "2025-06-30 10:13:56", "msecs": 880.0, "levelname": "INFO", "name": "src", "lineno": 24, "message": "Logging works!!!"}
{"asctime": "2025-06-30 10:14:00", "msecs": 292.0, "levelname": "INFO", "name": "uvicorn.error", "lineno": 62, "message": "Application startup complete."}
{"asctime": "2025-06-30 10:14:00", "msecs": 779.0, "levelname": "INFO", "name": "src", "lineno": 24, "message": "Logging works!!!"}
{"asctime": "2025-06-30 10:14:04", "msecs": 279.0, "levelname": "INFO", "name": "uvicorn.error", "lineno": 62, "message": "Application startup complete."}
{"asctime": "2025-06-30 10:14:12", "msecs": 70.0, "levelname": "INFO", "name": "uvicorn.error", "lineno": 263, "message": "Shutting down"}
{"asctime": "2025-06-30 10:14:12", "msecs": 179.0, "levelname": "INFO", "name": "uvicorn.error", "lineno": 67, "message": "Waiting for application shutdown."}
{"asctime": "2025-06-30 10:14:12", "msecs": 335.0, "levelname": "INFO", "name": "uvicorn.error", "lineno": 76, "message": "Application shutdown complete."}
{"asctime": "2025-06-30 10:14:12", "msecs": 336.0, "levelname": "INFO", "name": "uvicorn.error", "lineno": 93, "message": "Finished server process [14530]", "color_message": "Finished server process [\u001b[36m%d\u001b[0m]"}
{"asctime": "2025-06-30 10:14:12", "msecs": 856.0, "levelname": "INFO", "name": "src", "lineno": 24, "message": "Logging works!!!"}
{"asctime": "2025-06-30 10:14:16", "msecs": 195.0, "levelname": "INFO", "name": "uvicorn.error", "lineno": 62, "message": "Application startup complete."}
{"asctime": "2025-06-30 10:14:28", "msecs": 79.0, "levelname": "DEBUG", "name": "src.utils.utils", "lineno": 41, "message": "Decoding Token here"}
{"asctime": "2025-06-30 10:14:28", "msecs": 84.0, "levelname": "INFO", "name": "uvicorn.access", "lineno": 476, "message": "127.0.0.1:57958 - \"GET /api/v1/todo/count HTTP/1.1\" 500"}
{"asctime": "2025-06-30 10:14:28", "msecs": 85.0, "levelname": "ERROR", "name": "uvicorn.error", "lineno": 414, "message": "Exception in ASGI application\n", "exc_info": "Traceback (most recent call last):\n  File \"/Users/Apple/TO-DO project/venv/lib/python3.12/site-packages/uvicorn/protocols/http/httptools_impl.py\", line 409, in run_asgi\n    result = await app(  # type: ignore[func-returns-value]\n             ^^^^^^^^^^^^^^^^^^^^^^^^^^^^^^^^^^^^^^^^^^^^^^\n  File \"/Users/Apple/TO-DO project/venv/lib/python3.12/site-packages/uvicorn/middleware/proxy_headers.py\", line 60, in __call__\n    return await self.app(scope, receive, send)\n           ^^^^^^^^^^^^^^^^^^^^^^^^^^^^^^^^^^^^\n  File \"/Users/Apple/TO-DO project/venv/lib/python3.12/site-packages/fastapi/applications.py\", line 1054, in __call__\n    await super().__call__(scope, receive, send)\n  File \"/Users/Apple/TO-DO project/venv/lib/python3.12/site-packages/starlette/applications.py\", line 112, in __call__\n    await self.middleware_stack(scope, receive, send)\n  File \"/Users/Apple/TO-DO project/venv/lib/python3.12/site-packages/starlette/middleware/errors.py\", line 187, in __call__\n    raise exc\n  File \"/Users/Apple/TO-DO project/venv/lib/python3.12/site-packages/starlette/middleware/errors.py\", line 165, in __call__\n    await self.app(scope, receive, _send)\n  File \"/Users/Apple/TO-DO project/venv/lib/python3.12/site-packages/starlette/middleware/exceptions.py\", line 62, in __call__\n    await wrap_app_handling_exceptions(self.app, conn)(scope, receive, send)\n  File \"/Users/Apple/TO-DO project/venv/lib/python3.12/site-packages/starlette/_exception_handler.py\", line 53, in wrapped_app\n    raise exc\n  File \"/Users/Apple/TO-DO project/venv/lib/python3.12/site-packages/starlette/_exception_handler.py\", line 42, in wrapped_app\n    await app(scope, receive, sender)\n  File \"/Users/Apple/TO-DO project/venv/lib/python3.12/site-packages/starlette/routing.py\", line 714, in __call__\n    await self.middleware_stack(scope, receive, send)\n  File \"/Users/Apple/TO-DO project/venv/lib/python3.12/site-packages/starlette/routing.py\", line 734, in app\n    await route.handle(scope, receive, send)\n  File \"/Users/Apple/TO-DO project/venv/lib/python3.12/site-packages/starlette/routing.py\", line 288, in handle\n    await self.app(scope, receive, send)\n  File \"/Users/Apple/TO-DO project/venv/lib/python3.12/site-packages/starlette/routing.py\", line 76, in app\n    await wrap_app_handling_exceptions(app, request)(scope, receive, send)\n  File \"/Users/Apple/TO-DO project/venv/lib/python3.12/site-packages/starlette/_exception_handler.py\", line 53, in wrapped_app\n    raise exc\n  File \"/Users/Apple/TO-DO project/venv/lib/python3.12/site-packages/starlette/_exception_handler.py\", line 42, in wrapped_app\n    await app(scope, receive, sender)\n  File \"/Users/Apple/TO-DO project/venv/lib/python3.12/site-packages/starlette/routing.py\", line 73, in app\n    response = await f(request)\n               ^^^^^^^^^^^^^^^^\n  File \"/Users/Apple/TO-DO project/venv/lib/python3.12/site-packages/fastapi/routing.py\", line 301, in app\n    raw_response = await run_endpoint_function(\n                   ^^^^^^^^^^^^^^^^^^^^^^^^^^^^\n  File \"/Users/Apple/TO-DO project/venv/lib/python3.12/site-packages/fastapi/routing.py\", line 212, in run_endpoint_function\n    return await dependant.call(**values)\n           ^^^^^^^^^^^^^^^^^^^^^^^^^^^^^^\n  File \"/Users/Apple/TO-DO project/src/v1/routes/todo.py\", line 50, in count_todos\n    to_dos = await todo_service.count_todos(session=session)\n             ^^^^^^^^^^^^^^^^^^^^^^^^^^^^^^^^^^^^^^^^^^^^^^^\n  File \"/Users/Apple/TO-DO project/src/v1/service/todo.py\", line 82, in count_todos\n    statement = select(func.count()).select(TodoItem)\n                ^^^^^^^^^^^^^^^^^^^^^^^^^^^^^^^^^^^^^\n  File \"<string>\", line 2, in select\n  File \"/Users/Apple/TO-DO project/venv/lib/python3.12/site-packages/sqlalchemy/util/deprecations.py\", line 386, in warned\n    return fn(*args, **kwargs)  # type: ignore[no-any-return]\n           ^^^^^^^^^^^^^^^^^^^\n  File \"/Users/Apple/TO-DO project/venv/lib/python3.12/site-packages/sqlalchemy/sql/selectable.py\", line 3659, in select\n    return self._implicit_subquery.select(*arg, **kw)\n           ^^^^^^^^^^^^^^^^^^^^^^^^^^^^^^^^^^^^^^^^^^\nTypeError: FromClause.select() takes 1 positional argument but 2 were given"}
{"asctime": "2025-06-30 10:14:52", "msecs": 99.0, "levelname": "INFO", "name": "uvicorn.error", "lineno": 263, "message": "Shutting down"}
{"asctime": "2025-06-30 10:14:52", "msecs": 205.0, "levelname": "INFO", "name": "uvicorn.error", "lineno": 67, "message": "Waiting for application shutdown."}
{"asctime": "2025-06-30 10:14:52", "msecs": 345.0, "levelname": "INFO", "name": "uvicorn.error", "lineno": 76, "message": "Application shutdown complete."}
{"asctime": "2025-06-30 10:14:52", "msecs": 347.0, "levelname": "INFO", "name": "uvicorn.error", "lineno": 93, "message": "Finished server process [14543]", "color_message": "Finished server process [\u001b[36m%d\u001b[0m]"}
{"asctime": "2025-06-30 10:14:52", "msecs": 937.0, "levelname": "INFO", "name": "src", "lineno": 24, "message": "Logging works!!!"}
{"asctime": "2025-06-30 10:14:56", "msecs": 679.0, "levelname": "INFO", "name": "uvicorn.error", "lineno": 62, "message": "Application startup complete."}
{"asctime": "2025-06-30 10:16:21", "msecs": 813.0, "levelname": "DEBUG", "name": "src.utils.utils", "lineno": 41, "message": "Decoding Token here"}
{"asctime": "2025-06-30 10:16:22", "msecs": 365.0, "levelname": "INFO", "name": "uvicorn.access", "lineno": 476, "message": "127.0.0.1:57996 - \"GET /api/v1/todo/count HTTP/1.1\" 200"}
{"asctime": "2025-06-30 10:17:01", "msecs": 565.0, "levelname": "INFO", "name": "uvicorn.error", "lineno": 263, "message": "Shutting down"}
{"asctime": "2025-06-30 10:17:01", "msecs": 674.0, "levelname": "INFO", "name": "uvicorn.error", "lineno": 67, "message": "Waiting for application shutdown."}
{"asctime": "2025-06-30 10:17:01", "msecs": 835.0, "levelname": "INFO", "name": "uvicorn.error", "lineno": 76, "message": "Application shutdown complete."}
{"asctime": "2025-06-30 10:17:01", "msecs": 838.0, "levelname": "INFO", "name": "uvicorn.error", "lineno": 93, "message": "Finished server process [14604]", "color_message": "Finished server process [\u001b[36m%d\u001b[0m]"}
